2025-09-04 20:10:38,547 - src.services.elasticsearch_service - INFO - Initialized Elasticsearch connection to localhost:9200
2025-09-04 20:10:42,608 - elastic_transport.transport - INFO - HEAD http://localhost:9200/ [status:N/A duration:4.061s]
2025-09-04 20:10:42,609 - elastic_transport.node_pool - WARNING - Node <Urllib3HttpNode(http://localhost:9200)> has failed for 1 times in a row, putting on 1 second timeout
2025-09-04 20:10:42,609 - elastic_transport.transport - WARNING - Retrying request after failure (attempt 0 of 3)
Traceback (most recent call last):
  File "C:\Users\uzun.a.i\PycharmProjects\PythonProject\.venv\Lib\site-packages\urllib3\connection.py", line 198, in _new_conn
    sock = connection.create_connection(
        (self._dns_host, self.port),
    ...<2 lines>...
        socket_options=self.socket_options,
    )
  File "C:\Users\uzun.a.i\PycharmProjects\PythonProject\.venv\Lib\site-packages\urllib3\util\connection.py", line 85, in create_connection
    raise err
  File "C:\Users\uzun.a.i\PycharmProjects\PythonProject\.venv\Lib\site-packages\urllib3\util\connection.py", line 73, in create_connection
    sock.connect(sa)
    ~~~~~~~~~~~~^^^^
ConnectionRefusedError: [WinError 10061] Подключение не установлено, т.к. конечный компьютер отверг запрос на подключение

The above exception was the direct cause of the following exception:

Traceback (most recent call last):
  File "C:\Users\uzun.a.i\PycharmProjects\PythonProject\.venv\Lib\site-packages\elastic_transport\_node\_http_urllib3.py", line 167, in perform_request
    response = self.pool.urlopen(
        method,
    ...<4 lines>...
        **kw,  # type: ignore[arg-type]
    )
  File "C:\Users\uzun.a.i\PycharmProjects\PythonProject\.venv\Lib\site-packages\urllib3\connectionpool.py", line 841, in urlopen
    retries = retries.increment(
        method, url, error=new_e, _pool=self, _stacktrace=sys.exc_info()[2]
    )
  File "C:\Users\uzun.a.i\PycharmProjects\PythonProject\.venv\Lib\site-packages\urllib3\util\retry.py", line 449, in increment
    raise reraise(type(error), error, _stacktrace)
          ~~~~~~~^^^^^^^^^^^^^^^^^^^^^^^^^^^^^^^^^
  File "C:\Users\uzun.a.i\PycharmProjects\PythonProject\.venv\Lib\site-packages\urllib3\util\util.py", line 39, in reraise
    raise value
  File "C:\Users\uzun.a.i\PycharmProjects\PythonProject\.venv\Lib\site-packages\urllib3\connectionpool.py", line 787, in urlopen
    response = self._make_request(
        conn,
    ...<10 lines>...
        **response_kw,
    )
  File "C:\Users\uzun.a.i\PycharmProjects\PythonProject\.venv\Lib\site-packages\urllib3\connectionpool.py", line 493, in _make_request
    conn.request(
    ~~~~~~~~~~~~^
        method,
        ^^^^^^^
    ...<6 lines>...
        enforce_content_length=enforce_content_length,
        ^^^^^^^^^^^^^^^^^^^^^^^^^^^^^^^^^^^^^^^^^^^^^^
    )
    ^
  File "C:\Users\uzun.a.i\PycharmProjects\PythonProject\.venv\Lib\site-packages\urllib3\connection.py", line 494, in request
    self.endheaders()
    ~~~~~~~~~~~~~~~^^
  File "C:\Users\uzun.a.i\AppData\Local\Programs\Python\Python313\Lib\http\client.py", line 1333, in endheaders
    self._send_output(message_body, encode_chunked=encode_chunked)
    ~~~~~~~~~~~~~~~~~^^^^^^^^^^^^^^^^^^^^^^^^^^^^^^^^^^^^^^^^^^^^^
  File "C:\Users\uzun.a.i\AppData\Local\Programs\Python\Python313\Lib\http\client.py", line 1093, in _send_output
    self.send(msg)
    ~~~~~~~~~^^^^^
  File "C:\Users\uzun.a.i\AppData\Local\Programs\Python\Python313\Lib\http\client.py", line 1037, in send
    self.connect()
    ~~~~~~~~~~~~^^
  File "C:\Users\uzun.a.i\PycharmProjects\PythonProject\.venv\Lib\site-packages\urllib3\connection.py", line 325, in connect
    self.sock = self._new_conn()
                ~~~~~~~~~~~~~~^^
  File "C:\Users\uzun.a.i\PycharmProjects\PythonProject\.venv\Lib\site-packages\urllib3\connection.py", line 213, in _new_conn
    raise NewConnectionError(
        self, f"Failed to establish a new connection: {e}"
    ) from e
urllib3.exceptions.NewConnectionError: <urllib3.connection.HTTPConnection object at 0x000001C170A3FE00>: Failed to establish a new connection: [WinError 10061] Подключение не установлено, т.к. конечный компьютер отверг запрос на подключение

The above exception was the direct cause of the following exception:

Traceback (most recent call last):
  File "C:\Users\uzun.a.i\PycharmProjects\PythonProject\.venv\Lib\site-packages\elastic_transport\_transport.py", line 342, in perform_request
    resp = node.perform_request(
        method,
    ...<3 lines>...
        request_timeout=request_timeout,
    )
  File "C:\Users\uzun.a.i\PycharmProjects\PythonProject\.venv\Lib\site-packages\elastic_transport\_node\_http_urllib3.py", line 202, in perform_request
    raise err from e
elastic_transport.ConnectionError: Connection error caused by: NewConnectionError(<urllib3.connection.HTTPConnection object at 0x000001C170A3FE00>: Failed to establish a new connection: [WinError 10061] Подключение не установлено, т.к. конечный компьютер отверг запрос на подключение)
2025-09-04 20:10:46,739 - elastic_transport.transport - INFO - HEAD http://localhost:9200/ [status:N/A duration:4.078s]
2025-09-04 20:10:46,740 - elastic_transport.node_pool - WARNING - Node <Urllib3HttpNode(http://localhost:9200)> has failed for 2 times in a row, putting on 2 second timeout
2025-09-04 20:10:46,741 - elastic_transport.transport - WARNING - Retrying request after failure (attempt 1 of 3)
Traceback (most recent call last):
  File "C:\Users\uzun.a.i\PycharmProjects\PythonProject\.venv\Lib\site-packages\urllib3\connection.py", line 198, in _new_conn
    sock = connection.create_connection(
        (self._dns_host, self.port),
    ...<2 lines>...
        socket_options=self.socket_options,
    )
  File "C:\Users\uzun.a.i\PycharmProjects\PythonProject\.venv\Lib\site-packages\urllib3\util\connection.py", line 85, in create_connection
    raise err
  File "C:\Users\uzun.a.i\PycharmProjects\PythonProject\.venv\Lib\site-packages\urllib3\util\connection.py", line 73, in create_connection
    sock.connect(sa)
    ~~~~~~~~~~~~^^^^
ConnectionRefusedError: [WinError 10061] Подключение не установлено, т.к. конечный компьютер отверг запрос на подключение

The above exception was the direct cause of the following exception:

Traceback (most recent call last):
  File "C:\Users\uzun.a.i\PycharmProjects\PythonProject\.venv\Lib\site-packages\elastic_transport\_node\_http_urllib3.py", line 167, in perform_request
    response = self.pool.urlopen(
        method,
    ...<4 lines>...
        **kw,  # type: ignore[arg-type]
    )
  File "C:\Users\uzun.a.i\PycharmProjects\PythonProject\.venv\Lib\site-packages\urllib3\connectionpool.py", line 841, in urlopen
    retries = retries.increment(
        method, url, error=new_e, _pool=self, _stacktrace=sys.exc_info()[2]
    )
  File "C:\Users\uzun.a.i\PycharmProjects\PythonProject\.venv\Lib\site-packages\urllib3\util\retry.py", line 449, in increment
    raise reraise(type(error), error, _stacktrace)
          ~~~~~~~^^^^^^^^^^^^^^^^^^^^^^^^^^^^^^^^^
  File "C:\Users\uzun.a.i\PycharmProjects\PythonProject\.venv\Lib\site-packages\urllib3\util\util.py", line 39, in reraise
    raise value
  File "C:\Users\uzun.a.i\PycharmProjects\PythonProject\.venv\Lib\site-packages\urllib3\connectionpool.py", line 787, in urlopen
    response = self._make_request(
        conn,
    ...<10 lines>...
        **response_kw,
    )
  File "C:\Users\uzun.a.i\PycharmProjects\PythonProject\.venv\Lib\site-packages\urllib3\connectionpool.py", line 493, in _make_request
    conn.request(
    ~~~~~~~~~~~~^
        method,
        ^^^^^^^
    ...<6 lines>...
        enforce_content_length=enforce_content_length,
        ^^^^^^^^^^^^^^^^^^^^^^^^^^^^^^^^^^^^^^^^^^^^^^
    )
    ^
  File "C:\Users\uzun.a.i\PycharmProjects\PythonProject\.venv\Lib\site-packages\urllib3\connection.py", line 494, in request
    self.endheaders()
    ~~~~~~~~~~~~~~~^^
  File "C:\Users\uzun.a.i\AppData\Local\Programs\Python\Python313\Lib\http\client.py", line 1333, in endheaders
    self._send_output(message_body, encode_chunked=encode_chunked)
    ~~~~~~~~~~~~~~~~~^^^^^^^^^^^^^^^^^^^^^^^^^^^^^^^^^^^^^^^^^^^^^
  File "C:\Users\uzun.a.i\AppData\Local\Programs\Python\Python313\Lib\http\client.py", line 1093, in _send_output
    self.send(msg)
    ~~~~~~~~~^^^^^
  File "C:\Users\uzun.a.i\AppData\Local\Programs\Python\Python313\Lib\http\client.py", line 1037, in send
    self.connect()
    ~~~~~~~~~~~~^^
  File "C:\Users\uzun.a.i\PycharmProjects\PythonProject\.venv\Lib\site-packages\urllib3\connection.py", line 325, in connect
    self.sock = self._new_conn()
                ~~~~~~~~~~~~~~^^
  File "C:\Users\uzun.a.i\PycharmProjects\PythonProject\.venv\Lib\site-packages\urllib3\connection.py", line 213, in _new_conn
    raise NewConnectionError(
        self, f"Failed to establish a new connection: {e}"
    ) from e
urllib3.exceptions.NewConnectionError: <urllib3.connection.HTTPConnection object at 0x000001C170A2DD10>: Failed to establish a new connection: [WinError 10061] Подключение не установлено, т.к. конечный компьютер отверг запрос на подключение

The above exception was the direct cause of the following exception:

Traceback (most recent call last):
  File "C:\Users\uzun.a.i\PycharmProjects\PythonProject\.venv\Lib\site-packages\elastic_transport\_transport.py", line 342, in perform_request
    resp = node.perform_request(
        method,
    ...<3 lines>...
        request_timeout=request_timeout,
    )
  File "C:\Users\uzun.a.i\PycharmProjects\PythonProject\.venv\Lib\site-packages\elastic_transport\_node\_http_urllib3.py", line 202, in perform_request
    raise err from e
elastic_transport.ConnectionError: Connection error caused by: NewConnectionError(<urllib3.connection.HTTPConnection object at 0x000001C170A2DD10>: Failed to establish a new connection: [WinError 10061] Подключение не установлено, т.к. конечный компьютер отверг запрос на подключение)
2025-09-04 20:10:46,753 - elastic_transport.node_pool - INFO - Resurrected node <Urllib3HttpNode(http://localhost:9200)> (force=False)
2025-09-04 20:10:50,826 - elastic_transport.transport - INFO - HEAD http://localhost:9200/ [status:N/A duration:4.073s]
2025-09-04 20:10:50,826 - elastic_transport.node_pool - WARNING - Node <Urllib3HttpNode(http://localhost:9200)> has failed for 3 times in a row, putting on 4 second timeout
2025-09-04 20:10:50,826 - elastic_transport.transport - WARNING - Retrying request after failure (attempt 2 of 3)
Traceback (most recent call last):
  File "C:\Users\uzun.a.i\PycharmProjects\PythonProject\.venv\Lib\site-packages\urllib3\connection.py", line 198, in _new_conn
    sock = connection.create_connection(
        (self._dns_host, self.port),
    ...<2 lines>...
        socket_options=self.socket_options,
    )
  File "C:\Users\uzun.a.i\PycharmProjects\PythonProject\.venv\Lib\site-packages\urllib3\util\connection.py", line 85, in create_connection
    raise err
  File "C:\Users\uzun.a.i\PycharmProjects\PythonProject\.venv\Lib\site-packages\urllib3\util\connection.py", line 73, in create_connection
    sock.connect(sa)
    ~~~~~~~~~~~~^^^^
ConnectionRefusedError: [WinError 10061] Подключение не установлено, т.к. конечный компьютер отверг запрос на подключение

The above exception was the direct cause of the following exception:

Traceback (most recent call last):
  File "C:\Users\uzun.a.i\PycharmProjects\PythonProject\.venv\Lib\site-packages\elastic_transport\_node\_http_urllib3.py", line 167, in perform_request
    response = self.pool.urlopen(
        method,
    ...<4 lines>...
        **kw,  # type: ignore[arg-type]
    )
  File "C:\Users\uzun.a.i\PycharmProjects\PythonProject\.venv\Lib\site-packages\urllib3\connectionpool.py", line 841, in urlopen
    retries = retries.increment(
        method, url, error=new_e, _pool=self, _stacktrace=sys.exc_info()[2]
    )
  File "C:\Users\uzun.a.i\PycharmProjects\PythonProject\.venv\Lib\site-packages\urllib3\util\retry.py", line 449, in increment
    raise reraise(type(error), error, _stacktrace)
          ~~~~~~~^^^^^^^^^^^^^^^^^^^^^^^^^^^^^^^^^
  File "C:\Users\uzun.a.i\PycharmProjects\PythonProject\.venv\Lib\site-packages\urllib3\util\util.py", line 39, in reraise
    raise value
  File "C:\Users\uzun.a.i\PycharmProjects\PythonProject\.venv\Lib\site-packages\urllib3\connectionpool.py", line 787, in urlopen
    response = self._make_request(
        conn,
    ...<10 lines>...
        **response_kw,
    )
  File "C:\Users\uzun.a.i\PycharmProjects\PythonProject\.venv\Lib\site-packages\urllib3\connectionpool.py", line 493, in _make_request
    conn.request(
    ~~~~~~~~~~~~^
        method,
        ^^^^^^^
    ...<6 lines>...
        enforce_content_length=enforce_content_length,
        ^^^^^^^^^^^^^^^^^^^^^^^^^^^^^^^^^^^^^^^^^^^^^^
    )
    ^
  File "C:\Users\uzun.a.i\PycharmProjects\PythonProject\.venv\Lib\site-packages\urllib3\connection.py", line 494, in request
    self.endheaders()
    ~~~~~~~~~~~~~~~^^
  File "C:\Users\uzun.a.i\AppData\Local\Programs\Python\Python313\Lib\http\client.py", line 1333, in endheaders
    self._send_output(message_body, encode_chunked=encode_chunked)
    ~~~~~~~~~~~~~~~~~^^^^^^^^^^^^^^^^^^^^^^^^^^^^^^^^^^^^^^^^^^^^^
  File "C:\Users\uzun.a.i\AppData\Local\Programs\Python\Python313\Lib\http\client.py", line 1093, in _send_output
    self.send(msg)
    ~~~~~~~~~^^^^^
  File "C:\Users\uzun.a.i\AppData\Local\Programs\Python\Python313\Lib\http\client.py", line 1037, in send
    self.connect()
    ~~~~~~~~~~~~^^
  File "C:\Users\uzun.a.i\PycharmProjects\PythonProject\.venv\Lib\site-packages\urllib3\connection.py", line 325, in connect
    self.sock = self._new_conn()
                ~~~~~~~~~~~~~~^^
  File "C:\Users\uzun.a.i\PycharmProjects\PythonProject\.venv\Lib\site-packages\urllib3\connection.py", line 213, in _new_conn
    raise NewConnectionError(
        self, f"Failed to establish a new connection: {e}"
    ) from e
urllib3.exceptions.NewConnectionError: <urllib3.connection.HTTPConnection object at 0x000001C170A2DF90>: Failed to establish a new connection: [WinError 10061] Подключение не установлено, т.к. конечный компьютер отверг запрос на подключение

The above exception was the direct cause of the following exception:

Traceback (most recent call last):
  File "C:\Users\uzun.a.i\PycharmProjects\PythonProject\.venv\Lib\site-packages\elastic_transport\_transport.py", line 342, in perform_request
    resp = node.perform_request(
        method,
    ...<3 lines>...
        request_timeout=request_timeout,
    )
  File "C:\Users\uzun.a.i\PycharmProjects\PythonProject\.venv\Lib\site-packages\elastic_transport\_node\_http_urllib3.py", line 202, in perform_request
    raise err from e
elastic_transport.ConnectionError: Connection error caused by: NewConnectionError(<urllib3.connection.HTTPConnection object at 0x000001C170A2DF90>: Failed to establish a new connection: [WinError 10061] Подключение не установлено, т.к. конечный компьютер отверг запрос на подключение)
2025-09-04 20:10:50,829 - elastic_transport.node_pool - INFO - Resurrected node <Urllib3HttpNode(http://localhost:9200)> (force=False)
2025-09-04 20:10:54,888 - elastic_transport.transport - INFO - HEAD http://localhost:9200/ [status:N/A duration:4.059s]
2025-09-04 20:10:54,888 - elastic_transport.node_pool - WARNING - Node <Urllib3HttpNode(http://localhost:9200)> has failed for 4 times in a row, putting on 8 second timeout
2025-09-04 20:10:54,888 - src.material_matcher_app - WARNING - Cannot connect to Elasticsearch. Some features may not work.
2025-09-04 20:10:54,889 - src.material_matcher_app - INFO - MaterialMatcher application initialized successfully
2025-09-04 20:10:54,889 - src.material_matcher_app - INFO - No materials provided for matching
2025-09-04 20:12:48,589 - src.services.elasticsearch_service - INFO - Initialized Elasticsearch connection to localhost:9200
2025-09-04 20:12:52,687 - elastic_transport.transport - INFO - HEAD http://localhost:9200/ [status:N/A duration:4.098s]
2025-09-04 20:12:52,687 - elastic_transport.node_pool - WARNING - Node <Urllib3HttpNode(http://localhost:9200)> has failed for 1 times in a row, putting on 1 second timeout
2025-09-04 20:12:52,687 - elastic_transport.transport - WARNING - Retrying request after failure (attempt 0 of 3)
Traceback (most recent call last):
  File "C:\Users\uzun.a.i\PycharmProjects\PythonProject\.venv\Lib\site-packages\urllib3\connection.py", line 198, in _new_conn
    sock = connection.create_connection(
        (self._dns_host, self.port),
    ...<2 lines>...
        socket_options=self.socket_options,
    )
  File "C:\Users\uzun.a.i\PycharmProjects\PythonProject\.venv\Lib\site-packages\urllib3\util\connection.py", line 85, in create_connection
    raise err
  File "C:\Users\uzun.a.i\PycharmProjects\PythonProject\.venv\Lib\site-packages\urllib3\util\connection.py", line 73, in create_connection
    sock.connect(sa)
    ~~~~~~~~~~~~^^^^
ConnectionRefusedError: [WinError 10061] Подключение не установлено, т.к. конечный компьютер отверг запрос на подключение

The above exception was the direct cause of the following exception:

Traceback (most recent call last):
  File "C:\Users\uzun.a.i\PycharmProjects\PythonProject\.venv\Lib\site-packages\elastic_transport\_node\_http_urllib3.py", line 167, in perform_request
    response = self.pool.urlopen(
        method,
    ...<4 lines>...
        **kw,  # type: ignore[arg-type]
    )
  File "C:\Users\uzun.a.i\PycharmProjects\PythonProject\.venv\Lib\site-packages\urllib3\connectionpool.py", line 841, in urlopen
    retries = retries.increment(
        method, url, error=new_e, _pool=self, _stacktrace=sys.exc_info()[2]
    )
  File "C:\Users\uzun.a.i\PycharmProjects\PythonProject\.venv\Lib\site-packages\urllib3\util\retry.py", line 449, in increment
    raise reraise(type(error), error, _stacktrace)
          ~~~~~~~^^^^^^^^^^^^^^^^^^^^^^^^^^^^^^^^^
  File "C:\Users\uzun.a.i\PycharmProjects\PythonProject\.venv\Lib\site-packages\urllib3\util\util.py", line 39, in reraise
    raise value
  File "C:\Users\uzun.a.i\PycharmProjects\PythonProject\.venv\Lib\site-packages\urllib3\connectionpool.py", line 787, in urlopen
    response = self._make_request(
        conn,
    ...<10 lines>...
        **response_kw,
    )
  File "C:\Users\uzun.a.i\PycharmProjects\PythonProject\.venv\Lib\site-packages\urllib3\connectionpool.py", line 493, in _make_request
    conn.request(
    ~~~~~~~~~~~~^
        method,
        ^^^^^^^
    ...<6 lines>...
        enforce_content_length=enforce_content_length,
        ^^^^^^^^^^^^^^^^^^^^^^^^^^^^^^^^^^^^^^^^^^^^^^
    )
    ^
  File "C:\Users\uzun.a.i\PycharmProjects\PythonProject\.venv\Lib\site-packages\urllib3\connection.py", line 494, in request
    self.endheaders()
    ~~~~~~~~~~~~~~~^^
  File "C:\Users\uzun.a.i\AppData\Local\Programs\Python\Python313\Lib\http\client.py", line 1333, in endheaders
    self._send_output(message_body, encode_chunked=encode_chunked)
    ~~~~~~~~~~~~~~~~~^^^^^^^^^^^^^^^^^^^^^^^^^^^^^^^^^^^^^^^^^^^^^
  File "C:\Users\uzun.a.i\AppData\Local\Programs\Python\Python313\Lib\http\client.py", line 1093, in _send_output
    self.send(msg)
    ~~~~~~~~~^^^^^
  File "C:\Users\uzun.a.i\AppData\Local\Programs\Python\Python313\Lib\http\client.py", line 1037, in send
    self.connect()
    ~~~~~~~~~~~~^^
  File "C:\Users\uzun.a.i\PycharmProjects\PythonProject\.venv\Lib\site-packages\urllib3\connection.py", line 325, in connect
    self.sock = self._new_conn()
                ~~~~~~~~~~~~~~^^
  File "C:\Users\uzun.a.i\PycharmProjects\PythonProject\.venv\Lib\site-packages\urllib3\connection.py", line 213, in _new_conn
    raise NewConnectionError(
        self, f"Failed to establish a new connection: {e}"
    ) from e
urllib3.exceptions.NewConnectionError: <urllib3.connection.HTTPConnection object at 0x0000016D36F7F380>: Failed to establish a new connection: [WinError 10061] Подключение не установлено, т.к. конечный компьютер отверг запрос на подключение

The above exception was the direct cause of the following exception:

Traceback (most recent call last):
  File "C:\Users\uzun.a.i\PycharmProjects\PythonProject\.venv\Lib\site-packages\elastic_transport\_transport.py", line 342, in perform_request
    resp = node.perform_request(
        method,
    ...<3 lines>...
        request_timeout=request_timeout,
    )
  File "C:\Users\uzun.a.i\PycharmProjects\PythonProject\.venv\Lib\site-packages\elastic_transport\_node\_http_urllib3.py", line 202, in perform_request
    raise err from e
elastic_transport.ConnectionError: Connection error caused by: NewConnectionError(<urllib3.connection.HTTPConnection object at 0x0000016D36F7F380>: Failed to establish a new connection: [WinError 10061] Подключение не установлено, т.к. конечный компьютер отверг запрос на подключение)
2025-09-04 20:12:56,790 - elastic_transport.transport - INFO - HEAD http://localhost:9200/ [status:N/A duration:4.098s]
2025-09-04 20:12:56,790 - elastic_transport.node_pool - WARNING - Node <Urllib3HttpNode(http://localhost:9200)> has failed for 2 times in a row, putting on 2 second timeout
2025-09-04 20:12:56,790 - elastic_transport.transport - WARNING - Retrying request after failure (attempt 1 of 3)
Traceback (most recent call last):
  File "C:\Users\uzun.a.i\PycharmProjects\PythonProject\.venv\Lib\site-packages\urllib3\connection.py", line 198, in _new_conn
    sock = connection.create_connection(
        (self._dns_host, self.port),
    ...<2 lines>...
        socket_options=self.socket_options,
    )
  File "C:\Users\uzun.a.i\PycharmProjects\PythonProject\.venv\Lib\site-packages\urllib3\util\connection.py", line 85, in create_connection
    raise err
  File "C:\Users\uzun.a.i\PycharmProjects\PythonProject\.venv\Lib\site-packages\urllib3\util\connection.py", line 73, in create_connection
    sock.connect(sa)
    ~~~~~~~~~~~~^^^^
ConnectionRefusedError: [WinError 10061] Подключение не установлено, т.к. конечный компьютер отверг запрос на подключение

The above exception was the direct cause of the following exception:

Traceback (most recent call last):
  File "C:\Users\uzun.a.i\PycharmProjects\PythonProject\.venv\Lib\site-packages\elastic_transport\_node\_http_urllib3.py", line 167, in perform_request
    response = self.pool.urlopen(
        method,
    ...<4 lines>...
        **kw,  # type: ignore[arg-type]
    )
  File "C:\Users\uzun.a.i\PycharmProjects\PythonProject\.venv\Lib\site-packages\urllib3\connectionpool.py", line 841, in urlopen
    retries = retries.increment(
        method, url, error=new_e, _pool=self, _stacktrace=sys.exc_info()[2]
    )
  File "C:\Users\uzun.a.i\PycharmProjects\PythonProject\.venv\Lib\site-packages\urllib3\util\retry.py", line 449, in increment
    raise reraise(type(error), error, _stacktrace)
          ~~~~~~~^^^^^^^^^^^^^^^^^^^^^^^^^^^^^^^^^
  File "C:\Users\uzun.a.i\PycharmProjects\PythonProject\.venv\Lib\site-packages\urllib3\util\util.py", line 39, in reraise
    raise value
  File "C:\Users\uzun.a.i\PycharmProjects\PythonProject\.venv\Lib\site-packages\urllib3\connectionpool.py", line 787, in urlopen
    response = self._make_request(
        conn,
    ...<10 lines>...
        **response_kw,
    )
  File "C:\Users\uzun.a.i\PycharmProjects\PythonProject\.venv\Lib\site-packages\urllib3\connectionpool.py", line 493, in _make_request
    conn.request(
    ~~~~~~~~~~~~^
        method,
        ^^^^^^^
    ...<6 lines>...
        enforce_content_length=enforce_content_length,
        ^^^^^^^^^^^^^^^^^^^^^^^^^^^^^^^^^^^^^^^^^^^^^^
    )
    ^
  File "C:\Users\uzun.a.i\PycharmProjects\PythonProject\.venv\Lib\site-packages\urllib3\connection.py", line 494, in request
    self.endheaders()
    ~~~~~~~~~~~~~~~^^
  File "C:\Users\uzun.a.i\AppData\Local\Programs\Python\Python313\Lib\http\client.py", line 1333, in endheaders
    self._send_output(message_body, encode_chunked=encode_chunked)
    ~~~~~~~~~~~~~~~~~^^^^^^^^^^^^^^^^^^^^^^^^^^^^^^^^^^^^^^^^^^^^^
  File "C:\Users\uzun.a.i\AppData\Local\Programs\Python\Python313\Lib\http\client.py", line 1093, in _send_output
    self.send(msg)
    ~~~~~~~~~^^^^^
  File "C:\Users\uzun.a.i\AppData\Local\Programs\Python\Python313\Lib\http\client.py", line 1037, in send
    self.connect()
    ~~~~~~~~~~~~^^
  File "C:\Users\uzun.a.i\PycharmProjects\PythonProject\.venv\Lib\site-packages\urllib3\connection.py", line 325, in connect
    self.sock = self._new_conn()
                ~~~~~~~~~~~~~~^^
  File "C:\Users\uzun.a.i\PycharmProjects\PythonProject\.venv\Lib\site-packages\urllib3\connection.py", line 213, in _new_conn
    raise NewConnectionError(
        self, f"Failed to establish a new connection: {e}"
    ) from e
urllib3.exceptions.NewConnectionError: <urllib3.connection.HTTPConnection object at 0x0000016D36F74CD0>: Failed to establish a new connection: [WinError 10061] Подключение не установлено, т.к. конечный компьютер отверг запрос на подключение

The above exception was the direct cause of the following exception:

Traceback (most recent call last):
  File "C:\Users\uzun.a.i\PycharmProjects\PythonProject\.venv\Lib\site-packages\elastic_transport\_transport.py", line 342, in perform_request
    resp = node.perform_request(
        method,
    ...<3 lines>...
        request_timeout=request_timeout,
    )
  File "C:\Users\uzun.a.i\PycharmProjects\PythonProject\.venv\Lib\site-packages\elastic_transport\_node\_http_urllib3.py", line 202, in perform_request
    raise err from e
elastic_transport.ConnectionError: Connection error caused by: NewConnectionError(<urllib3.connection.HTTPConnection object at 0x0000016D36F74CD0>: Failed to establish a new connection: [WinError 10061] Подключение не установлено, т.к. конечный компьютер отверг запрос на подключение)
2025-09-04 20:12:56,793 - elastic_transport.node_pool - INFO - Resurrected node <Urllib3HttpNode(http://localhost:9200)> (force=False)
2025-09-04 20:13:00,873 - elastic_transport.transport - INFO - HEAD http://localhost:9200/ [status:N/A duration:4.079s]
2025-09-04 20:13:00,873 - elastic_transport.node_pool - WARNING - Node <Urllib3HttpNode(http://localhost:9200)> has failed for 3 times in a row, putting on 4 second timeout
2025-09-04 20:13:00,873 - elastic_transport.transport - WARNING - Retrying request after failure (attempt 2 of 3)
Traceback (most recent call last):
  File "C:\Users\uzun.a.i\PycharmProjects\PythonProject\.venv\Lib\site-packages\urllib3\connection.py", line 198, in _new_conn
    sock = connection.create_connection(
        (self._dns_host, self.port),
    ...<2 lines>...
        socket_options=self.socket_options,
    )
  File "C:\Users\uzun.a.i\PycharmProjects\PythonProject\.venv\Lib\site-packages\urllib3\util\connection.py", line 85, in create_connection
    raise err
  File "C:\Users\uzun.a.i\PycharmProjects\PythonProject\.venv\Lib\site-packages\urllib3\util\connection.py", line 73, in create_connection
    sock.connect(sa)
    ~~~~~~~~~~~~^^^^
ConnectionRefusedError: [WinError 10061] Подключение не установлено, т.к. конечный компьютер отверг запрос на подключение

The above exception was the direct cause of the following exception:

Traceback (most recent call last):
  File "C:\Users\uzun.a.i\PycharmProjects\PythonProject\.venv\Lib\site-packages\elastic_transport\_node\_http_urllib3.py", line 167, in perform_request
    response = self.pool.urlopen(
        method,
    ...<4 lines>...
        **kw,  # type: ignore[arg-type]
    )
  File "C:\Users\uzun.a.i\PycharmProjects\PythonProject\.venv\Lib\site-packages\urllib3\connectionpool.py", line 841, in urlopen
    retries = retries.increment(
        method, url, error=new_e, _pool=self, _stacktrace=sys.exc_info()[2]
    )
  File "C:\Users\uzun.a.i\PycharmProjects\PythonProject\.venv\Lib\site-packages\urllib3\util\retry.py", line 449, in increment
    raise reraise(type(error), error, _stacktrace)
          ~~~~~~~^^^^^^^^^^^^^^^^^^^^^^^^^^^^^^^^^
  File "C:\Users\uzun.a.i\PycharmProjects\PythonProject\.venv\Lib\site-packages\urllib3\util\util.py", line 39, in reraise
    raise value
  File "C:\Users\uzun.a.i\PycharmProjects\PythonProject\.venv\Lib\site-packages\urllib3\connectionpool.py", line 787, in urlopen
    response = self._make_request(
        conn,
    ...<10 lines>...
        **response_kw,
    )
  File "C:\Users\uzun.a.i\PycharmProjects\PythonProject\.venv\Lib\site-packages\urllib3\connectionpool.py", line 493, in _make_request
    conn.request(
    ~~~~~~~~~~~~^
        method,
        ^^^^^^^
    ...<6 lines>...
        enforce_content_length=enforce_content_length,
        ^^^^^^^^^^^^^^^^^^^^^^^^^^^^^^^^^^^^^^^^^^^^^^
    )
    ^
  File "C:\Users\uzun.a.i\PycharmProjects\PythonProject\.venv\Lib\site-packages\urllib3\connection.py", line 494, in request
    self.endheaders()
    ~~~~~~~~~~~~~~~^^
  File "C:\Users\uzun.a.i\AppData\Local\Programs\Python\Python313\Lib\http\client.py", line 1333, in endheaders
    self._send_output(message_body, encode_chunked=encode_chunked)
    ~~~~~~~~~~~~~~~~~^^^^^^^^^^^^^^^^^^^^^^^^^^^^^^^^^^^^^^^^^^^^^
  File "C:\Users\uzun.a.i\AppData\Local\Programs\Python\Python313\Lib\http\client.py", line 1093, in _send_output
    self.send(msg)
    ~~~~~~~~~^^^^^
  File "C:\Users\uzun.a.i\AppData\Local\Programs\Python\Python313\Lib\http\client.py", line 1037, in send
    self.connect()
    ~~~~~~~~~~~~^^
  File "C:\Users\uzun.a.i\PycharmProjects\PythonProject\.venv\Lib\site-packages\urllib3\connection.py", line 325, in connect
    self.sock = self._new_conn()
                ~~~~~~~~~~~~~~^^
  File "C:\Users\uzun.a.i\PycharmProjects\PythonProject\.venv\Lib\site-packages\urllib3\connection.py", line 213, in _new_conn
    raise NewConnectionError(
        self, f"Failed to establish a new connection: {e}"
    ) from e
urllib3.exceptions.NewConnectionError: <urllib3.connection.HTTPConnection object at 0x0000016D36F74F50>: Failed to establish a new connection: [WinError 10061] Подключение не установлено, т.к. конечный компьютер отверг запрос на подключение

The above exception was the direct cause of the following exception:

Traceback (most recent call last):
  File "C:\Users\uzun.a.i\PycharmProjects\PythonProject\.venv\Lib\site-packages\elastic_transport\_transport.py", line 342, in perform_request
    resp = node.perform_request(
        method,
    ...<3 lines>...
        request_timeout=request_timeout,
    )
  File "C:\Users\uzun.a.i\PycharmProjects\PythonProject\.venv\Lib\site-packages\elastic_transport\_node\_http_urllib3.py", line 202, in perform_request
    raise err from e
elastic_transport.ConnectionError: Connection error caused by: NewConnectionError(<urllib3.connection.HTTPConnection object at 0x0000016D36F74F50>: Failed to establish a new connection: [WinError 10061] Подключение не установлено, т.к. конечный компьютер отверг запрос на подключение)
2025-09-04 20:13:00,875 - elastic_transport.node_pool - INFO - Resurrected node <Urllib3HttpNode(http://localhost:9200)> (force=False)
2025-09-04 20:13:04,975 - elastic_transport.transport - INFO - HEAD http://localhost:9200/ [status:N/A duration:4.099s]
2025-09-04 20:13:04,975 - elastic_transport.node_pool - WARNING - Node <Urllib3HttpNode(http://localhost:9200)> has failed for 4 times in a row, putting on 8 second timeout
2025-09-04 20:13:04,975 - src.material_matcher_app - WARNING - Cannot connect to Elasticsearch. Some features may not work.
2025-09-04 20:13:04,975 - src.material_matcher_app - INFO - MaterialMatcher application initialized successfully
2025-09-04 20:13:04,975 - elastic_transport.node_pool - INFO - Resurrected node <Urllib3HttpNode(http://localhost:9200)> (force=False)
2025-09-04 20:13:09,068 - elastic_transport.transport - INFO - HEAD http://localhost:9200/ [status:N/A duration:4.092s]
2025-09-04 20:13:09,068 - elastic_transport.node_pool - WARNING - Node <Urllib3HttpNode(http://localhost:9200)> has failed for 5 times in a row, putting on 16 second timeout
2025-09-04 20:13:09,068 - elastic_transport.transport - WARNING - Retrying request after failure (attempt 0 of 3)
Traceback (most recent call last):
  File "C:\Users\uzun.a.i\PycharmProjects\PythonProject\.venv\Lib\site-packages\urllib3\connection.py", line 198, in _new_conn
    sock = connection.create_connection(
        (self._dns_host, self.port),
    ...<2 lines>...
        socket_options=self.socket_options,
    )
  File "C:\Users\uzun.a.i\PycharmProjects\PythonProject\.venv\Lib\site-packages\urllib3\util\connection.py", line 85, in create_connection
    raise err
  File "C:\Users\uzun.a.i\PycharmProjects\PythonProject\.venv\Lib\site-packages\urllib3\util\connection.py", line 73, in create_connection
    sock.connect(sa)
    ~~~~~~~~~~~~^^^^
ConnectionRefusedError: [WinError 10061] Подключение не установлено, т.к. конечный компьютер отверг запрос на подключение

The above exception was the direct cause of the following exception:

Traceback (most recent call last):
  File "C:\Users\uzun.a.i\PycharmProjects\PythonProject\.venv\Lib\site-packages\elastic_transport\_node\_http_urllib3.py", line 167, in perform_request
    response = self.pool.urlopen(
        method,
    ...<4 lines>...
        **kw,  # type: ignore[arg-type]
    )
  File "C:\Users\uzun.a.i\PycharmProjects\PythonProject\.venv\Lib\site-packages\urllib3\connectionpool.py", line 841, in urlopen
    retries = retries.increment(
        method, url, error=new_e, _pool=self, _stacktrace=sys.exc_info()[2]
    )
  File "C:\Users\uzun.a.i\PycharmProjects\PythonProject\.venv\Lib\site-packages\urllib3\util\retry.py", line 449, in increment
    raise reraise(type(error), error, _stacktrace)
          ~~~~~~~^^^^^^^^^^^^^^^^^^^^^^^^^^^^^^^^^
  File "C:\Users\uzun.a.i\PycharmProjects\PythonProject\.venv\Lib\site-packages\urllib3\util\util.py", line 39, in reraise
    raise value
  File "C:\Users\uzun.a.i\PycharmProjects\PythonProject\.venv\Lib\site-packages\urllib3\connectionpool.py", line 787, in urlopen
    response = self._make_request(
        conn,
    ...<10 lines>...
        **response_kw,
    )
  File "C:\Users\uzun.a.i\PycharmProjects\PythonProject\.venv\Lib\site-packages\urllib3\connectionpool.py", line 493, in _make_request
    conn.request(
    ~~~~~~~~~~~~^
        method,
        ^^^^^^^
    ...<6 lines>...
        enforce_content_length=enforce_content_length,
        ^^^^^^^^^^^^^^^^^^^^^^^^^^^^^^^^^^^^^^^^^^^^^^
    )
    ^
  File "C:\Users\uzun.a.i\PycharmProjects\PythonProject\.venv\Lib\site-packages\urllib3\connection.py", line 494, in request
    self.endheaders()
    ~~~~~~~~~~~~~~~^^
  File "C:\Users\uzun.a.i\AppData\Local\Programs\Python\Python313\Lib\http\client.py", line 1333, in endheaders
    self._send_output(message_body, encode_chunked=encode_chunked)
    ~~~~~~~~~~~~~~~~~^^^^^^^^^^^^^^^^^^^^^^^^^^^^^^^^^^^^^^^^^^^^^
  File "C:\Users\uzun.a.i\AppData\Local\Programs\Python\Python313\Lib\http\client.py", line 1093, in _send_output
    self.send(msg)
    ~~~~~~~~~^^^^^
  File "C:\Users\uzun.a.i\AppData\Local\Programs\Python\Python313\Lib\http\client.py", line 1037, in send
    self.connect()
    ~~~~~~~~~~~~^^
  File "C:\Users\uzun.a.i\PycharmProjects\PythonProject\.venv\Lib\site-packages\urllib3\connection.py", line 325, in connect
    self.sock = self._new_conn()
                ~~~~~~~~~~~~~~^^
  File "C:\Users\uzun.a.i\PycharmProjects\PythonProject\.venv\Lib\site-packages\urllib3\connection.py", line 213, in _new_conn
    raise NewConnectionError(
        self, f"Failed to establish a new connection: {e}"
    ) from e
urllib3.exceptions.NewConnectionError: <urllib3.connection.HTTPConnection object at 0x0000016D36ED7CE0>: Failed to establish a new connection: [WinError 10061] Подключение не установлено, т.к. конечный компьютер отверг запрос на подключение

The above exception was the direct cause of the following exception:

Traceback (most recent call last):
  File "C:\Users\uzun.a.i\PycharmProjects\PythonProject\.venv\Lib\site-packages\elastic_transport\_transport.py", line 342, in perform_request
    resp = node.perform_request(
        method,
    ...<3 lines>...
        request_timeout=request_timeout,
    )
  File "C:\Users\uzun.a.i\PycharmProjects\PythonProject\.venv\Lib\site-packages\elastic_transport\_node\_http_urllib3.py", line 202, in perform_request
    raise err from e
elastic_transport.ConnectionError: Connection error caused by: NewConnectionError(<urllib3.connection.HTTPConnection object at 0x0000016D36ED7CE0>: Failed to establish a new connection: [WinError 10061] Подключение не установлено, т.к. конечный компьютер отверг запрос на подключение)
2025-09-04 20:13:13,128 - elastic_transport.transport - INFO - HEAD http://localhost:9200/ [status:N/A duration:4.057s]
2025-09-04 20:13:13,128 - elastic_transport.node_pool - WARNING - Node <Urllib3HttpNode(http://localhost:9200)> has failed for 6 times in a row, putting on 30 second timeout
2025-09-04 20:13:13,128 - elastic_transport.transport - WARNING - Retrying request after failure (attempt 1 of 3)
Traceback (most recent call last):
  File "C:\Users\uzun.a.i\PycharmProjects\PythonProject\.venv\Lib\site-packages\urllib3\connection.py", line 198, in _new_conn
    sock = connection.create_connection(
        (self._dns_host, self.port),
    ...<2 lines>...
        socket_options=self.socket_options,
    )
  File "C:\Users\uzun.a.i\PycharmProjects\PythonProject\.venv\Lib\site-packages\urllib3\util\connection.py", line 85, in create_connection
    raise err
  File "C:\Users\uzun.a.i\PycharmProjects\PythonProject\.venv\Lib\site-packages\urllib3\util\connection.py", line 73, in create_connection
    sock.connect(sa)
    ~~~~~~~~~~~~^^^^
ConnectionRefusedError: [WinError 10061] Подключение не установлено, т.к. конечный компьютер отверг запрос на подключение

The above exception was the direct cause of the following exception:

Traceback (most recent call last):
  File "C:\Users\uzun.a.i\PycharmProjects\PythonProject\.venv\Lib\site-packages\elastic_transport\_node\_http_urllib3.py", line 167, in perform_request
    response = self.pool.urlopen(
        method,
    ...<4 lines>...
        **kw,  # type: ignore[arg-type]
    )
  File "C:\Users\uzun.a.i\PycharmProjects\PythonProject\.venv\Lib\site-packages\urllib3\connectionpool.py", line 841, in urlopen
    retries = retries.increment(
        method, url, error=new_e, _pool=self, _stacktrace=sys.exc_info()[2]
    )
  File "C:\Users\uzun.a.i\PycharmProjects\PythonProject\.venv\Lib\site-packages\urllib3\util\retry.py", line 449, in increment
    raise reraise(type(error), error, _stacktrace)
          ~~~~~~~^^^^^^^^^^^^^^^^^^^^^^^^^^^^^^^^^
  File "C:\Users\uzun.a.i\PycharmProjects\PythonProject\.venv\Lib\site-packages\urllib3\util\util.py", line 39, in reraise
    raise value
  File "C:\Users\uzun.a.i\PycharmProjects\PythonProject\.venv\Lib\site-packages\urllib3\connectionpool.py", line 787, in urlopen
    response = self._make_request(
        conn,
    ...<10 lines>...
        **response_kw,
    )
  File "C:\Users\uzun.a.i\PycharmProjects\PythonProject\.venv\Lib\site-packages\urllib3\connectionpool.py", line 493, in _make_request
    conn.request(
    ~~~~~~~~~~~~^
        method,
        ^^^^^^^
    ...<6 lines>...
        enforce_content_length=enforce_content_length,
        ^^^^^^^^^^^^^^^^^^^^^^^^^^^^^^^^^^^^^^^^^^^^^^
    )
    ^
  File "C:\Users\uzun.a.i\PycharmProjects\PythonProject\.venv\Lib\site-packages\urllib3\connection.py", line 494, in request
    self.endheaders()
    ~~~~~~~~~~~~~~~^^
  File "C:\Users\uzun.a.i\AppData\Local\Programs\Python\Python313\Lib\http\client.py", line 1333, in endheaders
    self._send_output(message_body, encode_chunked=encode_chunked)
    ~~~~~~~~~~~~~~~~~^^^^^^^^^^^^^^^^^^^^^^^^^^^^^^^^^^^^^^^^^^^^^
  File "C:\Users\uzun.a.i\AppData\Local\Programs\Python\Python313\Lib\http\client.py", line 1093, in _send_output
    self.send(msg)
    ~~~~~~~~~^^^^^
  File "C:\Users\uzun.a.i\AppData\Local\Programs\Python\Python313\Lib\http\client.py", line 1037, in send
    self.connect()
    ~~~~~~~~~~~~^^
  File "C:\Users\uzun.a.i\PycharmProjects\PythonProject\.venv\Lib\site-packages\urllib3\connection.py", line 325, in connect
    self.sock = self._new_conn()
                ~~~~~~~~~~~~~~^^
  File "C:\Users\uzun.a.i\PycharmProjects\PythonProject\.venv\Lib\site-packages\urllib3\connection.py", line 213, in _new_conn
    raise NewConnectionError(
        self, f"Failed to establish a new connection: {e}"
    ) from e
urllib3.exceptions.NewConnectionError: <urllib3.connection.HTTPConnection object at 0x0000016D36EEEF90>: Failed to establish a new connection: [WinError 10061] Подключение не установлено, т.к. конечный компьютер отверг запрос на подключение

The above exception was the direct cause of the following exception:

Traceback (most recent call last):
  File "C:\Users\uzun.a.i\PycharmProjects\PythonProject\.venv\Lib\site-packages\elastic_transport\_transport.py", line 342, in perform_request
    resp = node.perform_request(
        method,
    ...<3 lines>...
        request_timeout=request_timeout,
    )
  File "C:\Users\uzun.a.i\PycharmProjects\PythonProject\.venv\Lib\site-packages\elastic_transport\_node\_http_urllib3.py", line 202, in perform_request
    raise err from e
elastic_transport.ConnectionError: Connection error caused by: NewConnectionError(<urllib3.connection.HTTPConnection object at 0x0000016D36EEEF90>: Failed to establish a new connection: [WinError 10061] Подключение не установлено, т.к. конечный компьютер отверг запрос на подключение)
2025-09-04 20:13:13,131 - elastic_transport.node_pool - INFO - Resurrected node <Urllib3HttpNode(http://localhost:9200)> (force=False)
2025-09-04 20:13:17,233 - elastic_transport.transport - INFO - HEAD http://localhost:9200/ [status:N/A duration:4.103s]
2025-09-04 20:13:17,234 - elastic_transport.node_pool - WARNING - Node <Urllib3HttpNode(http://localhost:9200)> has failed for 7 times in a row, putting on 30 second timeout
2025-09-04 20:13:17,234 - elastic_transport.transport - WARNING - Retrying request after failure (attempt 2 of 3)
Traceback (most recent call last):
  File "C:\Users\uzun.a.i\PycharmProjects\PythonProject\.venv\Lib\site-packages\urllib3\connection.py", line 198, in _new_conn
    sock = connection.create_connection(
        (self._dns_host, self.port),
    ...<2 lines>...
        socket_options=self.socket_options,
    )
  File "C:\Users\uzun.a.i\PycharmProjects\PythonProject\.venv\Lib\site-packages\urllib3\util\connection.py", line 85, in create_connection
    raise err
  File "C:\Users\uzun.a.i\PycharmProjects\PythonProject\.venv\Lib\site-packages\urllib3\util\connection.py", line 73, in create_connection
    sock.connect(sa)
    ~~~~~~~~~~~~^^^^
ConnectionRefusedError: [WinError 10061] Подключение не установлено, т.к. конечный компьютер отверг запрос на подключение

The above exception was the direct cause of the following exception:

Traceback (most recent call last):
  File "C:\Users\uzun.a.i\PycharmProjects\PythonProject\.venv\Lib\site-packages\elastic_transport\_node\_http_urllib3.py", line 167, in perform_request
    response = self.pool.urlopen(
        method,
    ...<4 lines>...
        **kw,  # type: ignore[arg-type]
    )
  File "C:\Users\uzun.a.i\PycharmProjects\PythonProject\.venv\Lib\site-packages\urllib3\connectionpool.py", line 841, in urlopen
    retries = retries.increment(
        method, url, error=new_e, _pool=self, _stacktrace=sys.exc_info()[2]
    )
  File "C:\Users\uzun.a.i\PycharmProjects\PythonProject\.venv\Lib\site-packages\urllib3\util\retry.py", line 449, in increment
    raise reraise(type(error), error, _stacktrace)
          ~~~~~~~^^^^^^^^^^^^^^^^^^^^^^^^^^^^^^^^^
  File "C:\Users\uzun.a.i\PycharmProjects\PythonProject\.venv\Lib\site-packages\urllib3\util\util.py", line 39, in reraise
    raise value
  File "C:\Users\uzun.a.i\PycharmProjects\PythonProject\.venv\Lib\site-packages\urllib3\connectionpool.py", line 787, in urlopen
    response = self._make_request(
        conn,
    ...<10 lines>...
        **response_kw,
    )
  File "C:\Users\uzun.a.i\PycharmProjects\PythonProject\.venv\Lib\site-packages\urllib3\connectionpool.py", line 493, in _make_request
    conn.request(
    ~~~~~~~~~~~~^
        method,
        ^^^^^^^
    ...<6 lines>...
        enforce_content_length=enforce_content_length,
        ^^^^^^^^^^^^^^^^^^^^^^^^^^^^^^^^^^^^^^^^^^^^^^
    )
    ^
  File "C:\Users\uzun.a.i\PycharmProjects\PythonProject\.venv\Lib\site-packages\urllib3\connection.py", line 494, in request
    self.endheaders()
    ~~~~~~~~~~~~~~~^^
  File "C:\Users\uzun.a.i\AppData\Local\Programs\Python\Python313\Lib\http\client.py", line 1333, in endheaders
    self._send_output(message_body, encode_chunked=encode_chunked)
    ~~~~~~~~~~~~~~~~~^^^^^^^^^^^^^^^^^^^^^^^^^^^^^^^^^^^^^^^^^^^^^
  File "C:\Users\uzun.a.i\AppData\Local\Programs\Python\Python313\Lib\http\client.py", line 1093, in _send_output
    self.send(msg)
    ~~~~~~~~~^^^^^
  File "C:\Users\uzun.a.i\AppData\Local\Programs\Python\Python313\Lib\http\client.py", line 1037, in send
    self.connect()
    ~~~~~~~~~~~~^^
  File "C:\Users\uzun.a.i\PycharmProjects\PythonProject\.venv\Lib\site-packages\urllib3\connection.py", line 325, in connect
    self.sock = self._new_conn()
                ~~~~~~~~~~~~~~^^
  File "C:\Users\uzun.a.i\PycharmProjects\PythonProject\.venv\Lib\site-packages\urllib3\connection.py", line 213, in _new_conn
    raise NewConnectionError(
        self, f"Failed to establish a new connection: {e}"
    ) from e
urllib3.exceptions.NewConnectionError: <urllib3.connection.HTTPConnection object at 0x0000016D36F45590>: Failed to establish a new connection: [WinError 10061] Подключение не установлено, т.к. конечный компьютер отверг запрос на подключение

The above exception was the direct cause of the following exception:

Traceback (most recent call last):
  File "C:\Users\uzun.a.i\PycharmProjects\PythonProject\.venv\Lib\site-packages\elastic_transport\_transport.py", line 342, in perform_request
    resp = node.perform_request(
        method,
    ...<3 lines>...
        request_timeout=request_timeout,
    )
  File "C:\Users\uzun.a.i\PycharmProjects\PythonProject\.venv\Lib\site-packages\elastic_transport\_node\_http_urllib3.py", line 202, in perform_request
    raise err from e
elastic_transport.ConnectionError: Connection error caused by: NewConnectionError(<urllib3.connection.HTTPConnection object at 0x0000016D36F45590>: Failed to establish a new connection: [WinError 10061] Подключение не установлено, т.к. конечный компьютер отверг запрос на подключение)
2025-09-04 20:13:21,342 - elastic_transport.transport - INFO - HEAD http://localhost:9200/ [status:N/A duration:4.105s]
2025-09-04 20:13:21,342 - elastic_transport.node_pool - WARNING - Node <Urllib3HttpNode(http://localhost:9200)> has failed for 8 times in a row, putting on 30 second timeout
2025-09-04 20:14:38,270 - src.services.elasticsearch_service - INFO - Initialized Elasticsearch connection to localhost:9200
2025-09-04 20:14:42,326 - elastic_transport.transport - INFO - HEAD http://localhost:9200/ [status:N/A duration:4.056s]
2025-09-04 20:14:42,327 - elastic_transport.node_pool - WARNING - Node <Urllib3HttpNode(http://localhost:9200)> has failed for 1 times in a row, putting on 1 second timeout
2025-09-04 20:14:42,327 - elastic_transport.transport - WARNING - Retrying request after failure (attempt 0 of 3)
Traceback (most recent call last):
  File "C:\Users\uzun.a.i\PycharmProjects\PythonProject\.venv\Lib\site-packages\urllib3\connection.py", line 198, in _new_conn
    sock = connection.create_connection(
        (self._dns_host, self.port),
    ...<2 lines>...
        socket_options=self.socket_options,
    )
  File "C:\Users\uzun.a.i\PycharmProjects\PythonProject\.venv\Lib\site-packages\urllib3\util\connection.py", line 85, in create_connection
    raise err
  File "C:\Users\uzun.a.i\PycharmProjects\PythonProject\.venv\Lib\site-packages\urllib3\util\connection.py", line 73, in create_connection
    sock.connect(sa)
    ~~~~~~~~~~~~^^^^
ConnectionRefusedError: [WinError 10061] Подключение не установлено, т.к. конечный компьютер отверг запрос на подключение

The above exception was the direct cause of the following exception:

Traceback (most recent call last):
  File "C:\Users\uzun.a.i\PycharmProjects\PythonProject\.venv\Lib\site-packages\elastic_transport\_node\_http_urllib3.py", line 167, in perform_request
    response = self.pool.urlopen(
        method,
    ...<4 lines>...
        **kw,  # type: ignore[arg-type]
    )
  File "C:\Users\uzun.a.i\PycharmProjects\PythonProject\.venv\Lib\site-packages\urllib3\connectionpool.py", line 841, in urlopen
    retries = retries.increment(
        method, url, error=new_e, _pool=self, _stacktrace=sys.exc_info()[2]
    )
  File "C:\Users\uzun.a.i\PycharmProjects\PythonProject\.venv\Lib\site-packages\urllib3\util\retry.py", line 449, in increment
    raise reraise(type(error), error, _stacktrace)
          ~~~~~~~^^^^^^^^^^^^^^^^^^^^^^^^^^^^^^^^^
  File "C:\Users\uzun.a.i\PycharmProjects\PythonProject\.venv\Lib\site-packages\urllib3\util\util.py", line 39, in reraise
    raise value
  File "C:\Users\uzun.a.i\PycharmProjects\PythonProject\.venv\Lib\site-packages\urllib3\connectionpool.py", line 787, in urlopen
    response = self._make_request(
        conn,
    ...<10 lines>...
        **response_kw,
    )
  File "C:\Users\uzun.a.i\PycharmProjects\PythonProject\.venv\Lib\site-packages\urllib3\connectionpool.py", line 493, in _make_request
    conn.request(
    ~~~~~~~~~~~~^
        method,
        ^^^^^^^
    ...<6 lines>...
        enforce_content_length=enforce_content_length,
        ^^^^^^^^^^^^^^^^^^^^^^^^^^^^^^^^^^^^^^^^^^^^^^
    )
    ^
  File "C:\Users\uzun.a.i\PycharmProjects\PythonProject\.venv\Lib\site-packages\urllib3\connection.py", line 494, in request
    self.endheaders()
    ~~~~~~~~~~~~~~~^^
  File "C:\Users\uzun.a.i\AppData\Local\Programs\Python\Python313\Lib\http\client.py", line 1333, in endheaders
    self._send_output(message_body, encode_chunked=encode_chunked)
    ~~~~~~~~~~~~~~~~~^^^^^^^^^^^^^^^^^^^^^^^^^^^^^^^^^^^^^^^^^^^^^
  File "C:\Users\uzun.a.i\AppData\Local\Programs\Python\Python313\Lib\http\client.py", line 1093, in _send_output
    self.send(msg)
    ~~~~~~~~~^^^^^
  File "C:\Users\uzun.a.i\AppData\Local\Programs\Python\Python313\Lib\http\client.py", line 1037, in send
    self.connect()
    ~~~~~~~~~~~~^^
  File "C:\Users\uzun.a.i\PycharmProjects\PythonProject\.venv\Lib\site-packages\urllib3\connection.py", line 325, in connect
    self.sock = self._new_conn()
                ~~~~~~~~~~~~~~^^
  File "C:\Users\uzun.a.i\PycharmProjects\PythonProject\.venv\Lib\site-packages\urllib3\connection.py", line 213, in _new_conn
    raise NewConnectionError(
        self, f"Failed to establish a new connection: {e}"
    ) from e
urllib3.exceptions.NewConnectionError: <urllib3.connection.HTTPConnection object at 0x000002A05898B380>: Failed to establish a new connection: [WinError 10061] Подключение не установлено, т.к. конечный компьютер отверг запрос на подключение

The above exception was the direct cause of the following exception:

Traceback (most recent call last):
  File "C:\Users\uzun.a.i\PycharmProjects\PythonProject\.venv\Lib\site-packages\elastic_transport\_transport.py", line 342, in perform_request
    resp = node.perform_request(
        method,
    ...<3 lines>...
        request_timeout=request_timeout,
    )
  File "C:\Users\uzun.a.i\PycharmProjects\PythonProject\.venv\Lib\site-packages\elastic_transport\_node\_http_urllib3.py", line 202, in perform_request
    raise err from e
elastic_transport.ConnectionError: Connection error caused by: NewConnectionError(<urllib3.connection.HTTPConnection object at 0x000002A05898B380>: Failed to establish a new connection: [WinError 10061] Подключение не установлено, т.к. конечный компьютер отверг запрос на подключение)
2025-09-04 20:14:46,425 - elastic_transport.transport - INFO - HEAD http://localhost:9200/ [status:N/A duration:4.093s]
2025-09-04 20:14:46,425 - elastic_transport.node_pool - WARNING - Node <Urllib3HttpNode(http://localhost:9200)> has failed for 2 times in a row, putting on 2 second timeout
2025-09-04 20:14:46,425 - elastic_transport.transport - WARNING - Retrying request after failure (attempt 1 of 3)
Traceback (most recent call last):
  File "C:\Users\uzun.a.i\PycharmProjects\PythonProject\.venv\Lib\site-packages\urllib3\connection.py", line 198, in _new_conn
    sock = connection.create_connection(
        (self._dns_host, self.port),
    ...<2 lines>...
        socket_options=self.socket_options,
    )
  File "C:\Users\uzun.a.i\PycharmProjects\PythonProject\.venv\Lib\site-packages\urllib3\util\connection.py", line 85, in create_connection
    raise err
  File "C:\Users\uzun.a.i\PycharmProjects\PythonProject\.venv\Lib\site-packages\urllib3\util\connection.py", line 73, in create_connection
    sock.connect(sa)
    ~~~~~~~~~~~~^^^^
ConnectionRefusedError: [WinError 10061] Подключение не установлено, т.к. конечный компьютер отверг запрос на подключение

The above exception was the direct cause of the following exception:

Traceback (most recent call last):
  File "C:\Users\uzun.a.i\PycharmProjects\PythonProject\.venv\Lib\site-packages\elastic_transport\_node\_http_urllib3.py", line 167, in perform_request
    response = self.pool.urlopen(
        method,
    ...<4 lines>...
        **kw,  # type: ignore[arg-type]
    )
  File "C:\Users\uzun.a.i\PycharmProjects\PythonProject\.venv\Lib\site-packages\urllib3\connectionpool.py", line 841, in urlopen
    retries = retries.increment(
        method, url, error=new_e, _pool=self, _stacktrace=sys.exc_info()[2]
    )
  File "C:\Users\uzun.a.i\PycharmProjects\PythonProject\.venv\Lib\site-packages\urllib3\util\retry.py", line 449, in increment
    raise reraise(type(error), error, _stacktrace)
          ~~~~~~~^^^^^^^^^^^^^^^^^^^^^^^^^^^^^^^^^
  File "C:\Users\uzun.a.i\PycharmProjects\PythonProject\.venv\Lib\site-packages\urllib3\util\util.py", line 39, in reraise
    raise value
  File "C:\Users\uzun.a.i\PycharmProjects\PythonProject\.venv\Lib\site-packages\urllib3\connectionpool.py", line 787, in urlopen
    response = self._make_request(
        conn,
    ...<10 lines>...
        **response_kw,
    )
  File "C:\Users\uzun.a.i\PycharmProjects\PythonProject\.venv\Lib\site-packages\urllib3\connectionpool.py", line 493, in _make_request
    conn.request(
    ~~~~~~~~~~~~^
        method,
        ^^^^^^^
    ...<6 lines>...
        enforce_content_length=enforce_content_length,
        ^^^^^^^^^^^^^^^^^^^^^^^^^^^^^^^^^^^^^^^^^^^^^^
    )
    ^
  File "C:\Users\uzun.a.i\PycharmProjects\PythonProject\.venv\Lib\site-packages\urllib3\connection.py", line 494, in request
    self.endheaders()
    ~~~~~~~~~~~~~~~^^
  File "C:\Users\uzun.a.i\AppData\Local\Programs\Python\Python313\Lib\http\client.py", line 1333, in endheaders
    self._send_output(message_body, encode_chunked=encode_chunked)
    ~~~~~~~~~~~~~~~~~^^^^^^^^^^^^^^^^^^^^^^^^^^^^^^^^^^^^^^^^^^^^^
  File "C:\Users\uzun.a.i\AppData\Local\Programs\Python\Python313\Lib\http\client.py", line 1093, in _send_output
    self.send(msg)
    ~~~~~~~~~^^^^^
  File "C:\Users\uzun.a.i\AppData\Local\Programs\Python\Python313\Lib\http\client.py", line 1037, in send
    self.connect()
    ~~~~~~~~~~~~^^
  File "C:\Users\uzun.a.i\PycharmProjects\PythonProject\.venv\Lib\site-packages\urllib3\connection.py", line 325, in connect
    self.sock = self._new_conn()
                ~~~~~~~~~~~~~~^^
  File "C:\Users\uzun.a.i\PycharmProjects\PythonProject\.venv\Lib\site-packages\urllib3\connection.py", line 213, in _new_conn
    raise NewConnectionError(
        self, f"Failed to establish a new connection: {e}"
    ) from e
urllib3.exceptions.NewConnectionError: <urllib3.connection.HTTPConnection object at 0x000002A058980CD0>: Failed to establish a new connection: [WinError 10061] Подключение не установлено, т.к. конечный компьютер отверг запрос на подключение

The above exception was the direct cause of the following exception:

Traceback (most recent call last):
  File "C:\Users\uzun.a.i\PycharmProjects\PythonProject\.venv\Lib\site-packages\elastic_transport\_transport.py", line 342, in perform_request
    resp = node.perform_request(
        method,
    ...<3 lines>...
        request_timeout=request_timeout,
    )
  File "C:\Users\uzun.a.i\PycharmProjects\PythonProject\.venv\Lib\site-packages\elastic_transport\_node\_http_urllib3.py", line 202, in perform_request
    raise err from e
elastic_transport.ConnectionError: Connection error caused by: NewConnectionError(<urllib3.connection.HTTPConnection object at 0x000002A058980CD0>: Failed to establish a new connection: [WinError 10061] Подключение не установлено, т.к. конечный компьютер отверг запрос на подключение)
2025-09-04 20:14:46,428 - elastic_transport.node_pool - INFO - Resurrected node <Urllib3HttpNode(http://localhost:9200)> (force=False)
2025-09-04 20:14:50,528 - elastic_transport.transport - INFO - HEAD http://localhost:9200/ [status:N/A duration:4.100s]
2025-09-04 20:14:50,528 - elastic_transport.node_pool - WARNING - Node <Urllib3HttpNode(http://localhost:9200)> has failed for 3 times in a row, putting on 4 second timeout
2025-09-04 20:14:50,528 - elastic_transport.transport - WARNING - Retrying request after failure (attempt 2 of 3)
Traceback (most recent call last):
  File "C:\Users\uzun.a.i\PycharmProjects\PythonProject\.venv\Lib\site-packages\urllib3\connection.py", line 198, in _new_conn
    sock = connection.create_connection(
        (self._dns_host, self.port),
    ...<2 lines>...
        socket_options=self.socket_options,
    )
  File "C:\Users\uzun.a.i\PycharmProjects\PythonProject\.venv\Lib\site-packages\urllib3\util\connection.py", line 85, in create_connection
    raise err
  File "C:\Users\uzun.a.i\PycharmProjects\PythonProject\.venv\Lib\site-packages\urllib3\util\connection.py", line 73, in create_connection
    sock.connect(sa)
    ~~~~~~~~~~~~^^^^
ConnectionRefusedError: [WinError 10061] Подключение не установлено, т.к. конечный компьютер отверг запрос на подключение

The above exception was the direct cause of the following exception:

Traceback (most recent call last):
  File "C:\Users\uzun.a.i\PycharmProjects\PythonProject\.venv\Lib\site-packages\elastic_transport\_node\_http_urllib3.py", line 167, in perform_request
    response = self.pool.urlopen(
        method,
    ...<4 lines>...
        **kw,  # type: ignore[arg-type]
    )
  File "C:\Users\uzun.a.i\PycharmProjects\PythonProject\.venv\Lib\site-packages\urllib3\connectionpool.py", line 841, in urlopen
    retries = retries.increment(
        method, url, error=new_e, _pool=self, _stacktrace=sys.exc_info()[2]
    )
  File "C:\Users\uzun.a.i\PycharmProjects\PythonProject\.venv\Lib\site-packages\urllib3\util\retry.py", line 449, in increment
    raise reraise(type(error), error, _stacktrace)
          ~~~~~~~^^^^^^^^^^^^^^^^^^^^^^^^^^^^^^^^^
  File "C:\Users\uzun.a.i\PycharmProjects\PythonProject\.venv\Lib\site-packages\urllib3\util\util.py", line 39, in reraise
    raise value
  File "C:\Users\uzun.a.i\PycharmProjects\PythonProject\.venv\Lib\site-packages\urllib3\connectionpool.py", line 787, in urlopen
    response = self._make_request(
        conn,
    ...<10 lines>...
        **response_kw,
    )
  File "C:\Users\uzun.a.i\PycharmProjects\PythonProject\.venv\Lib\site-packages\urllib3\connectionpool.py", line 493, in _make_request
    conn.request(
    ~~~~~~~~~~~~^
        method,
        ^^^^^^^
    ...<6 lines>...
        enforce_content_length=enforce_content_length,
        ^^^^^^^^^^^^^^^^^^^^^^^^^^^^^^^^^^^^^^^^^^^^^^
    )
    ^
  File "C:\Users\uzun.a.i\PycharmProjects\PythonProject\.venv\Lib\site-packages\urllib3\connection.py", line 494, in request
    self.endheaders()
    ~~~~~~~~~~~~~~~^^
  File "C:\Users\uzun.a.i\AppData\Local\Programs\Python\Python313\Lib\http\client.py", line 1333, in endheaders
    self._send_output(message_body, encode_chunked=encode_chunked)
    ~~~~~~~~~~~~~~~~~^^^^^^^^^^^^^^^^^^^^^^^^^^^^^^^^^^^^^^^^^^^^^
  File "C:\Users\uzun.a.i\AppData\Local\Programs\Python\Python313\Lib\http\client.py", line 1093, in _send_output
    self.send(msg)
    ~~~~~~~~~^^^^^
  File "C:\Users\uzun.a.i\AppData\Local\Programs\Python\Python313\Lib\http\client.py", line 1037, in send
    self.connect()
    ~~~~~~~~~~~~^^
  File "C:\Users\uzun.a.i\PycharmProjects\PythonProject\.venv\Lib\site-packages\urllib3\connection.py", line 325, in connect
    self.sock = self._new_conn()
                ~~~~~~~~~~~~~~^^
  File "C:\Users\uzun.a.i\PycharmProjects\PythonProject\.venv\Lib\site-packages\urllib3\connection.py", line 213, in _new_conn
    raise NewConnectionError(
        self, f"Failed to establish a new connection: {e}"
    ) from e
urllib3.exceptions.NewConnectionError: <urllib3.connection.HTTPConnection object at 0x000002A058980F50>: Failed to establish a new connection: [WinError 10061] Подключение не установлено, т.к. конечный компьютер отверг запрос на подключение

The above exception was the direct cause of the following exception:

Traceback (most recent call last):
  File "C:\Users\uzun.a.i\PycharmProjects\PythonProject\.venv\Lib\site-packages\elastic_transport\_transport.py", line 342, in perform_request
    resp = node.perform_request(
        method,
    ...<3 lines>...
        request_timeout=request_timeout,
    )
  File "C:\Users\uzun.a.i\PycharmProjects\PythonProject\.venv\Lib\site-packages\elastic_transport\_node\_http_urllib3.py", line 202, in perform_request
    raise err from e
elastic_transport.ConnectionError: Connection error caused by: NewConnectionError(<urllib3.connection.HTTPConnection object at 0x000002A058980F50>: Failed to establish a new connection: [WinError 10061] Подключение не установлено, т.к. конечный компьютер отверг запрос на подключение)
2025-09-04 20:14:50,533 - elastic_transport.node_pool - INFO - Resurrected node <Urllib3HttpNode(http://localhost:9200)> (force=False)
2025-09-04 20:14:54,620 - elastic_transport.transport - INFO - HEAD http://localhost:9200/ [status:N/A duration:4.087s]
2025-09-04 20:14:54,620 - elastic_transport.node_pool - WARNING - Node <Urllib3HttpNode(http://localhost:9200)> has failed for 4 times in a row, putting on 8 second timeout
2025-09-04 20:14:54,620 - src.material_matcher_app - WARNING - Cannot connect to Elasticsearch. Some features may not work.
2025-09-04 20:14:54,621 - src.material_matcher_app - INFO - MaterialMatcher application initialized successfully
2025-09-04 20:14:54,621 - elastic_transport.node_pool - INFO - Resurrected node <Urllib3HttpNode(http://localhost:9200)> (force=False)
2025-09-04 20:14:58,703 - elastic_transport.transport - INFO - HEAD http://localhost:9200/ [status:N/A duration:4.083s]
2025-09-04 20:14:58,703 - elastic_transport.node_pool - WARNING - Node <Urllib3HttpNode(http://localhost:9200)> has failed for 5 times in a row, putting on 16 second timeout
2025-09-04 20:14:58,704 - elastic_transport.transport - WARNING - Retrying request after failure (attempt 0 of 3)
Traceback (most recent call last):
  File "C:\Users\uzun.a.i\PycharmProjects\PythonProject\.venv\Lib\site-packages\urllib3\connection.py", line 198, in _new_conn
    sock = connection.create_connection(
        (self._dns_host, self.port),
    ...<2 lines>...
        socket_options=self.socket_options,
    )
  File "C:\Users\uzun.a.i\PycharmProjects\PythonProject\.venv\Lib\site-packages\urllib3\util\connection.py", line 85, in create_connection
    raise err
  File "C:\Users\uzun.a.i\PycharmProjects\PythonProject\.venv\Lib\site-packages\urllib3\util\connection.py", line 73, in create_connection
    sock.connect(sa)
    ~~~~~~~~~~~~^^^^
ConnectionRefusedError: [WinError 10061] Подключение не установлено, т.к. конечный компьютер отверг запрос на подключение

The above exception was the direct cause of the following exception:

Traceback (most recent call last):
  File "C:\Users\uzun.a.i\PycharmProjects\PythonProject\.venv\Lib\site-packages\elastic_transport\_node\_http_urllib3.py", line 167, in perform_request
    response = self.pool.urlopen(
        method,
    ...<4 lines>...
        **kw,  # type: ignore[arg-type]
    )
  File "C:\Users\uzun.a.i\PycharmProjects\PythonProject\.venv\Lib\site-packages\urllib3\connectionpool.py", line 841, in urlopen
    retries = retries.increment(
        method, url, error=new_e, _pool=self, _stacktrace=sys.exc_info()[2]
    )
  File "C:\Users\uzun.a.i\PycharmProjects\PythonProject\.venv\Lib\site-packages\urllib3\util\retry.py", line 449, in increment
    raise reraise(type(error), error, _stacktrace)
          ~~~~~~~^^^^^^^^^^^^^^^^^^^^^^^^^^^^^^^^^
  File "C:\Users\uzun.a.i\PycharmProjects\PythonProject\.venv\Lib\site-packages\urllib3\util\util.py", line 39, in reraise
    raise value
  File "C:\Users\uzun.a.i\PycharmProjects\PythonProject\.venv\Lib\site-packages\urllib3\connectionpool.py", line 787, in urlopen
    response = self._make_request(
        conn,
    ...<10 lines>...
        **response_kw,
    )
  File "C:\Users\uzun.a.i\PycharmProjects\PythonProject\.venv\Lib\site-packages\urllib3\connectionpool.py", line 493, in _make_request
    conn.request(
    ~~~~~~~~~~~~^
        method,
        ^^^^^^^
    ...<6 lines>...
        enforce_content_length=enforce_content_length,
        ^^^^^^^^^^^^^^^^^^^^^^^^^^^^^^^^^^^^^^^^^^^^^^
    )
    ^
  File "C:\Users\uzun.a.i\PycharmProjects\PythonProject\.venv\Lib\site-packages\urllib3\connection.py", line 494, in request
    self.endheaders()
    ~~~~~~~~~~~~~~~^^
  File "C:\Users\uzun.a.i\AppData\Local\Programs\Python\Python313\Lib\http\client.py", line 1333, in endheaders
    self._send_output(message_body, encode_chunked=encode_chunked)
    ~~~~~~~~~~~~~~~~~^^^^^^^^^^^^^^^^^^^^^^^^^^^^^^^^^^^^^^^^^^^^^
  File "C:\Users\uzun.a.i\AppData\Local\Programs\Python\Python313\Lib\http\client.py", line 1093, in _send_output
    self.send(msg)
    ~~~~~~~~~^^^^^
  File "C:\Users\uzun.a.i\AppData\Local\Programs\Python\Python313\Lib\http\client.py", line 1037, in send
    self.connect()
    ~~~~~~~~~~~~^^
  File "C:\Users\uzun.a.i\PycharmProjects\PythonProject\.venv\Lib\site-packages\urllib3\connection.py", line 325, in connect
    self.sock = self._new_conn()
                ~~~~~~~~~~~~~~^^
  File "C:\Users\uzun.a.i\PycharmProjects\PythonProject\.venv\Lib\site-packages\urllib3\connection.py", line 213, in _new_conn
    raise NewConnectionError(
        self, f"Failed to establish a new connection: {e}"
    ) from e
urllib3.exceptions.NewConnectionError: <urllib3.connection.HTTPConnection object at 0x000002A0588E3CE0>: Failed to establish a new connection: [WinError 10061] Подключение не установлено, т.к. конечный компьютер отверг запрос на подключение

The above exception was the direct cause of the following exception:

Traceback (most recent call last):
  File "C:\Users\uzun.a.i\PycharmProjects\PythonProject\.venv\Lib\site-packages\elastic_transport\_transport.py", line 342, in perform_request
    resp = node.perform_request(
        method,
    ...<3 lines>...
        request_timeout=request_timeout,
    )
  File "C:\Users\uzun.a.i\PycharmProjects\PythonProject\.venv\Lib\site-packages\elastic_transport\_node\_http_urllib3.py", line 202, in perform_request
    raise err from e
elastic_transport.ConnectionError: Connection error caused by: NewConnectionError(<urllib3.connection.HTTPConnection object at 0x000002A0588E3CE0>: Failed to establish a new connection: [WinError 10061] Подключение не установлено, т.к. конечный компьютер отверг запрос на подключение)
2025-09-04 20:15:02,788 - elastic_transport.transport - INFO - HEAD http://localhost:9200/ [status:N/A duration:4.080s]
2025-09-04 20:15:02,788 - elastic_transport.node_pool - WARNING - Node <Urllib3HttpNode(http://localhost:9200)> has failed for 6 times in a row, putting on 30 second timeout
2025-09-04 20:15:02,788 - elastic_transport.transport - WARNING - Retrying request after failure (attempt 1 of 3)
Traceback (most recent call last):
  File "C:\Users\uzun.a.i\PycharmProjects\PythonProject\.venv\Lib\site-packages\urllib3\connection.py", line 198, in _new_conn
    sock = connection.create_connection(
        (self._dns_host, self.port),
    ...<2 lines>...
        socket_options=self.socket_options,
    )
  File "C:\Users\uzun.a.i\PycharmProjects\PythonProject\.venv\Lib\site-packages\urllib3\util\connection.py", line 85, in create_connection
    raise err
  File "C:\Users\uzun.a.i\PycharmProjects\PythonProject\.venv\Lib\site-packages\urllib3\util\connection.py", line 73, in create_connection
    sock.connect(sa)
    ~~~~~~~~~~~~^^^^
ConnectionRefusedError: [WinError 10061] Подключение не установлено, т.к. конечный компьютер отверг запрос на подключение

The above exception was the direct cause of the following exception:

Traceback (most recent call last):
  File "C:\Users\uzun.a.i\PycharmProjects\PythonProject\.venv\Lib\site-packages\elastic_transport\_node\_http_urllib3.py", line 167, in perform_request
    response = self.pool.urlopen(
        method,
    ...<4 lines>...
        **kw,  # type: ignore[arg-type]
    )
  File "C:\Users\uzun.a.i\PycharmProjects\PythonProject\.venv\Lib\site-packages\urllib3\connectionpool.py", line 841, in urlopen
    retries = retries.increment(
        method, url, error=new_e, _pool=self, _stacktrace=sys.exc_info()[2]
    )
  File "C:\Users\uzun.a.i\PycharmProjects\PythonProject\.venv\Lib\site-packages\urllib3\util\retry.py", line 449, in increment
    raise reraise(type(error), error, _stacktrace)
          ~~~~~~~^^^^^^^^^^^^^^^^^^^^^^^^^^^^^^^^^
  File "C:\Users\uzun.a.i\PycharmProjects\PythonProject\.venv\Lib\site-packages\urllib3\util\util.py", line 39, in reraise
    raise value
  File "C:\Users\uzun.a.i\PycharmProjects\PythonProject\.venv\Lib\site-packages\urllib3\connectionpool.py", line 787, in urlopen
    response = self._make_request(
        conn,
    ...<10 lines>...
        **response_kw,
    )
  File "C:\Users\uzun.a.i\PycharmProjects\PythonProject\.venv\Lib\site-packages\urllib3\connectionpool.py", line 493, in _make_request
    conn.request(
    ~~~~~~~~~~~~^
        method,
        ^^^^^^^
    ...<6 lines>...
        enforce_content_length=enforce_content_length,
        ^^^^^^^^^^^^^^^^^^^^^^^^^^^^^^^^^^^^^^^^^^^^^^
    )
    ^
  File "C:\Users\uzun.a.i\PycharmProjects\PythonProject\.venv\Lib\site-packages\urllib3\connection.py", line 494, in request
    self.endheaders()
    ~~~~~~~~~~~~~~~^^
  File "C:\Users\uzun.a.i\AppData\Local\Programs\Python\Python313\Lib\http\client.py", line 1333, in endheaders
    self._send_output(message_body, encode_chunked=encode_chunked)
    ~~~~~~~~~~~~~~~~~^^^^^^^^^^^^^^^^^^^^^^^^^^^^^^^^^^^^^^^^^^^^^
  File "C:\Users\uzun.a.i\AppData\Local\Programs\Python\Python313\Lib\http\client.py", line 1093, in _send_output
    self.send(msg)
    ~~~~~~~~~^^^^^
  File "C:\Users\uzun.a.i\AppData\Local\Programs\Python\Python313\Lib\http\client.py", line 1037, in send
    self.connect()
    ~~~~~~~~~~~~^^
  File "C:\Users\uzun.a.i\PycharmProjects\PythonProject\.venv\Lib\site-packages\urllib3\connection.py", line 325, in connect
    self.sock = self._new_conn()
                ~~~~~~~~~~~~~~^^
  File "C:\Users\uzun.a.i\PycharmProjects\PythonProject\.venv\Lib\site-packages\urllib3\connection.py", line 213, in _new_conn
    raise NewConnectionError(
        self, f"Failed to establish a new connection: {e}"
    ) from e
urllib3.exceptions.NewConnectionError: <urllib3.connection.HTTPConnection object at 0x000002A0588FEF90>: Failed to establish a new connection: [WinError 10061] Подключение не установлено, т.к. конечный компьютер отверг запрос на подключение

The above exception was the direct cause of the following exception:

Traceback (most recent call last):
  File "C:\Users\uzun.a.i\PycharmProjects\PythonProject\.venv\Lib\site-packages\elastic_transport\_transport.py", line 342, in perform_request
    resp = node.perform_request(
        method,
    ...<3 lines>...
        request_timeout=request_timeout,
    )
  File "C:\Users\uzun.a.i\PycharmProjects\PythonProject\.venv\Lib\site-packages\elastic_transport\_node\_http_urllib3.py", line 202, in perform_request
    raise err from e
elastic_transport.ConnectionError: Connection error caused by: NewConnectionError(<urllib3.connection.HTTPConnection object at 0x000002A0588FEF90>: Failed to establish a new connection: [WinError 10061] Подключение не установлено, т.к. конечный компьютер отверг запрос на подключение)
2025-09-04 20:15:02,791 - elastic_transport.node_pool - INFO - Resurrected node <Urllib3HttpNode(http://localhost:9200)> (force=False)
2025-09-04 20:15:06,899 - elastic_transport.transport - INFO - HEAD http://localhost:9200/ [status:N/A duration:4.108s]
2025-09-04 20:15:06,900 - elastic_transport.node_pool - WARNING - Node <Urllib3HttpNode(http://localhost:9200)> has failed for 7 times in a row, putting on 30 second timeout
2025-09-04 20:15:06,900 - elastic_transport.transport - WARNING - Retrying request after failure (attempt 2 of 3)
Traceback (most recent call last):
  File "C:\Users\uzun.a.i\PycharmProjects\PythonProject\.venv\Lib\site-packages\urllib3\connection.py", line 198, in _new_conn
    sock = connection.create_connection(
        (self._dns_host, self.port),
    ...<2 lines>...
        socket_options=self.socket_options,
    )
  File "C:\Users\uzun.a.i\PycharmProjects\PythonProject\.venv\Lib\site-packages\urllib3\util\connection.py", line 85, in create_connection
    raise err
  File "C:\Users\uzun.a.i\PycharmProjects\PythonProject\.venv\Lib\site-packages\urllib3\util\connection.py", line 73, in create_connection
    sock.connect(sa)
    ~~~~~~~~~~~~^^^^
ConnectionRefusedError: [WinError 10061] Подключение не установлено, т.к. конечный компьютер отверг запрос на подключение

The above exception was the direct cause of the following exception:

Traceback (most recent call last):
  File "C:\Users\uzun.a.i\PycharmProjects\PythonProject\.venv\Lib\site-packages\elastic_transport\_node\_http_urllib3.py", line 167, in perform_request
    response = self.pool.urlopen(
        method,
    ...<4 lines>...
        **kw,  # type: ignore[arg-type]
    )
  File "C:\Users\uzun.a.i\PycharmProjects\PythonProject\.venv\Lib\site-packages\urllib3\connectionpool.py", line 841, in urlopen
    retries = retries.increment(
        method, url, error=new_e, _pool=self, _stacktrace=sys.exc_info()[2]
    )
  File "C:\Users\uzun.a.i\PycharmProjects\PythonProject\.venv\Lib\site-packages\urllib3\util\retry.py", line 449, in increment
    raise reraise(type(error), error, _stacktrace)
          ~~~~~~~^^^^^^^^^^^^^^^^^^^^^^^^^^^^^^^^^
  File "C:\Users\uzun.a.i\PycharmProjects\PythonProject\.venv\Lib\site-packages\urllib3\util\util.py", line 39, in reraise
    raise value
  File "C:\Users\uzun.a.i\PycharmProjects\PythonProject\.venv\Lib\site-packages\urllib3\connectionpool.py", line 787, in urlopen
    response = self._make_request(
        conn,
    ...<10 lines>...
        **response_kw,
    )
  File "C:\Users\uzun.a.i\PycharmProjects\PythonProject\.venv\Lib\site-packages\urllib3\connectionpool.py", line 493, in _make_request
    conn.request(
    ~~~~~~~~~~~~^
        method,
        ^^^^^^^
    ...<6 lines>...
        enforce_content_length=enforce_content_length,
        ^^^^^^^^^^^^^^^^^^^^^^^^^^^^^^^^^^^^^^^^^^^^^^
    )
    ^
  File "C:\Users\uzun.a.i\PycharmProjects\PythonProject\.venv\Lib\site-packages\urllib3\connection.py", line 494, in request
    self.endheaders()
    ~~~~~~~~~~~~~~~^^
  File "C:\Users\uzun.a.i\AppData\Local\Programs\Python\Python313\Lib\http\client.py", line 1333, in endheaders
    self._send_output(message_body, encode_chunked=encode_chunked)
    ~~~~~~~~~~~~~~~~~^^^^^^^^^^^^^^^^^^^^^^^^^^^^^^^^^^^^^^^^^^^^^
  File "C:\Users\uzun.a.i\AppData\Local\Programs\Python\Python313\Lib\http\client.py", line 1093, in _send_output
    self.send(msg)
    ~~~~~~~~~^^^^^
  File "C:\Users\uzun.a.i\AppData\Local\Programs\Python\Python313\Lib\http\client.py", line 1037, in send
    self.connect()
    ~~~~~~~~~~~~^^
  File "C:\Users\uzun.a.i\PycharmProjects\PythonProject\.venv\Lib\site-packages\urllib3\connection.py", line 325, in connect
    self.sock = self._new_conn()
                ~~~~~~~~~~~~~~^^
  File "C:\Users\uzun.a.i\PycharmProjects\PythonProject\.venv\Lib\site-packages\urllib3\connection.py", line 213, in _new_conn
    raise NewConnectionError(
        self, f"Failed to establish a new connection: {e}"
    ) from e
urllib3.exceptions.NewConnectionError: <urllib3.connection.HTTPConnection object at 0x000002A058955590>: Failed to establish a new connection: [WinError 10061] Подключение не установлено, т.к. конечный компьютер отверг запрос на подключение

The above exception was the direct cause of the following exception:

Traceback (most recent call last):
  File "C:\Users\uzun.a.i\PycharmProjects\PythonProject\.venv\Lib\site-packages\elastic_transport\_transport.py", line 342, in perform_request
    resp = node.perform_request(
        method,
    ...<3 lines>...
        request_timeout=request_timeout,
    )
  File "C:\Users\uzun.a.i\PycharmProjects\PythonProject\.venv\Lib\site-packages\elastic_transport\_node\_http_urllib3.py", line 202, in perform_request
    raise err from e
elastic_transport.ConnectionError: Connection error caused by: NewConnectionError(<urllib3.connection.HTTPConnection object at 0x000002A058955590>: Failed to establish a new connection: [WinError 10061] Подключение не установлено, т.к. конечный компьютер отверг запрос на подключение)
2025-09-04 20:15:11,004 - elastic_transport.transport - INFO - HEAD http://localhost:9200/ [status:N/A duration:4.100s]
2025-09-04 20:15:11,004 - elastic_transport.node_pool - WARNING - Node <Urllib3HttpNode(http://localhost:9200)> has failed for 8 times in a row, putting on 30 second timeout
2025-09-04 20:15:42,004 - src.services.elasticsearch_service - INFO - Initialized Elasticsearch connection to localhost:9200
2025-09-04 20:15:46,071 - elastic_transport.transport - INFO - HEAD http://localhost:9200/ [status:N/A duration:4.067s]
2025-09-04 20:15:46,072 - elastic_transport.node_pool - WARNING - Node <Urllib3HttpNode(http://localhost:9200)> has failed for 1 times in a row, putting on 1 second timeout
2025-09-04 20:15:46,072 - elastic_transport.transport - WARNING - Retrying request after failure (attempt 0 of 3)
Traceback (most recent call last):
  File "C:\Users\uzun.a.i\PycharmProjects\PythonProject\.venv\Lib\site-packages\urllib3\connection.py", line 198, in _new_conn
    sock = connection.create_connection(
        (self._dns_host, self.port),
    ...<2 lines>...
        socket_options=self.socket_options,
    )
  File "C:\Users\uzun.a.i\PycharmProjects\PythonProject\.venv\Lib\site-packages\urllib3\util\connection.py", line 85, in create_connection
    raise err
  File "C:\Users\uzun.a.i\PycharmProjects\PythonProject\.venv\Lib\site-packages\urllib3\util\connection.py", line 73, in create_connection
    sock.connect(sa)
    ~~~~~~~~~~~~^^^^
ConnectionRefusedError: [WinError 10061] Подключение не установлено, т.к. конечный компьютер отверг запрос на подключение

The above exception was the direct cause of the following exception:

Traceback (most recent call last):
  File "C:\Users\uzun.a.i\PycharmProjects\PythonProject\.venv\Lib\site-packages\elastic_transport\_node\_http_urllib3.py", line 167, in perform_request
    response = self.pool.urlopen(
        method,
    ...<4 lines>...
        **kw,  # type: ignore[arg-type]
    )
  File "C:\Users\uzun.a.i\PycharmProjects\PythonProject\.venv\Lib\site-packages\urllib3\connectionpool.py", line 841, in urlopen
    retries = retries.increment(
        method, url, error=new_e, _pool=self, _stacktrace=sys.exc_info()[2]
    )
  File "C:\Users\uzun.a.i\PycharmProjects\PythonProject\.venv\Lib\site-packages\urllib3\util\retry.py", line 449, in increment
    raise reraise(type(error), error, _stacktrace)
          ~~~~~~~^^^^^^^^^^^^^^^^^^^^^^^^^^^^^^^^^
  File "C:\Users\uzun.a.i\PycharmProjects\PythonProject\.venv\Lib\site-packages\urllib3\util\util.py", line 39, in reraise
    raise value
  File "C:\Users\uzun.a.i\PycharmProjects\PythonProject\.venv\Lib\site-packages\urllib3\connectionpool.py", line 787, in urlopen
    response = self._make_request(
        conn,
    ...<10 lines>...
        **response_kw,
    )
  File "C:\Users\uzun.a.i\PycharmProjects\PythonProject\.venv\Lib\site-packages\urllib3\connectionpool.py", line 493, in _make_request
    conn.request(
    ~~~~~~~~~~~~^
        method,
        ^^^^^^^
    ...<6 lines>...
        enforce_content_length=enforce_content_length,
        ^^^^^^^^^^^^^^^^^^^^^^^^^^^^^^^^^^^^^^^^^^^^^^
    )
    ^
  File "C:\Users\uzun.a.i\PycharmProjects\PythonProject\.venv\Lib\site-packages\urllib3\connection.py", line 494, in request
    self.endheaders()
    ~~~~~~~~~~~~~~~^^
  File "C:\Users\uzun.a.i\AppData\Local\Programs\Python\Python313\Lib\http\client.py", line 1333, in endheaders
    self._send_output(message_body, encode_chunked=encode_chunked)
    ~~~~~~~~~~~~~~~~~^^^^^^^^^^^^^^^^^^^^^^^^^^^^^^^^^^^^^^^^^^^^^
  File "C:\Users\uzun.a.i\AppData\Local\Programs\Python\Python313\Lib\http\client.py", line 1093, in _send_output
    self.send(msg)
    ~~~~~~~~~^^^^^
  File "C:\Users\uzun.a.i\AppData\Local\Programs\Python\Python313\Lib\http\client.py", line 1037, in send
    self.connect()
    ~~~~~~~~~~~~^^
  File "C:\Users\uzun.a.i\PycharmProjects\PythonProject\.venv\Lib\site-packages\urllib3\connection.py", line 325, in connect
    self.sock = self._new_conn()
                ~~~~~~~~~~~~~~^^
  File "C:\Users\uzun.a.i\PycharmProjects\PythonProject\.venv\Lib\site-packages\urllib3\connection.py", line 213, in _new_conn
    raise NewConnectionError(
        self, f"Failed to establish a new connection: {e}"
    ) from e
urllib3.exceptions.NewConnectionError: <urllib3.connection.HTTPConnection object at 0x0000020DA11BC050>: Failed to establish a new connection: [WinError 10061] Подключение не установлено, т.к. конечный компьютер отверг запрос на подключение

The above exception was the direct cause of the following exception:

Traceback (most recent call last):
  File "C:\Users\uzun.a.i\PycharmProjects\PythonProject\.venv\Lib\site-packages\elastic_transport\_transport.py", line 342, in perform_request
    resp = node.perform_request(
        method,
    ...<3 lines>...
        request_timeout=request_timeout,
    )
  File "C:\Users\uzun.a.i\PycharmProjects\PythonProject\.venv\Lib\site-packages\elastic_transport\_node\_http_urllib3.py", line 202, in perform_request
    raise err from e
elastic_transport.ConnectionError: Connection error caused by: NewConnectionError(<urllib3.connection.HTTPConnection object at 0x0000020DA11BC050>: Failed to establish a new connection: [WinError 10061] Подключение не установлено, т.к. конечный компьютер отверг запрос на подключение)
2025-09-04 20:15:50,162 - elastic_transport.transport - INFO - HEAD http://localhost:9200/ [status:N/A duration:4.084s]
2025-09-04 20:15:50,162 - elastic_transport.node_pool - WARNING - Node <Urllib3HttpNode(http://localhost:9200)> has failed for 2 times in a row, putting on 2 second timeout
2025-09-04 20:15:50,162 - elastic_transport.transport - WARNING - Retrying request after failure (attempt 1 of 3)
Traceback (most recent call last):
  File "C:\Users\uzun.a.i\PycharmProjects\PythonProject\.venv\Lib\site-packages\urllib3\connection.py", line 198, in _new_conn
    sock = connection.create_connection(
        (self._dns_host, self.port),
    ...<2 lines>...
        socket_options=self.socket_options,
    )
  File "C:\Users\uzun.a.i\PycharmProjects\PythonProject\.venv\Lib\site-packages\urllib3\util\connection.py", line 85, in create_connection
    raise err
  File "C:\Users\uzun.a.i\PycharmProjects\PythonProject\.venv\Lib\site-packages\urllib3\util\connection.py", line 73, in create_connection
    sock.connect(sa)
    ~~~~~~~~~~~~^^^^
ConnectionRefusedError: [WinError 10061] Подключение не установлено, т.к. конечный компьютер отверг запрос на подключение

The above exception was the direct cause of the following exception:

Traceback (most recent call last):
  File "C:\Users\uzun.a.i\PycharmProjects\PythonProject\.venv\Lib\site-packages\elastic_transport\_node\_http_urllib3.py", line 167, in perform_request
    response = self.pool.urlopen(
        method,
    ...<4 lines>...
        **kw,  # type: ignore[arg-type]
    )
  File "C:\Users\uzun.a.i\PycharmProjects\PythonProject\.venv\Lib\site-packages\urllib3\connectionpool.py", line 841, in urlopen
    retries = retries.increment(
        method, url, error=new_e, _pool=self, _stacktrace=sys.exc_info()[2]
    )
  File "C:\Users\uzun.a.i\PycharmProjects\PythonProject\.venv\Lib\site-packages\urllib3\util\retry.py", line 449, in increment
    raise reraise(type(error), error, _stacktrace)
          ~~~~~~~^^^^^^^^^^^^^^^^^^^^^^^^^^^^^^^^^
  File "C:\Users\uzun.a.i\PycharmProjects\PythonProject\.venv\Lib\site-packages\urllib3\util\util.py", line 39, in reraise
    raise value
  File "C:\Users\uzun.a.i\PycharmProjects\PythonProject\.venv\Lib\site-packages\urllib3\connectionpool.py", line 787, in urlopen
    response = self._make_request(
        conn,
    ...<10 lines>...
        **response_kw,
    )
  File "C:\Users\uzun.a.i\PycharmProjects\PythonProject\.venv\Lib\site-packages\urllib3\connectionpool.py", line 493, in _make_request
    conn.request(
    ~~~~~~~~~~~~^
        method,
        ^^^^^^^
    ...<6 lines>...
        enforce_content_length=enforce_content_length,
        ^^^^^^^^^^^^^^^^^^^^^^^^^^^^^^^^^^^^^^^^^^^^^^
    )
    ^
  File "C:\Users\uzun.a.i\PycharmProjects\PythonProject\.venv\Lib\site-packages\urllib3\connection.py", line 494, in request
    self.endheaders()
    ~~~~~~~~~~~~~~~^^
  File "C:\Users\uzun.a.i\AppData\Local\Programs\Python\Python313\Lib\http\client.py", line 1333, in endheaders
    self._send_output(message_body, encode_chunked=encode_chunked)
    ~~~~~~~~~~~~~~~~~^^^^^^^^^^^^^^^^^^^^^^^^^^^^^^^^^^^^^^^^^^^^^
  File "C:\Users\uzun.a.i\AppData\Local\Programs\Python\Python313\Lib\http\client.py", line 1093, in _send_output
    self.send(msg)
    ~~~~~~~~~^^^^^
  File "C:\Users\uzun.a.i\AppData\Local\Programs\Python\Python313\Lib\http\client.py", line 1037, in send
    self.connect()
    ~~~~~~~~~~~~^^
  File "C:\Users\uzun.a.i\PycharmProjects\PythonProject\.venv\Lib\site-packages\urllib3\connection.py", line 325, in connect
    self.sock = self._new_conn()
                ~~~~~~~~~~~~~~^^
  File "C:\Users\uzun.a.i\PycharmProjects\PythonProject\.venv\Lib\site-packages\urllib3\connection.py", line 213, in _new_conn
    raise NewConnectionError(
        self, f"Failed to establish a new connection: {e}"
    ) from e
urllib3.exceptions.NewConnectionError: <urllib3.connection.HTTPConnection object at 0x0000020DA1125F90>: Failed to establish a new connection: [WinError 10061] Подключение не установлено, т.к. конечный компьютер отверг запрос на подключение

The above exception was the direct cause of the following exception:

Traceback (most recent call last):
  File "C:\Users\uzun.a.i\PycharmProjects\PythonProject\.venv\Lib\site-packages\elastic_transport\_transport.py", line 342, in perform_request
    resp = node.perform_request(
        method,
    ...<3 lines>...
        request_timeout=request_timeout,
    )
  File "C:\Users\uzun.a.i\PycharmProjects\PythonProject\.venv\Lib\site-packages\elastic_transport\_node\_http_urllib3.py", line 202, in perform_request
    raise err from e
elastic_transport.ConnectionError: Connection error caused by: NewConnectionError(<urllib3.connection.HTTPConnection object at 0x0000020DA1125F90>: Failed to establish a new connection: [WinError 10061] Подключение не установлено, т.к. конечный компьютер отверг запрос на подключение)
2025-09-04 20:15:50,165 - elastic_transport.node_pool - INFO - Resurrected node <Urllib3HttpNode(http://localhost:9200)> (force=False)
2025-09-04 20:15:54,236 - elastic_transport.transport - INFO - HEAD http://localhost:9200/ [status:N/A duration:4.071s]
2025-09-04 20:15:54,237 - elastic_transport.node_pool - WARNING - Node <Urllib3HttpNode(http://localhost:9200)> has failed for 3 times in a row, putting on 4 second timeout
2025-09-04 20:15:54,237 - elastic_transport.transport - WARNING - Retrying request after failure (attempt 2 of 3)
Traceback (most recent call last):
  File "C:\Users\uzun.a.i\PycharmProjects\PythonProject\.venv\Lib\site-packages\urllib3\connection.py", line 198, in _new_conn
    sock = connection.create_connection(
        (self._dns_host, self.port),
    ...<2 lines>...
        socket_options=self.socket_options,
    )
  File "C:\Users\uzun.a.i\PycharmProjects\PythonProject\.venv\Lib\site-packages\urllib3\util\connection.py", line 85, in create_connection
    raise err
  File "C:\Users\uzun.a.i\PycharmProjects\PythonProject\.venv\Lib\site-packages\urllib3\util\connection.py", line 73, in create_connection
    sock.connect(sa)
    ~~~~~~~~~~~~^^^^
ConnectionRefusedError: [WinError 10061] Подключение не установлено, т.к. конечный компьютер отверг запрос на подключение

The above exception was the direct cause of the following exception:

Traceback (most recent call last):
  File "C:\Users\uzun.a.i\PycharmProjects\PythonProject\.venv\Lib\site-packages\elastic_transport\_node\_http_urllib3.py", line 167, in perform_request
    response = self.pool.urlopen(
        method,
    ...<4 lines>...
        **kw,  # type: ignore[arg-type]
    )
  File "C:\Users\uzun.a.i\PycharmProjects\PythonProject\.venv\Lib\site-packages\urllib3\connectionpool.py", line 841, in urlopen
    retries = retries.increment(
        method, url, error=new_e, _pool=self, _stacktrace=sys.exc_info()[2]
    )
  File "C:\Users\uzun.a.i\PycharmProjects\PythonProject\.venv\Lib\site-packages\urllib3\util\retry.py", line 449, in increment
    raise reraise(type(error), error, _stacktrace)
          ~~~~~~~^^^^^^^^^^^^^^^^^^^^^^^^^^^^^^^^^
  File "C:\Users\uzun.a.i\PycharmProjects\PythonProject\.venv\Lib\site-packages\urllib3\util\util.py", line 39, in reraise
    raise value
  File "C:\Users\uzun.a.i\PycharmProjects\PythonProject\.venv\Lib\site-packages\urllib3\connectionpool.py", line 787, in urlopen
    response = self._make_request(
        conn,
    ...<10 lines>...
        **response_kw,
    )
  File "C:\Users\uzun.a.i\PycharmProjects\PythonProject\.venv\Lib\site-packages\urllib3\connectionpool.py", line 493, in _make_request
    conn.request(
    ~~~~~~~~~~~~^
        method,
        ^^^^^^^
    ...<6 lines>...
        enforce_content_length=enforce_content_length,
        ^^^^^^^^^^^^^^^^^^^^^^^^^^^^^^^^^^^^^^^^^^^^^^
    )
    ^
  File "C:\Users\uzun.a.i\PycharmProjects\PythonProject\.venv\Lib\site-packages\urllib3\connection.py", line 494, in request
    self.endheaders()
    ~~~~~~~~~~~~~~~^^
  File "C:\Users\uzun.a.i\AppData\Local\Programs\Python\Python313\Lib\http\client.py", line 1333, in endheaders
    self._send_output(message_body, encode_chunked=encode_chunked)
    ~~~~~~~~~~~~~~~~~^^^^^^^^^^^^^^^^^^^^^^^^^^^^^^^^^^^^^^^^^^^^^
  File "C:\Users\uzun.a.i\AppData\Local\Programs\Python\Python313\Lib\http\client.py", line 1093, in _send_output
    self.send(msg)
    ~~~~~~~~~^^^^^
  File "C:\Users\uzun.a.i\AppData\Local\Programs\Python\Python313\Lib\http\client.py", line 1037, in send
    self.connect()
    ~~~~~~~~~~~~^^
  File "C:\Users\uzun.a.i\PycharmProjects\PythonProject\.venv\Lib\site-packages\urllib3\connection.py", line 325, in connect
    self.sock = self._new_conn()
                ~~~~~~~~~~~~~~^^
  File "C:\Users\uzun.a.i\PycharmProjects\PythonProject\.venv\Lib\site-packages\urllib3\connection.py", line 213, in _new_conn
    raise NewConnectionError(
        self, f"Failed to establish a new connection: {e}"
    ) from e
urllib3.exceptions.NewConnectionError: <urllib3.connection.HTTPConnection object at 0x0000020DA1126210>: Failed to establish a new connection: [WinError 10061] Подключение не установлено, т.к. конечный компьютер отверг запрос на подключение

The above exception was the direct cause of the following exception:

Traceback (most recent call last):
  File "C:\Users\uzun.a.i\PycharmProjects\PythonProject\.venv\Lib\site-packages\elastic_transport\_transport.py", line 342, in perform_request
    resp = node.perform_request(
        method,
    ...<3 lines>...
        request_timeout=request_timeout,
    )
  File "C:\Users\uzun.a.i\PycharmProjects\PythonProject\.venv\Lib\site-packages\elastic_transport\_node\_http_urllib3.py", line 202, in perform_request
    raise err from e
elastic_transport.ConnectionError: Connection error caused by: NewConnectionError(<urllib3.connection.HTTPConnection object at 0x0000020DA1126210>: Failed to establish a new connection: [WinError 10061] Подключение не установлено, т.к. конечный компьютер отверг запрос на подключение)
2025-09-04 20:15:54,240 - elastic_transport.node_pool - INFO - Resurrected node <Urllib3HttpNode(http://localhost:9200)> (force=False)
2025-09-04 20:15:58,290 - elastic_transport.transport - INFO - HEAD http://localhost:9200/ [status:N/A duration:4.050s]
2025-09-04 20:15:58,290 - elastic_transport.node_pool - WARNING - Node <Urllib3HttpNode(http://localhost:9200)> has failed for 4 times in a row, putting on 8 second timeout
2025-09-04 20:15:58,290 - src.material_matcher_app - WARNING - Cannot connect to Elasticsearch. Some features may not work.
2025-09-04 20:15:58,290 - src.material_matcher_app - INFO - MaterialMatcher application initialized successfully
2025-09-04 20:15:58,290 - elastic_transport.node_pool - INFO - Resurrected node <Urllib3HttpNode(http://localhost:9200)> (force=False)
2025-09-04 20:16:02,345 - elastic_transport.transport - INFO - HEAD http://localhost:9200/ [status:N/A duration:4.055s]
2025-09-04 20:16:02,346 - elastic_transport.node_pool - WARNING - Node <Urllib3HttpNode(http://localhost:9200)> has failed for 5 times in a row, putting on 16 second timeout
2025-09-04 20:16:02,346 - elastic_transport.transport - WARNING - Retrying request after failure (attempt 0 of 3)
Traceback (most recent call last):
  File "C:\Users\uzun.a.i\PycharmProjects\PythonProject\.venv\Lib\site-packages\urllib3\connection.py", line 198, in _new_conn
    sock = connection.create_connection(
        (self._dns_host, self.port),
    ...<2 lines>...
        socket_options=self.socket_options,
    )
  File "C:\Users\uzun.a.i\PycharmProjects\PythonProject\.venv\Lib\site-packages\urllib3\util\connection.py", line 85, in create_connection
    raise err
  File "C:\Users\uzun.a.i\PycharmProjects\PythonProject\.venv\Lib\site-packages\urllib3\util\connection.py", line 73, in create_connection
    sock.connect(sa)
    ~~~~~~~~~~~~^^^^
ConnectionRefusedError: [WinError 10061] Подключение не установлено, т.к. конечный компьютер отверг запрос на подключение

The above exception was the direct cause of the following exception:

Traceback (most recent call last):
  File "C:\Users\uzun.a.i\PycharmProjects\PythonProject\.venv\Lib\site-packages\elastic_transport\_node\_http_urllib3.py", line 167, in perform_request
    response = self.pool.urlopen(
        method,
    ...<4 lines>...
        **kw,  # type: ignore[arg-type]
    )
  File "C:\Users\uzun.a.i\PycharmProjects\PythonProject\.venv\Lib\site-packages\urllib3\connectionpool.py", line 841, in urlopen
    retries = retries.increment(
        method, url, error=new_e, _pool=self, _stacktrace=sys.exc_info()[2]
    )
  File "C:\Users\uzun.a.i\PycharmProjects\PythonProject\.venv\Lib\site-packages\urllib3\util\retry.py", line 449, in increment
    raise reraise(type(error), error, _stacktrace)
          ~~~~~~~^^^^^^^^^^^^^^^^^^^^^^^^^^^^^^^^^
  File "C:\Users\uzun.a.i\PycharmProjects\PythonProject\.venv\Lib\site-packages\urllib3\util\util.py", line 39, in reraise
    raise value
  File "C:\Users\uzun.a.i\PycharmProjects\PythonProject\.venv\Lib\site-packages\urllib3\connectionpool.py", line 787, in urlopen
    response = self._make_request(
        conn,
    ...<10 lines>...
        **response_kw,
    )
  File "C:\Users\uzun.a.i\PycharmProjects\PythonProject\.venv\Lib\site-packages\urllib3\connectionpool.py", line 493, in _make_request
    conn.request(
    ~~~~~~~~~~~~^
        method,
        ^^^^^^^
    ...<6 lines>...
        enforce_content_length=enforce_content_length,
        ^^^^^^^^^^^^^^^^^^^^^^^^^^^^^^^^^^^^^^^^^^^^^^
    )
    ^
  File "C:\Users\uzun.a.i\PycharmProjects\PythonProject\.venv\Lib\site-packages\urllib3\connection.py", line 494, in request
    self.endheaders()
    ~~~~~~~~~~~~~~~^^
  File "C:\Users\uzun.a.i\AppData\Local\Programs\Python\Python313\Lib\http\client.py", line 1333, in endheaders
    self._send_output(message_body, encode_chunked=encode_chunked)
    ~~~~~~~~~~~~~~~~~^^^^^^^^^^^^^^^^^^^^^^^^^^^^^^^^^^^^^^^^^^^^^
  File "C:\Users\uzun.a.i\AppData\Local\Programs\Python\Python313\Lib\http\client.py", line 1093, in _send_output
    self.send(msg)
    ~~~~~~~~~^^^^^
  File "C:\Users\uzun.a.i\AppData\Local\Programs\Python\Python313\Lib\http\client.py", line 1037, in send
    self.connect()
    ~~~~~~~~~~~~^^
  File "C:\Users\uzun.a.i\PycharmProjects\PythonProject\.venv\Lib\site-packages\urllib3\connection.py", line 325, in connect
    self.sock = self._new_conn()
                ~~~~~~~~~~~~~~^^
  File "C:\Users\uzun.a.i\PycharmProjects\PythonProject\.venv\Lib\site-packages\urllib3\connection.py", line 213, in _new_conn
    raise NewConnectionError(
        self, f"Failed to establish a new connection: {e}"
    ) from e
urllib3.exceptions.NewConnectionError: <urllib3.connection.HTTPConnection object at 0x0000020DA11B50F0>: Failed to establish a new connection: [WinError 10061] Подключение не установлено, т.к. конечный компьютер отверг запрос на подключение

The above exception was the direct cause of the following exception:

Traceback (most recent call last):
  File "C:\Users\uzun.a.i\PycharmProjects\PythonProject\.venv\Lib\site-packages\elastic_transport\_transport.py", line 342, in perform_request
    resp = node.perform_request(
        method,
    ...<3 lines>...
        request_timeout=request_timeout,
    )
  File "C:\Users\uzun.a.i\PycharmProjects\PythonProject\.venv\Lib\site-packages\elastic_transport\_node\_http_urllib3.py", line 202, in perform_request
    raise err from e
elastic_transport.ConnectionError: Connection error caused by: NewConnectionError(<urllib3.connection.HTTPConnection object at 0x0000020DA11B50F0>: Failed to establish a new connection: [WinError 10061] Подключение не установлено, т.к. конечный компьютер отверг запрос на подключение)
2025-09-04 20:16:06,432 - elastic_transport.transport - INFO - HEAD http://localhost:9200/ [status:N/A duration:4.081s]
2025-09-04 20:16:06,432 - elastic_transport.node_pool - WARNING - Node <Urllib3HttpNode(http://localhost:9200)> has failed for 6 times in a row, putting on 30 second timeout
2025-09-04 20:16:06,432 - elastic_transport.transport - WARNING - Retrying request after failure (attempt 1 of 3)
Traceback (most recent call last):
  File "C:\Users\uzun.a.i\PycharmProjects\PythonProject\.venv\Lib\site-packages\urllib3\connection.py", line 198, in _new_conn
    sock = connection.create_connection(
        (self._dns_host, self.port),
    ...<2 lines>...
        socket_options=self.socket_options,
    )
  File "C:\Users\uzun.a.i\PycharmProjects\PythonProject\.venv\Lib\site-packages\urllib3\util\connection.py", line 85, in create_connection
    raise err
  File "C:\Users\uzun.a.i\PycharmProjects\PythonProject\.venv\Lib\site-packages\urllib3\util\connection.py", line 73, in create_connection
    sock.connect(sa)
    ~~~~~~~~~~~~^^^^
ConnectionRefusedError: [WinError 10061] Подключение не установлено, т.к. конечный компьютер отверг запрос на подключение

The above exception was the direct cause of the following exception:

Traceback (most recent call last):
  File "C:\Users\uzun.a.i\PycharmProjects\PythonProject\.venv\Lib\site-packages\elastic_transport\_node\_http_urllib3.py", line 167, in perform_request
    response = self.pool.urlopen(
        method,
    ...<4 lines>...
        **kw,  # type: ignore[arg-type]
    )
  File "C:\Users\uzun.a.i\PycharmProjects\PythonProject\.venv\Lib\site-packages\urllib3\connectionpool.py", line 841, in urlopen
    retries = retries.increment(
        method, url, error=new_e, _pool=self, _stacktrace=sys.exc_info()[2]
    )
  File "C:\Users\uzun.a.i\PycharmProjects\PythonProject\.venv\Lib\site-packages\urllib3\util\retry.py", line 449, in increment
    raise reraise(type(error), error, _stacktrace)
          ~~~~~~~^^^^^^^^^^^^^^^^^^^^^^^^^^^^^^^^^
  File "C:\Users\uzun.a.i\PycharmProjects\PythonProject\.venv\Lib\site-packages\urllib3\util\util.py", line 39, in reraise
    raise value
  File "C:\Users\uzun.a.i\PycharmProjects\PythonProject\.venv\Lib\site-packages\urllib3\connectionpool.py", line 787, in urlopen
    response = self._make_request(
        conn,
    ...<10 lines>...
        **response_kw,
    )
  File "C:\Users\uzun.a.i\PycharmProjects\PythonProject\.venv\Lib\site-packages\urllib3\connectionpool.py", line 493, in _make_request
    conn.request(
    ~~~~~~~~~~~~^
        method,
        ^^^^^^^
    ...<6 lines>...
        enforce_content_length=enforce_content_length,
        ^^^^^^^^^^^^^^^^^^^^^^^^^^^^^^^^^^^^^^^^^^^^^^
    )
    ^
  File "C:\Users\uzun.a.i\PycharmProjects\PythonProject\.venv\Lib\site-packages\urllib3\connection.py", line 494, in request
    self.endheaders()
    ~~~~~~~~~~~~~~~^^
  File "C:\Users\uzun.a.i\AppData\Local\Programs\Python\Python313\Lib\http\client.py", line 1333, in endheaders
    self._send_output(message_body, encode_chunked=encode_chunked)
    ~~~~~~~~~~~~~~~~~^^^^^^^^^^^^^^^^^^^^^^^^^^^^^^^^^^^^^^^^^^^^^
  File "C:\Users\uzun.a.i\AppData\Local\Programs\Python\Python313\Lib\http\client.py", line 1093, in _send_output
    self.send(msg)
    ~~~~~~~~~^^^^^
  File "C:\Users\uzun.a.i\AppData\Local\Programs\Python\Python313\Lib\http\client.py", line 1037, in send
    self.connect()
    ~~~~~~~~~~~~^^
  File "C:\Users\uzun.a.i\PycharmProjects\PythonProject\.venv\Lib\site-packages\urllib3\connection.py", line 325, in connect
    self.sock = self._new_conn()
                ~~~~~~~~~~~~~~^^
  File "C:\Users\uzun.a.i\PycharmProjects\PythonProject\.venv\Lib\site-packages\urllib3\connection.py", line 213, in _new_conn
    raise NewConnectionError(
        self, f"Failed to establish a new connection: {e}"
    ) from e
urllib3.exceptions.NewConnectionError: <urllib3.connection.HTTPConnection object at 0x0000020DA11CC4D0>: Failed to establish a new connection: [WinError 10061] Подключение не установлено, т.к. конечный компьютер отверг запрос на подключение

The above exception was the direct cause of the following exception:

Traceback (most recent call last):
  File "C:\Users\uzun.a.i\PycharmProjects\PythonProject\.venv\Lib\site-packages\elastic_transport\_transport.py", line 342, in perform_request
    resp = node.perform_request(
        method,
    ...<3 lines>...
        request_timeout=request_timeout,
    )
  File "C:\Users\uzun.a.i\PycharmProjects\PythonProject\.venv\Lib\site-packages\elastic_transport\_node\_http_urllib3.py", line 202, in perform_request
    raise err from e
elastic_transport.ConnectionError: Connection error caused by: NewConnectionError(<urllib3.connection.HTTPConnection object at 0x0000020DA11CC4D0>: Failed to establish a new connection: [WinError 10061] Подключение не установлено, т.к. конечный компьютер отверг запрос на подключение)
2025-09-04 20:16:06,436 - elastic_transport.node_pool - INFO - Resurrected node <Urllib3HttpNode(http://localhost:9200)> (force=False)
2025-09-04 20:16:10,555 - elastic_transport.transport - INFO - HEAD http://localhost:9200/ [status:N/A duration:4.119s]
2025-09-04 20:16:10,555 - elastic_transport.node_pool - WARNING - Node <Urllib3HttpNode(http://localhost:9200)> has failed for 7 times in a row, putting on 30 second timeout
2025-09-04 20:16:10,555 - elastic_transport.transport - WARNING - Retrying request after failure (attempt 2 of 3)
Traceback (most recent call last):
  File "C:\Users\uzun.a.i\PycharmProjects\PythonProject\.venv\Lib\site-packages\urllib3\connection.py", line 198, in _new_conn
    sock = connection.create_connection(
        (self._dns_host, self.port),
    ...<2 lines>...
        socket_options=self.socket_options,
    )
  File "C:\Users\uzun.a.i\PycharmProjects\PythonProject\.venv\Lib\site-packages\urllib3\util\connection.py", line 85, in create_connection
    raise err
  File "C:\Users\uzun.a.i\PycharmProjects\PythonProject\.venv\Lib\site-packages\urllib3\util\connection.py", line 73, in create_connection
    sock.connect(sa)
    ~~~~~~~~~~~~^^^^
ConnectionRefusedError: [WinError 10061] Подключение не установлено, т.к. конечный компьютер отверг запрос на подключение

The above exception was the direct cause of the following exception:

Traceback (most recent call last):
  File "C:\Users\uzun.a.i\PycharmProjects\PythonProject\.venv\Lib\site-packages\elastic_transport\_node\_http_urllib3.py", line 167, in perform_request
    response = self.pool.urlopen(
        method,
    ...<4 lines>...
        **kw,  # type: ignore[arg-type]
    )
  File "C:\Users\uzun.a.i\PycharmProjects\PythonProject\.venv\Lib\site-packages\urllib3\connectionpool.py", line 841, in urlopen
    retries = retries.increment(
        method, url, error=new_e, _pool=self, _stacktrace=sys.exc_info()[2]
    )
  File "C:\Users\uzun.a.i\PycharmProjects\PythonProject\.venv\Lib\site-packages\urllib3\util\retry.py", line 449, in increment
    raise reraise(type(error), error, _stacktrace)
          ~~~~~~~^^^^^^^^^^^^^^^^^^^^^^^^^^^^^^^^^
  File "C:\Users\uzun.a.i\PycharmProjects\PythonProject\.venv\Lib\site-packages\urllib3\util\util.py", line 39, in reraise
    raise value
  File "C:\Users\uzun.a.i\PycharmProjects\PythonProject\.venv\Lib\site-packages\urllib3\connectionpool.py", line 787, in urlopen
    response = self._make_request(
        conn,
    ...<10 lines>...
        **response_kw,
    )
  File "C:\Users\uzun.a.i\PycharmProjects\PythonProject\.venv\Lib\site-packages\urllib3\connectionpool.py", line 493, in _make_request
    conn.request(
    ~~~~~~~~~~~~^
        method,
        ^^^^^^^
    ...<6 lines>...
        enforce_content_length=enforce_content_length,
        ^^^^^^^^^^^^^^^^^^^^^^^^^^^^^^^^^^^^^^^^^^^^^^
    )
    ^
  File "C:\Users\uzun.a.i\PycharmProjects\PythonProject\.venv\Lib\site-packages\urllib3\connection.py", line 494, in request
    self.endheaders()
    ~~~~~~~~~~~~~~~^^
  File "C:\Users\uzun.a.i\AppData\Local\Programs\Python\Python313\Lib\http\client.py", line 1333, in endheaders
    self._send_output(message_body, encode_chunked=encode_chunked)
    ~~~~~~~~~~~~~~~~~^^^^^^^^^^^^^^^^^^^^^^^^^^^^^^^^^^^^^^^^^^^^^
  File "C:\Users\uzun.a.i\AppData\Local\Programs\Python\Python313\Lib\http\client.py", line 1093, in _send_output
    self.send(msg)
    ~~~~~~~~~^^^^^
  File "C:\Users\uzun.a.i\AppData\Local\Programs\Python\Python313\Lib\http\client.py", line 1037, in send
    self.connect()
    ~~~~~~~~~~~~^^
  File "C:\Users\uzun.a.i\PycharmProjects\PythonProject\.venv\Lib\site-packages\urllib3\connection.py", line 325, in connect
    self.sock = self._new_conn()
                ~~~~~~~~~~~~~~^^
  File "C:\Users\uzun.a.i\PycharmProjects\PythonProject\.venv\Lib\site-packages\urllib3\connection.py", line 213, in _new_conn
    raise NewConnectionError(
        self, f"Failed to establish a new connection: {e}"
    ) from e
urllib3.exceptions.NewConnectionError: <urllib3.connection.HTTPConnection object at 0x0000020DA108F460>: Failed to establish a new connection: [WinError 10061] Подключение не установлено, т.к. конечный компьютер отверг запрос на подключение

The above exception was the direct cause of the following exception:

Traceback (most recent call last):
  File "C:\Users\uzun.a.i\PycharmProjects\PythonProject\.venv\Lib\site-packages\elastic_transport\_transport.py", line 342, in perform_request
    resp = node.perform_request(
        method,
    ...<3 lines>...
        request_timeout=request_timeout,
    )
  File "C:\Users\uzun.a.i\PycharmProjects\PythonProject\.venv\Lib\site-packages\elastic_transport\_node\_http_urllib3.py", line 202, in perform_request
    raise err from e
elastic_transport.ConnectionError: Connection error caused by: NewConnectionError(<urllib3.connection.HTTPConnection object at 0x0000020DA108F460>: Failed to establish a new connection: [WinError 10061] Подключение не установлено, т.к. конечный компьютер отверг запрос на подключение)
2025-09-04 20:16:14,601 - elastic_transport.transport - INFO - HEAD http://localhost:9200/ [status:N/A duration:4.042s]
2025-09-04 20:16:14,601 - elastic_transport.node_pool - WARNING - Node <Urllib3HttpNode(http://localhost:9200)> has failed for 8 times in a row, putting on 30 second timeout
2025-09-04 20:16:18,638 - elastic_transport.transport - INFO - HEAD http://localhost:9200/ [status:N/A duration:4.037s]
2025-09-04 20:16:18,638 - elastic_transport.node_pool - WARNING - Node <Urllib3HttpNode(http://localhost:9200)> has failed for 9 times in a row, putting on 30 second timeout
2025-09-04 20:16:18,638 - elastic_transport.transport - WARNING - Retrying request after failure (attempt 0 of 3)
Traceback (most recent call last):
  File "C:\Users\uzun.a.i\PycharmProjects\PythonProject\.venv\Lib\site-packages\urllib3\connection.py", line 198, in _new_conn
    sock = connection.create_connection(
        (self._dns_host, self.port),
    ...<2 lines>...
        socket_options=self.socket_options,
    )
  File "C:\Users\uzun.a.i\PycharmProjects\PythonProject\.venv\Lib\site-packages\urllib3\util\connection.py", line 85, in create_connection
    raise err
  File "C:\Users\uzun.a.i\PycharmProjects\PythonProject\.venv\Lib\site-packages\urllib3\util\connection.py", line 73, in create_connection
    sock.connect(sa)
    ~~~~~~~~~~~~^^^^
ConnectionRefusedError: [WinError 10061] Подключение не установлено, т.к. конечный компьютер отверг запрос на подключение

The above exception was the direct cause of the following exception:

Traceback (most recent call last):
  File "C:\Users\uzun.a.i\PycharmProjects\PythonProject\.venv\Lib\site-packages\elastic_transport\_node\_http_urllib3.py", line 167, in perform_request
    response = self.pool.urlopen(
        method,
    ...<4 lines>...
        **kw,  # type: ignore[arg-type]
    )
  File "C:\Users\uzun.a.i\PycharmProjects\PythonProject\.venv\Lib\site-packages\urllib3\connectionpool.py", line 841, in urlopen
    retries = retries.increment(
        method, url, error=new_e, _pool=self, _stacktrace=sys.exc_info()[2]
    )
  File "C:\Users\uzun.a.i\PycharmProjects\PythonProject\.venv\Lib\site-packages\urllib3\util\retry.py", line 449, in increment
    raise reraise(type(error), error, _stacktrace)
          ~~~~~~~^^^^^^^^^^^^^^^^^^^^^^^^^^^^^^^^^
  File "C:\Users\uzun.a.i\PycharmProjects\PythonProject\.venv\Lib\site-packages\urllib3\util\util.py", line 39, in reraise
    raise value
  File "C:\Users\uzun.a.i\PycharmProjects\PythonProject\.venv\Lib\site-packages\urllib3\connectionpool.py", line 787, in urlopen
    response = self._make_request(
        conn,
    ...<10 lines>...
        **response_kw,
    )
  File "C:\Users\uzun.a.i\PycharmProjects\PythonProject\.venv\Lib\site-packages\urllib3\connectionpool.py", line 493, in _make_request
    conn.request(
    ~~~~~~~~~~~~^
        method,
        ^^^^^^^
    ...<6 lines>...
        enforce_content_length=enforce_content_length,
        ^^^^^^^^^^^^^^^^^^^^^^^^^^^^^^^^^^^^^^^^^^^^^^
    )
    ^
  File "C:\Users\uzun.a.i\PycharmProjects\PythonProject\.venv\Lib\site-packages\urllib3\connection.py", line 494, in request
    self.endheaders()
    ~~~~~~~~~~~~~~~^^
  File "C:\Users\uzun.a.i\AppData\Local\Programs\Python\Python313\Lib\http\client.py", line 1333, in endheaders
    self._send_output(message_body, encode_chunked=encode_chunked)
    ~~~~~~~~~~~~~~~~~^^^^^^^^^^^^^^^^^^^^^^^^^^^^^^^^^^^^^^^^^^^^^
  File "C:\Users\uzun.a.i\AppData\Local\Programs\Python\Python313\Lib\http\client.py", line 1093, in _send_output
    self.send(msg)
    ~~~~~~~~~^^^^^
  File "C:\Users\uzun.a.i\AppData\Local\Programs\Python\Python313\Lib\http\client.py", line 1037, in send
    self.connect()
    ~~~~~~~~~~~~^^
  File "C:\Users\uzun.a.i\PycharmProjects\PythonProject\.venv\Lib\site-packages\urllib3\connection.py", line 325, in connect
    self.sock = self._new_conn()
                ~~~~~~~~~~~~~~^^
  File "C:\Users\uzun.a.i\PycharmProjects\PythonProject\.venv\Lib\site-packages\urllib3\connection.py", line 213, in _new_conn
    raise NewConnectionError(
        self, f"Failed to establish a new connection: {e}"
    ) from e
urllib3.exceptions.NewConnectionError: <urllib3.connection.HTTPConnection object at 0x0000020DA123C5A0>: Failed to establish a new connection: [WinError 10061] Подключение не установлено, т.к. конечный компьютер отверг запрос на подключение

The above exception was the direct cause of the following exception:

Traceback (most recent call last):
  File "C:\Users\uzun.a.i\PycharmProjects\PythonProject\.venv\Lib\site-packages\elastic_transport\_transport.py", line 342, in perform_request
    resp = node.perform_request(
        method,
    ...<3 lines>...
        request_timeout=request_timeout,
    )
  File "C:\Users\uzun.a.i\PycharmProjects\PythonProject\.venv\Lib\site-packages\elastic_transport\_node\_http_urllib3.py", line 202, in perform_request
    raise err from e
elastic_transport.ConnectionError: Connection error caused by: NewConnectionError(<urllib3.connection.HTTPConnection object at 0x0000020DA123C5A0>: Failed to establish a new connection: [WinError 10061] Подключение не установлено, т.к. конечный компьютер отверг запрос на подключение)
2025-09-04 20:16:18,645 - elastic_transport.node_pool - INFO - Resurrected node <Urllib3HttpNode(http://localhost:9200)> (force=False)
2025-09-04 20:16:22,691 - elastic_transport.transport - INFO - HEAD http://localhost:9200/ [status:N/A duration:4.045s]
2025-09-04 20:16:22,691 - elastic_transport.node_pool - WARNING - Node <Urllib3HttpNode(http://localhost:9200)> has failed for 10 times in a row, putting on 30 second timeout
2025-09-04 20:16:22,691 - elastic_transport.transport - WARNING - Retrying request after failure (attempt 1 of 3)
Traceback (most recent call last):
  File "C:\Users\uzun.a.i\PycharmProjects\PythonProject\.venv\Lib\site-packages\urllib3\connection.py", line 198, in _new_conn
    sock = connection.create_connection(
        (self._dns_host, self.port),
    ...<2 lines>...
        socket_options=self.socket_options,
    )
  File "C:\Users\uzun.a.i\PycharmProjects\PythonProject\.venv\Lib\site-packages\urllib3\util\connection.py", line 85, in create_connection
    raise err
  File "C:\Users\uzun.a.i\PycharmProjects\PythonProject\.venv\Lib\site-packages\urllib3\util\connection.py", line 73, in create_connection
    sock.connect(sa)
    ~~~~~~~~~~~~^^^^
ConnectionRefusedError: [WinError 10061] Подключение не установлено, т.к. конечный компьютер отверг запрос на подключение

The above exception was the direct cause of the following exception:

Traceback (most recent call last):
  File "C:\Users\uzun.a.i\PycharmProjects\PythonProject\.venv\Lib\site-packages\elastic_transport\_node\_http_urllib3.py", line 167, in perform_request
    response = self.pool.urlopen(
        method,
    ...<4 lines>...
        **kw,  # type: ignore[arg-type]
    )
  File "C:\Users\uzun.a.i\PycharmProjects\PythonProject\.venv\Lib\site-packages\urllib3\connectionpool.py", line 841, in urlopen
    retries = retries.increment(
        method, url, error=new_e, _pool=self, _stacktrace=sys.exc_info()[2]
    )
  File "C:\Users\uzun.a.i\PycharmProjects\PythonProject\.venv\Lib\site-packages\urllib3\util\retry.py", line 449, in increment
    raise reraise(type(error), error, _stacktrace)
          ~~~~~~~^^^^^^^^^^^^^^^^^^^^^^^^^^^^^^^^^
  File "C:\Users\uzun.a.i\PycharmProjects\PythonProject\.venv\Lib\site-packages\urllib3\util\util.py", line 39, in reraise
    raise value
  File "C:\Users\uzun.a.i\PycharmProjects\PythonProject\.venv\Lib\site-packages\urllib3\connectionpool.py", line 787, in urlopen
    response = self._make_request(
        conn,
    ...<10 lines>...
        **response_kw,
    )
  File "C:\Users\uzun.a.i\PycharmProjects\PythonProject\.venv\Lib\site-packages\urllib3\connectionpool.py", line 493, in _make_request
    conn.request(
    ~~~~~~~~~~~~^
        method,
        ^^^^^^^
    ...<6 lines>...
        enforce_content_length=enforce_content_length,
        ^^^^^^^^^^^^^^^^^^^^^^^^^^^^^^^^^^^^^^^^^^^^^^
    )
    ^
  File "C:\Users\uzun.a.i\PycharmProjects\PythonProject\.venv\Lib\site-packages\urllib3\connection.py", line 494, in request
    self.endheaders()
    ~~~~~~~~~~~~~~~^^
  File "C:\Users\uzun.a.i\AppData\Local\Programs\Python\Python313\Lib\http\client.py", line 1333, in endheaders
    self._send_output(message_body, encode_chunked=encode_chunked)
    ~~~~~~~~~~~~~~~~~^^^^^^^^^^^^^^^^^^^^^^^^^^^^^^^^^^^^^^^^^^^^^
  File "C:\Users\uzun.a.i\AppData\Local\Programs\Python\Python313\Lib\http\client.py", line 1093, in _send_output
    self.send(msg)
    ~~~~~~~~~^^^^^
  File "C:\Users\uzun.a.i\AppData\Local\Programs\Python\Python313\Lib\http\client.py", line 1037, in send
    self.connect()
    ~~~~~~~~~~~~^^
  File "C:\Users\uzun.a.i\PycharmProjects\PythonProject\.venv\Lib\site-packages\urllib3\connection.py", line 325, in connect
    self.sock = self._new_conn()
                ~~~~~~~~~~~~~~^^
  File "C:\Users\uzun.a.i\PycharmProjects\PythonProject\.venv\Lib\site-packages\urllib3\connection.py", line 213, in _new_conn
    raise NewConnectionError(
        self, f"Failed to establish a new connection: {e}"
    ) from e
urllib3.exceptions.NewConnectionError: <urllib3.connection.HTTPConnection object at 0x0000020DA123C050>: Failed to establish a new connection: [WinError 10061] Подключение не установлено, т.к. конечный компьютер отверг запрос на подключение

The above exception was the direct cause of the following exception:

Traceback (most recent call last):
  File "C:\Users\uzun.a.i\PycharmProjects\PythonProject\.venv\Lib\site-packages\elastic_transport\_transport.py", line 342, in perform_request
    resp = node.perform_request(
        method,
    ...<3 lines>...
        request_timeout=request_timeout,
    )
  File "C:\Users\uzun.a.i\PycharmProjects\PythonProject\.venv\Lib\site-packages\elastic_transport\_node\_http_urllib3.py", line 202, in perform_request
    raise err from e
elastic_transport.ConnectionError: Connection error caused by: NewConnectionError(<urllib3.connection.HTTPConnection object at 0x0000020DA123C050>: Failed to establish a new connection: [WinError 10061] Подключение не установлено, т.к. конечный компьютер отверг запрос на подключение)
2025-09-04 20:16:26,770 - elastic_transport.transport - INFO - HEAD http://localhost:9200/ [status:N/A duration:4.072s]
2025-09-04 20:16:26,770 - elastic_transport.node_pool - WARNING - Node <Urllib3HttpNode(http://localhost:9200)> has failed for 11 times in a row, putting on 30 second timeout
2025-09-04 20:16:26,771 - elastic_transport.transport - WARNING - Retrying request after failure (attempt 2 of 3)
Traceback (most recent call last):
  File "C:\Users\uzun.a.i\PycharmProjects\PythonProject\.venv\Lib\site-packages\urllib3\connection.py", line 198, in _new_conn
    sock = connection.create_connection(
        (self._dns_host, self.port),
    ...<2 lines>...
        socket_options=self.socket_options,
    )
  File "C:\Users\uzun.a.i\PycharmProjects\PythonProject\.venv\Lib\site-packages\urllib3\util\connection.py", line 85, in create_connection
    raise err
  File "C:\Users\uzun.a.i\PycharmProjects\PythonProject\.venv\Lib\site-packages\urllib3\util\connection.py", line 73, in create_connection
    sock.connect(sa)
    ~~~~~~~~~~~~^^^^
ConnectionRefusedError: [WinError 10061] Подключение не установлено, т.к. конечный компьютер отверг запрос на подключение

The above exception was the direct cause of the following exception:

Traceback (most recent call last):
  File "C:\Users\uzun.a.i\PycharmProjects\PythonProject\.venv\Lib\site-packages\elastic_transport\_node\_http_urllib3.py", line 167, in perform_request
    response = self.pool.urlopen(
        method,
    ...<4 lines>...
        **kw,  # type: ignore[arg-type]
    )
  File "C:\Users\uzun.a.i\PycharmProjects\PythonProject\.venv\Lib\site-packages\urllib3\connectionpool.py", line 841, in urlopen
    retries = retries.increment(
        method, url, error=new_e, _pool=self, _stacktrace=sys.exc_info()[2]
    )
  File "C:\Users\uzun.a.i\PycharmProjects\PythonProject\.venv\Lib\site-packages\urllib3\util\retry.py", line 449, in increment
    raise reraise(type(error), error, _stacktrace)
          ~~~~~~~^^^^^^^^^^^^^^^^^^^^^^^^^^^^^^^^^
  File "C:\Users\uzun.a.i\PycharmProjects\PythonProject\.venv\Lib\site-packages\urllib3\util\util.py", line 39, in reraise
    raise value
  File "C:\Users\uzun.a.i\PycharmProjects\PythonProject\.venv\Lib\site-packages\urllib3\connectionpool.py", line 787, in urlopen
    response = self._make_request(
        conn,
    ...<10 lines>...
        **response_kw,
    )
  File "C:\Users\uzun.a.i\PycharmProjects\PythonProject\.venv\Lib\site-packages\urllib3\connectionpool.py", line 493, in _make_request
    conn.request(
    ~~~~~~~~~~~~^
        method,
        ^^^^^^^
    ...<6 lines>...
        enforce_content_length=enforce_content_length,
        ^^^^^^^^^^^^^^^^^^^^^^^^^^^^^^^^^^^^^^^^^^^^^^
    )
    ^
  File "C:\Users\uzun.a.i\PycharmProjects\PythonProject\.venv\Lib\site-packages\urllib3\connection.py", line 494, in request
    self.endheaders()
    ~~~~~~~~~~~~~~~^^
  File "C:\Users\uzun.a.i\AppData\Local\Programs\Python\Python313\Lib\http\client.py", line 1333, in endheaders
    self._send_output(message_body, encode_chunked=encode_chunked)
    ~~~~~~~~~~~~~~~~~^^^^^^^^^^^^^^^^^^^^^^^^^^^^^^^^^^^^^^^^^^^^^
  File "C:\Users\uzun.a.i\AppData\Local\Programs\Python\Python313\Lib\http\client.py", line 1093, in _send_output
    self.send(msg)
    ~~~~~~~~~^^^^^
  File "C:\Users\uzun.a.i\AppData\Local\Programs\Python\Python313\Lib\http\client.py", line 1037, in send
    self.connect()
    ~~~~~~~~~~~~^^
  File "C:\Users\uzun.a.i\PycharmProjects\PythonProject\.venv\Lib\site-packages\urllib3\connection.py", line 325, in connect
    self.sock = self._new_conn()
                ~~~~~~~~~~~~~~^^
  File "C:\Users\uzun.a.i\PycharmProjects\PythonProject\.venv\Lib\site-packages\urllib3\connection.py", line 213, in _new_conn
    raise NewConnectionError(
        self, f"Failed to establish a new connection: {e}"
    ) from e
urllib3.exceptions.NewConnectionError: <urllib3.connection.HTTPConnection object at 0x0000020DA123C7C0>: Failed to establish a new connection: [WinError 10061] Подключение не установлено, т.к. конечный компьютер отверг запрос на подключение

The above exception was the direct cause of the following exception:

Traceback (most recent call last):
  File "C:\Users\uzun.a.i\PycharmProjects\PythonProject\.venv\Lib\site-packages\elastic_transport\_transport.py", line 342, in perform_request
    resp = node.perform_request(
        method,
    ...<3 lines>...
        request_timeout=request_timeout,
    )
  File "C:\Users\uzun.a.i\PycharmProjects\PythonProject\.venv\Lib\site-packages\elastic_transport\_node\_http_urllib3.py", line 202, in perform_request
    raise err from e
elastic_transport.ConnectionError: Connection error caused by: NewConnectionError(<urllib3.connection.HTTPConnection object at 0x0000020DA123C7C0>: Failed to establish a new connection: [WinError 10061] Подключение не установлено, т.к. конечный компьютер отверг запрос на подключение)
2025-09-04 20:16:30,818 - elastic_transport.transport - INFO - HEAD http://localhost:9200/ [status:N/A duration:4.043s]
2025-09-04 20:16:30,818 - elastic_transport.node_pool - WARNING - Node <Urllib3HttpNode(http://localhost:9200)> has failed for 12 times in a row, putting on 30 second timeout
2025-09-04 20:18:10,401 - src.services.elasticsearch_service - INFO - Initialized Elasticsearch connection to localhost:9200
2025-09-04 20:18:10,401 - src.material_matcher_app - INFO - MaterialMatcher application initialized successfully
2025-09-04 20:18:16,921 - src.services.elasticsearch_service - INFO - Initialized Elasticsearch connection to localhost:9200
2025-09-04 20:18:16,921 - src.material_matcher_app - INFO - MaterialMatcher application initialized successfully
2025-09-04 20:18:53,601 - src.services.elasticsearch_service - INFO - Initialized Elasticsearch connection to localhost:9200
2025-09-04 20:18:53,601 - src.material_matcher_app - INFO - MaterialMatcher application initialized successfully
2025-09-04 20:21:47,456 - src.services.elasticsearch_service - INFO - Initialized Elasticsearch connection to localhost:9200
2025-09-04 20:21:47,456 - src.material_matcher_app - INFO - MaterialMatcher application initialized successfully
2025-09-04 20:23:24,369 - src.services.elasticsearch_service - INFO - Initialized Elasticsearch connection to localhost:9200
2025-09-04 20:23:24,369 - src.material_matcher_app - INFO - MaterialMatcher application initialized successfully
2025-09-04 20:27:32,327 - src.services.elasticsearch_service - INFO - Initialized Elasticsearch connection to localhost:9200
2025-09-04 20:27:32,328 - src.material_matcher_app - INFO - MaterialMatcher application initialized successfully
2025-09-04 20:29:15,966 - src.services.elasticsearch_service - INFO - Initialized Elasticsearch connection to localhost:9200
2025-09-04 20:29:15,966 - src.material_matcher_app - INFO - MaterialMatcher application initialized successfully
2025-09-04 20:30:11,976 - src.material_matcher_app - INFO - Loading materials from C:/Users/uzun.a.i/Desktop/программы/парсер/BOOK1.xlsx
2025-09-04 20:30:12,188 - src.material_matcher_app - ERROR - Error loading materials: 'dict' object has no attribute 'iterrows'
2025-09-04 20:32:27,282 - src.services.elasticsearch_service - INFO - Initialized Elasticsearch connection to localhost:9200
2025-09-04 20:32:27,282 - src.material_matcher_app - INFO - MaterialMatcher application initialized successfully
2025-09-04 20:33:20,193 - src.services.elasticsearch_service - INFO - Initialized Elasticsearch connection to localhost:9200
2025-09-04 20:33:20,193 - src.material_matcher_app - INFO - MaterialMatcher application initialized successfully
2025-09-04 20:33:20,205 - src.material_matcher_app - INFO - Setting up Elasticsearch indices...
2025-09-04 20:33:20,517 - src.services.elasticsearch_service - INFO - Created materials index: materials
2025-09-04 20:33:20,764 - src.services.elasticsearch_service - INFO - Created price list index: price_list
2025-09-04 20:33:20,764 - src.material_matcher_app - INFO - Indices created successfully
2025-09-04 20:33:27,258 - src.services.elasticsearch_service - INFO - Initialized Elasticsearch connection to localhost:9200
2025-09-04 20:33:27,258 - src.material_matcher_app - INFO - MaterialMatcher application initialized successfully
2025-09-04 20:33:41,378 - src.services.elasticsearch_service - INFO - Initialized Elasticsearch connection to localhost:9200
2025-09-04 20:33:41,379 - src.material_matcher_app - INFO - MaterialMatcher application initialized successfully
2025-09-04 20:33:41,390 - src.material_matcher_app - INFO - Loading materials from data/sample/materials.csv
2025-09-04 20:33:41,391 - src.material_matcher_app - INFO - Loaded 10 materials
2025-09-04 20:33:41,391 - src.material_matcher_app - INFO - Loading price list from data/sample/price_list.csv
2025-09-04 20:33:41,392 - src.material_matcher_app - INFO - Loaded 15 price list items
2025-09-04 20:33:41,392 - src.material_matcher_app - INFO - Indexing 10 materials...
2025-09-04 20:33:42,045 - src.services.elasticsearch_service - INFO - Indexed 10 materials
2025-09-04 20:33:42,046 - src.material_matcher_app - INFO - Indexing 15 price list items...
2025-09-04 20:33:42,752 - src.services.elasticsearch_service - INFO - Indexed 15 price list items
2025-09-04 20:33:42,752 - src.material_matcher_app - INFO - Starting matching process for 10 materials...
2025-09-04 20:33:42,752 - src.services.matching_service - INFO - Starting batch matching for 10 materials
2025-09-04 20:33:43,271 - src.services.matching_service - INFO - Completed matching for 10/10 materials
2025-09-04 20:33:43,272 - src.services.matching_service - INFO - Batch matching completed. Processed 10 materials
2025-09-04 20:33:43,272 - src.material_matcher_app - INFO - Matching completed in 0.52 seconds
2025-09-04 20:33:43,272 - src.material_matcher_app - INFO - Matching statistics: {'total_materials': 10, 'materials_with_matches': 10, 'materials_without_matches': 0, 'match_rate': 100.0, 'total_matches': 34, 'average_matches_per_material': 3.4, 'average_similarity': 48.19479306833094, 'max_similarity': 89.5888888888889, 'min_similarity': 21.066089743589746}
2025-09-04 20:33:43,272 - src.material_matcher_app - INFO - Exporting results to test_results.json
2025-09-04 20:33:43,275 - src.material_matcher_app - INFO - Results exported successfully to test_results.json
2025-09-04 20:41:32,815 - src.services.elasticsearch_service - INFO - Initialized Elasticsearch connection to localhost:9200
2025-09-04 20:41:32,815 - src.material_matcher_app - INFO - MaterialMatcher application initialized successfully
2025-09-04 20:42:05,390 - src.material_matcher_app - INFO - Loading materials from C:/Users/uzun.a.i/PycharmProjects/PythonProject/material.xlsx
2025-09-04 20:42:05,550 - src.material_matcher_app - ERROR - Error loading materials: 'dict' object has no attribute 'iterrows'
2025-09-04 20:42:16,135 - src.material_matcher_app - INFO - Loading price list from C:/Users/uzun.a.i/PycharmProjects/PythonProject/pricelist.xlsx
2025-09-04 20:42:16,168 - src.material_matcher_app - ERROR - Error loading price list: 'dict' object has no attribute 'iterrows'
2025-09-04 20:45:35,188 - src.services.elasticsearch_service - INFO - Initialized Elasticsearch connection to localhost:9200
2025-09-04 20:45:35,188 - src.material_matcher_app - INFO - MaterialMatcher application initialized successfully
2025-09-04 20:45:35,197 - src.material_matcher_app - INFO - Setting up Elasticsearch indices...
2025-09-04 20:45:35,258 - src.services.elasticsearch_service - INFO - Deleted existing index: materials
2025-09-04 20:45:35,439 - src.services.elasticsearch_service - INFO - Created materials index: materials
2025-09-04 20:45:35,484 - src.services.elasticsearch_service - INFO - Deleted existing index: price_list
2025-09-04 20:45:35,715 - src.services.elasticsearch_service - INFO - Created price list index: price_list
2025-09-04 20:45:35,715 - src.material_matcher_app - INFO - Indices created successfully
2025-09-04 20:45:35,715 - src.material_matcher_app - INFO - Loading materials from materials_converted.csv
2025-09-04 20:45:35,716 - src.material_matcher_app - INFO - Loaded 31 materials
2025-09-04 20:45:35,716 - src.material_matcher_app - INFO - Loading price list from pricelist_converted.csv
2025-09-04 20:45:35,723 - src.material_matcher_app - INFO - Loaded 466 price list items
2025-09-04 20:45:35,723 - src.material_matcher_app - INFO - Indexing 31 materials...
2025-09-04 20:45:37,320 - src.services.elasticsearch_service - INFO - Indexed 31 materials
2025-09-04 20:45:37,320 - src.material_matcher_app - INFO - Indexing 466 price list items...
2025-09-04 20:46:00,831 - src.services.elasticsearch_service - INFO - Indexed 466 price list items
2025-09-04 20:46:00,831 - src.material_matcher_app - INFO - Starting matching process for 31 materials...
2025-09-04 20:46:00,831 - src.services.matching_service - INFO - Starting batch matching for 31 materials
2025-09-04 20:46:01,349 - src.services.matching_service - INFO - Completed matching for 10/31 materials
2025-09-04 20:46:01,853 - src.services.matching_service - INFO - Completed matching for 20/31 materials
2025-09-04 20:46:02,300 - src.services.matching_service - INFO - Completed matching for 30/31 materials
2025-09-04 20:46:02,321 - src.services.matching_service - INFO - Batch matching completed. Processed 31 materials
2025-09-04 20:46:02,322 - src.material_matcher_app - INFO - Matching completed in 1.49 seconds
2025-09-04 20:46:02,322 - src.material_matcher_app - INFO - Matching statistics: {'total_materials': 31, 'materials_with_matches': 31, 'materials_without_matches': 0, 'match_rate': 100.0, 'total_matches': 310, 'average_matches_per_material': 10.0, 'average_similarity': 47.82158139165004, 'max_similarity': 75.00000000000001, 'min_similarity': 34.05923076923077}
2025-09-04 20:46:02,322 - src.material_matcher_app - INFO - Exporting results to user_matching_results.json
2025-09-04 20:46:02,343 - src.material_matcher_app - INFO - Results exported successfully to user_matching_results.json
2025-09-04 20:48:39,443 - src.services.elasticsearch_service - INFO - Initialized Elasticsearch connection to localhost:9200
2025-09-04 20:48:39,443 - src.material_matcher_app - INFO - MaterialMatcher application initialized successfully
2025-09-04 20:48:56,821 - src.material_matcher_app - INFO - Loading materials from C:/Users/uzun.a.i/PycharmProjects/PythonProject/material.xlsx
2025-09-04 20:48:56,981 - src.material_matcher_app - ERROR - Error loading materials: 'dict' object has no attribute 'iterrows'
2025-09-04 20:49:04,918 - src.material_matcher_app - INFO - Loading price list from C:/Users/uzun.a.i/PycharmProjects/PythonProject/pricelist.xlsx
2025-09-04 20:49:04,950 - src.material_matcher_app - ERROR - Error loading price list: 'dict' object has no attribute 'iterrows'
2025-09-04 20:49:13,589 - src.material_matcher_app - INFO - Loading materials from C:/Users/uzun.a.i/PycharmProjects/PythonProject/materials_converted.csv
2025-09-04 20:49:13,590 - src.material_matcher_app - INFO - Loaded 31 materials
2025-09-04 20:49:20,014 - src.material_matcher_app - INFO - Loading price list from C:/Users/uzun.a.i/PycharmProjects/PythonProject/pricelist_converted.csv
2025-09-04 20:49:20,021 - src.material_matcher_app - INFO - Loaded 466 price list items
2025-09-04 20:49:42,329 - src.material_matcher_app - INFO - Starting matching process for 31 materials...
2025-09-04 20:49:42,329 - src.services.matching_service - INFO - Starting batch matching for 31 materials
2025-09-04 20:49:42,758 - src.services.matching_service - INFO - Completed matching for 10/31 materials
2025-09-04 20:49:43,175 - src.services.matching_service - INFO - Completed matching for 20/31 materials
2025-09-04 20:49:43,582 - src.services.matching_service - INFO - Completed matching for 30/31 materials
2025-09-04 20:49:43,603 - src.services.matching_service - INFO - Batch matching completed. Processed 31 materials
2025-09-04 20:49:43,603 - src.material_matcher_app - INFO - Matching completed in 1.27 seconds
2025-09-04 20:49:43,603 - src.material_matcher_app - INFO - Matching statistics: {'total_materials': 31, 'materials_with_matches': 31, 'materials_without_matches': 0, 'match_rate': 100.0, 'total_matches': 310, 'average_matches_per_material': 10.0, 'average_similarity': 47.82158139165004, 'max_similarity': 75.00000000000001, 'min_similarity': 34.05923076923077}
2025-09-05 11:17:09,642 - src.services.elasticsearch_service - INFO - Initialized Elasticsearch connection to localhost:9200
2025-09-05 11:17:09,642 - src.material_matcher_app - INFO - MaterialMatcher application initialized successfully
2025-09-05 11:17:09,653 - src.material_matcher_app - INFO - Setting up Elasticsearch indices...
2025-09-05 11:17:09,717 - src.services.elasticsearch_service - INFO - Deleted existing index: materials
2025-09-05 11:17:09,930 - src.services.elasticsearch_service - INFO - Created materials index: materials
2025-09-05 11:17:09,976 - src.services.elasticsearch_service - INFO - Deleted existing index: price_list
2025-09-05 11:17:10,221 - src.services.elasticsearch_service - INFO - Created price list index: price_list
2025-09-05 11:17:10,221 - src.material_matcher_app - INFO - Indices created successfully
2025-09-05 11:17:10,221 - src.material_matcher_app - INFO - Loading materials from materials_converted.csv
2025-09-05 11:17:10,225 - src.material_matcher_app - INFO - Loaded 31 materials
2025-09-05 11:17:10,225 - src.material_matcher_app - INFO - Loading price list from pricelist_converted.csv
2025-09-05 11:17:10,235 - src.material_matcher_app - INFO - Loaded 466 price list items
2025-09-05 11:17:10,235 - src.material_matcher_app - INFO - Indexing 31 materials...
2025-09-05 11:17:11,766 - src.services.elasticsearch_service - INFO - Indexed 31 materials
2025-09-05 11:17:11,766 - src.material_matcher_app - INFO - Indexing 466 price list items...
2025-09-05 11:17:34,626 - src.services.elasticsearch_service - INFO - Indexed 466 price list items
2025-09-05 11:17:34,626 - src.material_matcher_app - INFO - Starting matching process for 31 materials...
2025-09-05 11:17:34,626 - src.services.matching_service - INFO - Starting batch matching for 31 materials
2025-09-05 11:17:35,041 - src.services.matching_service - INFO - Completed matching for 10/31 materials
2025-09-05 11:17:35,563 - src.services.matching_service - INFO - Completed matching for 20/31 materials
2025-09-05 11:17:35,927 - src.services.matching_service - INFO - Completed matching for 30/31 materials
2025-09-05 11:17:35,958 - src.services.matching_service - INFO - Batch matching completed. Processed 31 materials
2025-09-05 11:17:35,959 - src.material_matcher_app - INFO - Matching completed in 1.33 seconds
2025-09-05 11:17:35,959 - src.material_matcher_app - INFO - Matching statistics: {'total_materials': 31, 'materials_with_matches': 31, 'materials_without_matches': 0, 'match_rate': 100.0, 'total_matches': 310, 'average_matches_per_material': 10.0, 'average_similarity': 47.8370431664344, 'max_similarity': 75.00000000000001, 'min_similarity': 34.49278481012659}
2025-09-05 11:39:58,647 - src.services.elasticsearch_service - INFO - Initialized Elasticsearch connection to localhost:9200
2025-09-05 11:39:58,647 - src.material_matcher_app - INFO - MaterialMatcher application initialized successfully
2025-09-05 11:40:13,011 - src.material_matcher_app - INFO - Loading materials from C:/Users/uzun.a.i/PycharmProjects/PythonProject/materials_converted.csv
2025-09-05 11:40:13,012 - src.material_matcher_app - INFO - Loaded 31 materials
2025-09-05 11:40:14,033 - src.material_matcher_app - INFO - Loading price list from C:/Users/uzun.a.i/PycharmProjects/PythonProject/pricelist_converted.csv
2025-09-05 11:40:14,040 - src.material_matcher_app - INFO - Loaded 466 price list items
2025-09-05 11:40:22,257 - src.material_matcher_app - INFO - Starting matching process for 31 materials...
2025-09-05 11:40:22,257 - src.services.matching_service - INFO - Starting batch matching for 31 materials
2025-09-05 11:40:22,665 - src.services.matching_service - INFO - Completed matching for 10/31 materials
2025-09-05 11:40:23,108 - src.services.matching_service - INFO - Completed matching for 20/31 materials
2025-09-05 11:40:23,501 - src.services.matching_service - INFO - Completed matching for 30/31 materials
2025-09-05 11:40:23,558 - src.services.matching_service - INFO - Batch matching completed. Processed 31 materials
2025-09-05 11:40:23,558 - src.material_matcher_app - INFO - Matching completed in 1.30 seconds
2025-09-05 11:40:23,558 - src.material_matcher_app - INFO - Matching statistics: {'total_materials': 31, 'materials_with_matches': 31, 'materials_without_matches': 0, 'match_rate': 100.0, 'total_matches': 310, 'average_matches_per_material': 10.0, 'average_similarity': 47.8370431664344, 'max_similarity': 75.00000000000001, 'min_similarity': 34.49278481012659}
2025-09-05 11:49:44,170 - src.services.elasticsearch_service - INFO - Initialized Elasticsearch connection to localhost:9200
2025-09-05 11:49:44,170 - src.material_matcher_app - INFO - MaterialMatcher application initialized successfully
2025-09-05 11:49:44,180 - src.material_matcher_app - INFO - Loading materials from material.xlsx
2025-09-05 11:49:44,190 - src.material_matcher_app - ERROR - Error loading materials: 'dict' object has no attribute 'columns'
2025-09-05 11:49:44,190 - src.material_matcher_app - INFO - Loading price list from pricelist.xlsx
2025-09-05 11:49:44,263 - src.material_matcher_app - ERROR - Error loading price list: 'dict' object has no attribute 'columns'
2025-09-05 11:49:44,263 - src.material_matcher_app - INFO - Setting up Elasticsearch indices...
2025-09-05 11:49:44,316 - src.services.elasticsearch_service - INFO - Deleted existing index: materials
2025-09-05 11:49:44,497 - src.services.elasticsearch_service - INFO - Created materials index: materials
2025-09-05 11:49:44,535 - src.services.elasticsearch_service - INFO - Deleted existing index: price_list
2025-09-05 11:49:44,736 - src.services.elasticsearch_service - INFO - Created price list index: price_list
2025-09-05 11:49:44,737 - src.material_matcher_app - INFO - Indices created successfully
2025-09-05 11:49:44,737 - src.material_matcher_app - WARNING - No materials found for matching
2025-09-05 11:53:01,477 - src.services.elasticsearch_service - INFO - Initialized Elasticsearch connection to localhost:9200
2025-09-05 11:53:01,477 - src.material_matcher_app - INFO - MaterialMatcher application initialized successfully
2025-09-05 11:53:01,485 - src.material_matcher_app - INFO - Loading materials from material.xlsx
2025-09-05 11:53:01,494 - src.material_matcher_app - ERROR - Error loading materials: 'dict' object has no attribute 'columns'
2025-09-05 11:53:01,495 - src.material_matcher_app - INFO - Loading price list from pricelist.xlsx
2025-09-05 11:53:01,560 - src.material_matcher_app - ERROR - Error loading price list: 'dict' object has no attribute 'columns'
2025-09-05 11:53:01,560 - src.material_matcher_app - INFO - Setting up Elasticsearch indices...
2025-09-05 11:53:01,594 - src.services.elasticsearch_service - INFO - Deleted existing index: materials
2025-09-05 11:53:01,791 - src.services.elasticsearch_service - INFO - Created materials index: materials
2025-09-05 11:53:01,823 - src.services.elasticsearch_service - INFO - Deleted existing index: price_list
2025-09-05 11:53:02,008 - src.services.elasticsearch_service - INFO - Created price list index: price_list
2025-09-05 11:53:02,009 - src.material_matcher_app - INFO - Indices created successfully
2025-09-05 11:53:02,009 - src.material_matcher_app - WARNING - No materials found for matching
2025-09-05 11:55:10,252 - src.services.elasticsearch_service - INFO - Initialized Elasticsearch connection to localhost:9200
2025-09-05 11:55:10,252 - src.material_matcher_app - INFO - MaterialMatcher application initialized successfully
2025-09-05 11:55:10,261 - src.material_matcher_app - INFO - Loading materials from material.xlsx
2025-09-05 11:55:10,268 - src.material_matcher_app - INFO - Loaded 31 materials
2025-09-05 11:55:10,268 - src.material_matcher_app - INFO - Loading price list from pricelist.xlsx
2025-09-05 11:55:10,327 - src.material_matcher_app - INFO - Loaded 466 price list items
2025-09-05 11:55:10,328 - src.material_matcher_app - INFO - Setting up Elasticsearch indices...
2025-09-05 11:55:10,361 - src.services.elasticsearch_service - INFO - Deleted existing index: materials
2025-09-05 11:55:10,544 - src.services.elasticsearch_service - INFO - Created materials index: materials
2025-09-05 11:55:10,576 - src.services.elasticsearch_service - INFO - Deleted existing index: price_list
2025-09-05 11:55:10,770 - src.services.elasticsearch_service - INFO - Created price list index: price_list
2025-09-05 11:55:10,770 - src.material_matcher_app - INFO - Indices created successfully
2025-09-05 11:55:10,770 - src.material_matcher_app - INFO - Indexing 31 materials...
2025-09-05 11:55:12,252 - src.services.elasticsearch_service - INFO - Indexed 31 materials
2025-09-05 11:55:12,252 - src.material_matcher_app - INFO - Indexing 466 price list items...
2025-09-05 11:55:34,723 - src.services.elasticsearch_service - INFO - Indexed 466 price list items
2025-09-05 11:55:34,723 - src.material_matcher_app - INFO - Starting matching process for 5 materials...
2025-09-05 11:55:34,723 - src.services.matching_service - INFO - Starting batch matching for 5 materials
2025-09-05 11:55:34,923 - src.services.matching_service - INFO - Batch matching completed. Processed 5 materials
2025-09-05 11:55:34,923 - src.material_matcher_app - INFO - Matching completed in 0.20 seconds
2025-09-05 11:55:34,923 - src.material_matcher_app - INFO - Matching statistics: {'total_materials': 5, 'materials_with_matches': 5, 'materials_without_matches': 0, 'match_rate': 100.0, 'total_matches': 50, 'average_matches_per_material': 10.0, 'average_similarity': 51.17843084543057, 'max_similarity': 75.00000000000001, 'min_similarity': 38.76680412371134}
2025-09-05 11:55:58,842 - src.services.elasticsearch_service - INFO - Initialized Elasticsearch connection to localhost:9200
2025-09-05 11:55:58,842 - src.material_matcher_app - INFO - MaterialMatcher application initialized successfully
2025-09-05 11:55:58,850 - src.material_matcher_app - INFO - Loading materials from material.xlsx
2025-09-05 11:55:59,014 - src.material_matcher_app - INFO - Loaded 31 materials
2025-09-05 11:55:59,014 - src.material_matcher_app - INFO - Loading price list from pricelist.xlsx
2025-09-05 11:55:59,072 - src.material_matcher_app - INFO - Loaded 466 price list items
2025-09-05 11:55:59,072 - src.material_matcher_app - INFO - Indexing 31 materials...
2025-09-05 11:56:00,648 - src.services.elasticsearch_service - INFO - Indexed 31 materials
2025-09-05 11:56:00,648 - src.material_matcher_app - INFO - Indexing 466 price list items...
2025-09-05 11:56:23,300 - src.services.elasticsearch_service - INFO - Indexed 466 price list items
2025-09-05 11:56:23,300 - src.material_matcher_app - INFO - Starting matching process for 31 materials...
2025-09-05 11:56:23,300 - src.services.matching_service - INFO - Starting batch matching for 31 materials
2025-09-05 11:56:23,680 - src.services.matching_service - INFO - Completed matching for 10/31 materials
2025-09-05 11:56:24,072 - src.services.matching_service - INFO - Completed matching for 20/31 materials
2025-09-05 11:56:24,415 - src.services.matching_service - INFO - Completed matching for 30/31 materials
2025-09-05 11:56:24,435 - src.services.matching_service - INFO - Batch matching completed. Processed 31 materials
2025-09-05 11:56:24,435 - src.material_matcher_app - INFO - Matching completed in 1.14 seconds
2025-09-05 11:56:24,436 - src.material_matcher_app - INFO - Matching statistics: {'total_materials': 31, 'materials_with_matches': 31, 'materials_without_matches': 0, 'match_rate': 100.0, 'total_matches': 310, 'average_matches_per_material': 10.0, 'average_similarity': 47.79789271541233, 'max_similarity': 75.00000000000001, 'min_similarity': 34.05923076923077}
2025-09-05 11:56:24,436 - src.material_matcher_app - INFO - Exporting results to test_results.json
2025-09-05 11:56:24,458 - src.material_matcher_app - INFO - Results exported successfully to test_results.json
2025-09-05 12:12:14,938 - src.services.elasticsearch_service - INFO - Initialized Elasticsearch connection to localhost:9200
2025-09-05 12:12:14,938 - src.material_matcher_app - INFO - MaterialMatcher application initialized successfully
2025-09-05 12:12:14,947 - src.material_matcher_app - INFO - Loading materials from material.xlsx
2025-09-05 12:12:15,118 - src.material_matcher_app - INFO - Loaded 31 materials
2025-09-05 12:12:15,118 - src.material_matcher_app - INFO - Loading price list from pricelist.xlsx
2025-09-05 12:12:15,180 - src.material_matcher_app - INFO - Loaded 466 price list items
2025-09-05 12:12:15,180 - src.material_matcher_app - INFO - Indexing 31 materials...
2025-09-05 12:12:16,731 - src.services.elasticsearch_service - INFO - Indexed 31 materials
2025-09-05 12:12:16,731 - src.material_matcher_app - INFO - Indexing 466 price list items...
2025-09-05 12:12:39,531 - src.services.elasticsearch_service - INFO - Indexed 466 price list items
2025-09-05 12:12:39,531 - src.material_matcher_app - INFO - Starting matching process for 31 materials...
2025-09-05 12:12:39,531 - src.services.matching_service - INFO - Starting batch matching for 31 materials
2025-09-05 12:12:39,892 - src.services.matching_service - INFO - Completed matching for 10/31 materials
2025-09-05 12:12:40,271 - src.services.matching_service - INFO - Completed matching for 20/31 materials
2025-09-05 12:12:40,642 - src.services.matching_service - INFO - Completed matching for 30/31 materials
2025-09-05 12:12:40,681 - src.services.matching_service - INFO - Batch matching completed. Processed 31 materials
2025-09-05 12:12:40,682 - src.material_matcher_app - INFO - Matching completed in 1.15 seconds
2025-09-05 12:12:40,682 - src.material_matcher_app - INFO - Matching statistics: {'total_materials': 31, 'materials_with_matches': 31, 'materials_without_matches': 0, 'match_rate': 100.0, 'total_matches': 310, 'average_matches_per_material': 10.0, 'average_similarity': 47.81558830240839, 'max_similarity': 75.00000000000001, 'min_similarity': 34.421204819277115}
2025-09-05 12:12:40,682 - src.material_matcher_app - INFO - Exporting results to test_results.xlsx
2025-09-05 12:12:40,795 - src.material_matcher_app - INFO - Results exported successfully to test_results.xlsx
2025-09-05 13:25:01,356 - src.services.elasticsearch_service - INFO - Initialized Elasticsearch connection to localhost:9200
2025-09-05 13:25:01,356 - src.material_matcher_app - INFO - MaterialMatcher application initialized successfully
2025-09-05 13:25:08,519 - src.material_matcher_app - INFO - Loading materials from C:/Users/uzun.a.i/PycharmProjects/PythonProject/material.xlsx
2025-09-05 13:25:08,708 - src.material_matcher_app - INFO - Loaded 31 materials
2025-09-05 13:25:30,208 - src.material_matcher_app - INFO - Loading price list from C:/Users/uzun.a.i/PycharmProjects/PythonProject/pricelist.xlsx
2025-09-05 13:25:30,264 - src.material_matcher_app - INFO - Loaded 466 price list items
2025-09-05 13:25:32,150 - src.material_matcher_app - INFO - Starting matching process for 31 materials...
2025-09-05 13:25:32,150 - src.services.matching_service - INFO - Starting batch matching for 31 materials
2025-09-05 13:25:32,472 - src.services.matching_service - INFO - Completed matching for 10/31 materials
2025-09-05 13:25:32,738 - src.services.matching_service - INFO - Completed matching for 20/31 materials
2025-09-05 13:25:32,978 - src.services.matching_service - INFO - Completed matching for 30/31 materials
2025-09-05 13:25:33,017 - src.services.matching_service - INFO - Batch matching completed. Processed 31 materials
2025-09-05 13:25:33,017 - src.material_matcher_app - INFO - Matching completed in 0.87 seconds
2025-09-05 13:25:33,017 - src.material_matcher_app - INFO - Matching statistics: {'total_materials': 31, 'materials_with_matches': 31, 'materials_without_matches': 0, 'match_rate': 100.0, 'total_matches': 217, 'average_matches_per_material': 7.0, 'average_similarity': 50.03398439465437, 'max_similarity': 75.00000000000001, 'min_similarity': 35.11226519337017}
2025-09-05 13:26:02,040 - src.material_matcher_app - INFO - Starting matching process for 31 materials...
2025-09-05 13:26:02,040 - src.services.matching_service - INFO - Starting batch matching for 31 materials
2025-09-05 13:26:02,716 - src.services.matching_service - INFO - Completed matching for 10/31 materials
2025-09-05 13:26:03,350 - src.services.matching_service - INFO - Completed matching for 20/31 materials
2025-09-05 13:26:03,788 - src.services.matching_service - INFO - Completed matching for 30/31 materials
2025-09-05 13:26:03,842 - src.services.matching_service - INFO - Batch matching completed. Processed 31 materials
2025-09-05 13:26:03,842 - src.material_matcher_app - INFO - Matching completed in 1.80 seconds
2025-09-05 13:26:03,842 - src.material_matcher_app - INFO - Matching statistics: {'total_materials': 31, 'materials_with_matches': 31, 'materials_without_matches': 0, 'match_rate': 100.0, 'total_matches': 217, 'average_matches_per_material': 7.0, 'average_similarity': 50.03398439465437, 'max_similarity': 75.00000000000001, 'min_similarity': 35.11226519337017}
2025-09-05 13:35:49,553 - src.services.elasticsearch_service - INFO - Initialized Elasticsearch connection to localhost:9200
2025-09-05 13:35:49,553 - src.material_matcher_app - INFO - MaterialMatcher application initialized successfully
2025-09-05 13:35:49,578 - src.material_matcher_app - INFO - Loading materials from material.xlsx
2025-09-05 13:35:49,743 - src.material_matcher_app - INFO - Loaded 31 materials
2025-09-05 13:35:49,743 - src.material_matcher_app - INFO - Loading price list from pricelist.xlsx
2025-09-05 13:35:49,800 - src.material_matcher_app - INFO - Loaded 466 price list items
2025-09-05 13:35:49,800 - src.material_matcher_app - INFO - Indexing 31 materials...
2025-09-05 13:35:51,349 - src.services.elasticsearch_service - INFO - Indexed 31 materials
2025-09-05 13:35:51,350 - src.material_matcher_app - INFO - Indexing 466 price list items...
2025-09-05 13:36:14,401 - src.services.elasticsearch_service - INFO - Indexed 466 price list items
2025-09-05 13:36:14,401 - src.material_matcher_app - INFO - Starting matching process for 31 materials...
2025-09-05 13:36:14,402 - src.services.matching_service - INFO - Starting batch matching for 31 materials
2025-09-05 13:36:14,739 - src.services.matching_service - INFO - Completed matching for 10/31 materials
2025-09-05 13:36:15,104 - src.services.matching_service - INFO - Completed matching for 20/31 materials
2025-09-05 13:36:15,463 - src.services.matching_service - INFO - Completed matching for 30/31 materials
2025-09-05 13:36:15,483 - src.services.matching_service - INFO - Batch matching completed. Processed 31 materials
2025-09-05 13:36:15,483 - src.material_matcher_app - INFO - Matching completed in 1.08 seconds
2025-09-05 13:36:15,484 - src.material_matcher_app - INFO - Matching statistics: {'total_materials': 31, 'materials_with_matches': 31, 'materials_without_matches': 0, 'match_rate': 100.0, 'total_matches': 310, 'average_matches_per_material': 10.0, 'average_similarity': 47.81558830240839, 'max_similarity': 75.00000000000001, 'min_similarity': 34.421204819277115}
2025-09-05 13:36:15,484 - src.material_matcher_app - INFO - Exporting results to debug_results.json
2025-09-05 13:36:15,505 - src.material_matcher_app - INFO - Results exported successfully to debug_results.json
2025-09-05 13:37:56,677 - src.services.elasticsearch_service - INFO - Initialized Elasticsearch connection to localhost:9200
2025-09-05 13:37:56,677 - src.material_matcher_app - INFO - MaterialMatcher application initialized successfully
2025-09-05 13:37:56,686 - src.material_matcher_app - INFO - Loading materials from material.xlsx
2025-09-05 13:37:56,855 - src.material_matcher_app - INFO - Loaded 31 materials
2025-09-05 13:37:56,855 - src.material_matcher_app - INFO - Loading price list from pricelist.xlsx
2025-09-05 13:37:56,912 - src.material_matcher_app - INFO - Loaded 466 price list items
2025-09-05 13:37:56,912 - src.material_matcher_app - INFO - Indexing 31 materials...
2025-09-05 13:37:58,433 - src.services.elasticsearch_service - INFO - Indexed 31 materials
2025-09-05 13:37:58,433 - src.material_matcher_app - INFO - Indexing 466 price list items...
2025-09-05 13:38:20,929 - src.services.elasticsearch_service - INFO - Indexed 466 price list items
2025-09-05 13:38:20,929 - src.material_matcher_app - INFO - Starting matching process for 31 materials...
2025-09-05 13:38:20,929 - src.services.matching_service - INFO - Starting batch matching for 31 materials
2025-09-05 13:38:21,279 - src.services.matching_service - INFO - Completed matching for 10/31 materials
2025-09-05 13:38:21,674 - src.services.matching_service - INFO - Completed matching for 20/31 materials
2025-09-05 13:38:22,028 - src.services.matching_service - INFO - Completed matching for 30/31 materials
2025-09-05 13:38:22,029 - src.services.matching_service - INFO - Batch matching completed. Processed 31 materials
2025-09-05 13:38:22,029 - src.material_matcher_app - INFO - Matching completed in 1.10 seconds
2025-09-05 13:38:22,029 - src.material_matcher_app - INFO - Matching statistics: {'total_materials': 31, 'materials_with_matches': 31, 'materials_without_matches': 0, 'match_rate': 100.0, 'total_matches': 310, 'average_matches_per_material': 10.0, 'average_similarity': 47.82933382212164, 'max_similarity': 75.0, 'min_similarity': 34.42120481927711}
2025-09-05 13:38:22,029 - src.material_matcher_app - INFO - Exporting results to final_test.xlsx
2025-09-05 13:38:22,136 - src.material_matcher_app - INFO - Results exported successfully to final_test.xlsx
2025-09-05 13:39:50,405 - src.services.elasticsearch_service - INFO - Initialized Elasticsearch connection to localhost:9200
2025-09-05 13:39:50,405 - src.material_matcher_app - INFO - MaterialMatcher application initialized successfully
2025-09-05 13:39:50,413 - src.material_matcher_app - INFO - Loading materials from material.xlsx
2025-09-05 13:39:50,574 - src.material_matcher_app - INFO - Loaded 31 materials
2025-09-05 13:39:50,574 - src.material_matcher_app - INFO - Loading price list from pricelist.xlsx
2025-09-05 13:39:50,631 - src.material_matcher_app - INFO - Loaded 466 price list items
2025-09-05 13:39:50,631 - src.material_matcher_app - INFO - Indexing 31 materials...
2025-09-05 13:39:52,148 - src.services.elasticsearch_service - INFO - Indexed 31 materials
2025-09-05 13:39:52,148 - src.material_matcher_app - INFO - Indexing 466 price list items...
2025-09-05 13:40:15,867 - src.services.elasticsearch_service - INFO - Indexed 466 price list items
2025-09-05 13:40:15,867 - src.material_matcher_app - INFO - Starting matching process for 31 materials...
2025-09-05 13:40:15,867 - src.services.matching_service - INFO - Starting batch matching for 31 materials
2025-09-05 13:40:16,247 - src.services.matching_service - INFO - Completed matching for 10/31 materials
2025-09-05 13:40:16,662 - src.services.matching_service - INFO - Completed matching for 20/31 materials
2025-09-05 13:40:17,012 - src.services.matching_service - INFO - Completed matching for 30/31 materials
2025-09-05 13:40:17,019 - src.services.matching_service - INFO - Batch matching completed. Processed 31 materials
2025-09-05 13:40:17,019 - src.material_matcher_app - INFO - Matching completed in 1.15 seconds
2025-09-05 13:40:17,019 - src.material_matcher_app - INFO - Matching statistics: {'total_materials': 31, 'materials_with_matches': 31, 'materials_without_matches': 0, 'match_rate': 100.0, 'total_matches': 310, 'average_matches_per_material': 10.0, 'average_similarity': 60.315892961906584, 'max_similarity': 87.49999999999999, 'min_similarity': 46.9212048192771}
2025-09-05 13:40:17,019 - src.material_matcher_app - INFO - Exporting results to final_test.json
2025-09-05 13:40:17,041 - src.material_matcher_app - INFO - Results exported successfully to final_test.json
2025-09-05 13:40:37,320 - src.services.elasticsearch_service - INFO - Initialized Elasticsearch connection to localhost:9200
2025-09-05 13:40:37,320 - src.material_matcher_app - INFO - MaterialMatcher application initialized successfully
2025-09-05 13:40:37,328 - src.material_matcher_app - INFO - Loading materials from material.xlsx
2025-09-05 13:40:37,490 - src.material_matcher_app - INFO - Loaded 31 materials
2025-09-05 13:40:37,490 - src.material_matcher_app - INFO - Loading price list from pricelist.xlsx
2025-09-05 13:40:37,548 - src.material_matcher_app - INFO - Loaded 466 price list items
2025-09-05 13:40:37,548 - src.material_matcher_app - INFO - Indexing 31 materials...
2025-09-05 13:40:39,057 - src.services.elasticsearch_service - INFO - Indexed 31 materials
2025-09-05 13:40:39,057 - src.material_matcher_app - INFO - Indexing 466 price list items...
2025-09-05 13:41:01,578 - src.services.elasticsearch_service - INFO - Indexed 466 price list items
2025-09-05 13:41:01,578 - src.material_matcher_app - INFO - Starting matching process for 31 materials...
2025-09-05 13:41:01,578 - src.services.matching_service - INFO - Starting batch matching for 31 materials
2025-09-05 13:41:02,019 - src.services.matching_service - INFO - Completed matching for 10/31 materials
2025-09-05 13:41:02,404 - src.services.matching_service - INFO - Completed matching for 20/31 materials
2025-09-05 13:41:02,790 - src.services.matching_service - INFO - Completed matching for 30/31 materials
2025-09-05 13:41:02,822 - src.services.matching_service - INFO - Batch matching completed. Processed 31 materials
2025-09-05 13:41:02,822 - src.material_matcher_app - INFO - Matching completed in 1.24 seconds
2025-09-05 13:41:02,822 - src.material_matcher_app - INFO - Matching statistics: {'total_materials': 31, 'materials_with_matches': 31, 'materials_without_matches': 0, 'match_rate': 100.0, 'total_matches': 310, 'average_matches_per_material': 10.0, 'average_similarity': 60.31438122229003, 'max_similarity': 87.49999999999999, 'min_similarity': 46.9212048192771}
2025-09-05 13:41:02,822 - src.material_matcher_app - INFO - Exporting results to final_results.xlsx
2025-09-05 13:41:02,926 - src.material_matcher_app - INFO - Results exported successfully to final_results.xlsx
2025-09-05 13:42:44,618 - src.services.elasticsearch_service - INFO - Initialized Elasticsearch connection to localhost:9200
2025-09-05 13:42:44,618 - src.material_matcher_app - INFO - MaterialMatcher application initialized successfully
2025-09-05 13:43:36,042 - src.material_matcher_app - INFO - Loading materials from C:/Users/uzun.a.i/PycharmProjects/PythonProject/material.xlsx
2025-09-05 13:43:36,215 - src.material_matcher_app - INFO - Loaded 31 materials
2025-09-05 13:43:37,511 - src.material_matcher_app - INFO - Loading price list from C:/Users/uzun.a.i/PycharmProjects/PythonProject/pricelist.xlsx
2025-09-05 13:43:37,568 - src.material_matcher_app - INFO - Loaded 466 price list items
2025-09-05 13:43:41,434 - src.material_matcher_app - INFO - Starting matching process for 31 materials...
2025-09-05 13:43:41,434 - src.services.matching_service - INFO - Starting batch matching for 31 materials
2025-09-05 13:43:41,789 - src.services.matching_service - INFO - Completed matching for 10/31 materials
2025-09-05 13:43:42,164 - src.services.matching_service - INFO - Completed matching for 20/31 materials
2025-09-05 13:43:42,495 - src.services.matching_service - INFO - Completed matching for 30/31 materials
2025-09-05 13:43:42,496 - src.services.matching_service - INFO - Batch matching completed. Processed 31 materials
2025-09-05 13:43:42,496 - src.material_matcher_app - INFO - Matching completed in 1.06 seconds
2025-09-05 13:43:42,496 - src.material_matcher_app - INFO - Matching statistics: {'total_materials': 31, 'materials_with_matches': 31, 'materials_without_matches': 0, 'match_rate': 100.0, 'total_matches': 310, 'average_matches_per_material': 10.0, 'average_similarity': 60.31438122229003, 'max_similarity': 87.49999999999999, 'min_similarity': 46.9212048192771}
2025-09-05 13:46:39,921 - src.services.elasticsearch_service - INFO - Initialized Elasticsearch connection to localhost:9200
2025-09-05 13:46:39,921 - src.material_matcher_app - INFO - MaterialMatcher application initialized successfully
2025-09-05 13:46:39,929 - src.material_matcher_app - INFO - Loading materials from material.xlsx
2025-09-05 13:46:40,096 - src.material_matcher_app - INFO - Loaded 31 materials
2025-09-05 13:46:40,096 - src.material_matcher_app - INFO - Loading price list from pricelist.xlsx
2025-09-05 13:46:40,154 - src.material_matcher_app - INFO - Loaded 466 price list items
2025-09-05 13:46:40,154 - src.material_matcher_app - INFO - Indexing 31 materials...
2025-09-05 13:46:41,662 - src.services.elasticsearch_service - INFO - Indexed 31 materials
2025-09-05 13:46:41,662 - src.material_matcher_app - INFO - Indexing 466 price list items...
2025-09-05 13:47:04,138 - src.services.elasticsearch_service - INFO - Indexed 466 price list items
2025-09-05 13:47:04,138 - src.material_matcher_app - INFO - Starting matching process for 31 materials...
2025-09-05 13:47:04,138 - src.services.matching_service - INFO - Starting batch matching for 31 materials
2025-09-05 13:47:04,529 - src.services.matching_service - INFO - Completed matching for 10/31 materials
2025-09-05 13:47:04,942 - src.services.matching_service - INFO - Completed matching for 20/31 materials
2025-09-05 13:47:05,270 - src.services.matching_service - INFO - Completed matching for 30/31 materials
2025-09-05 13:47:05,290 - src.services.matching_service - INFO - Batch matching completed. Processed 31 materials
2025-09-05 13:47:05,290 - src.material_matcher_app - INFO - Matching completed in 1.15 seconds
2025-09-05 13:47:05,290 - src.material_matcher_app - INFO - Matching statistics: {'total_materials': 31, 'materials_with_matches': 31, 'materials_without_matches': 0, 'match_rate': 100.0, 'total_matches': 310, 'average_matches_per_material': 10.0, 'average_similarity': 68.30782844577755, 'max_similarity': 100.0, 'min_similarity': 54.4212048192771}
2025-09-05 13:47:05,290 - src.material_matcher_app - INFO - Exporting results to test_100_percent.json
2025-09-05 13:47:05,312 - src.material_matcher_app - INFO - Results exported successfully to test_100_percent.json
2025-09-05 13:47:45,827 - src.services.elasticsearch_service - INFO - Initialized Elasticsearch connection to localhost:9200
2025-09-05 13:47:45,827 - src.material_matcher_app - INFO - MaterialMatcher application initialized successfully
2025-09-05 13:47:45,837 - src.material_matcher_app - INFO - Loading materials from material.xlsx
2025-09-05 13:47:45,992 - src.material_matcher_app - INFO - Loaded 31 materials
2025-09-05 13:47:45,992 - src.material_matcher_app - INFO - Loading price list from pricelist.xlsx
2025-09-05 13:47:46,048 - src.material_matcher_app - INFO - Loaded 466 price list items
2025-09-05 13:47:46,048 - src.material_matcher_app - INFO - Indexing 31 materials...
2025-09-05 13:47:47,565 - src.services.elasticsearch_service - INFO - Indexed 31 materials
2025-09-05 13:47:47,566 - src.material_matcher_app - INFO - Indexing 466 price list items...
2025-09-05 13:48:10,166 - src.services.elasticsearch_service - INFO - Indexed 466 price list items
2025-09-05 13:48:10,166 - src.material_matcher_app - INFO - Starting matching process for 31 materials...
2025-09-05 13:48:10,166 - src.services.matching_service - INFO - Starting batch matching for 31 materials
2025-09-05 13:48:10,554 - src.services.matching_service - INFO - Completed matching for 10/31 materials
2025-09-05 13:48:10,947 - src.services.matching_service - INFO - Completed matching for 20/31 materials
2025-09-05 13:48:11,326 - src.services.matching_service - INFO - Completed matching for 30/31 materials
2025-09-05 13:48:11,327 - src.services.matching_service - INFO - Batch matching completed. Processed 31 materials
2025-09-05 13:48:11,327 - src.material_matcher_app - INFO - Matching completed in 1.16 seconds
2025-09-05 13:48:11,327 - src.material_matcher_app - INFO - Matching statistics: {'total_materials': 31, 'materials_with_matches': 31, 'materials_without_matches': 0, 'match_rate': 100.0, 'total_matches': 310, 'average_matches_per_material': 10.0, 'average_similarity': 68.30782844577755, 'max_similarity': 100.0, 'min_similarity': 54.4212048192771}
2025-09-05 13:48:11,327 - src.material_matcher_app - INFO - Exporting results to final_100_percent.xlsx
2025-09-05 13:48:11,433 - src.material_matcher_app - INFO - Results exported successfully to final_100_percent.xlsx
2025-09-05 13:57:05,754 - src.services.elasticsearch_service - INFO - Initialized Elasticsearch connection to localhost:9200
2025-09-05 13:57:05,755 - src.material_matcher_app - INFO - MaterialMatcher application initialized successfully
2025-09-05 13:57:33,058 - src.material_matcher_app - INFO - Loading materials from C:/Users/uzun.a.i/PycharmProjects/PythonProject/material.xlsx
2025-09-05 13:57:33,225 - src.material_matcher_app - INFO - Loaded 31 materials
2025-09-05 13:57:33,994 - src.material_matcher_app - INFO - Loading price list from C:/Users/uzun.a.i/PycharmProjects/PythonProject/pricelist.xlsx
2025-09-05 13:57:34,050 - src.material_matcher_app - INFO - Loaded 466 price list items
2025-09-05 13:58:01,917 - src.material_matcher_app - INFO - Starting matching process for 31 materials...
2025-09-05 13:58:01,918 - src.services.matching_service - INFO - Starting batch matching for 31 materials
2025-09-05 13:58:02,271 - src.services.matching_service - INFO - Completed matching for 10/31 materials
2025-09-05 13:58:02,690 - src.services.matching_service - INFO - Completed matching for 20/31 materials
2025-09-05 13:58:03,016 - src.services.matching_service - INFO - Completed matching for 30/31 materials
2025-09-05 13:58:03,031 - src.services.matching_service - INFO - Batch matching completed. Processed 31 materials
2025-09-05 13:58:03,031 - src.material_matcher_app - INFO - Matching completed in 1.11 seconds
2025-09-05 13:58:03,031 - src.material_matcher_app - INFO - Matching statistics: {'total_materials': 31, 'materials_with_matches': 31, 'materials_without_matches': 0, 'match_rate': 100.0, 'total_matches': 310, 'average_matches_per_material': 10.0, 'average_similarity': 68.30782844577755, 'max_similarity': 100.0, 'min_similarity': 54.4212048192771}
2025-09-05 14:02:09,776 - src.material_matcher_app - INFO - Loading materials from C:/Users/uzun.a.i/PycharmProjects/PythonProject/material.xlsx
2025-09-05 14:02:09,786 - src.material_matcher_app - INFO - Loaded 31 materials
2025-09-05 14:02:12,412 - src.material_matcher_app - INFO - Starting matching process for 31 materials...
2025-09-05 14:02:12,412 - src.services.matching_service - INFO - Starting batch matching for 31 materials
2025-09-05 14:02:12,691 - src.services.matching_service - INFO - Completed matching for 10/31 materials
2025-09-05 14:02:13,047 - src.services.matching_service - INFO - Completed matching for 20/31 materials
2025-09-05 14:02:13,399 - src.services.matching_service - INFO - Completed matching for 30/31 materials
2025-09-05 14:02:13,420 - src.services.matching_service - INFO - Batch matching completed. Processed 31 materials
2025-09-05 14:02:13,420 - src.material_matcher_app - INFO - Matching completed in 1.01 seconds
2025-09-05 14:02:13,420 - src.material_matcher_app - INFO - Matching statistics: {'total_materials': 31, 'materials_with_matches': 31, 'materials_without_matches': 0, 'match_rate': 100.0, 'total_matches': 310, 'average_matches_per_material': 10.0, 'average_similarity': 67.47326714354234, 'max_similarity': 100.0, 'min_similarity': 49.21999999999999}
2025-09-05 14:15:19,922 - src.services.elasticsearch_service - INFO - Initialized Elasticsearch connection to localhost:9200
2025-09-05 14:15:19,923 - src.material_matcher_app - INFO - MaterialMatcher application initialized successfully
2025-09-05 14:29:24,900 - src.services.elasticsearch_service - INFO - Initialized Elasticsearch connection to localhost:9200
2025-09-05 14:29:24,900 - src.material_matcher_app - INFO - MaterialMatcher application initialized successfully
2025-09-05 14:29:49,393 - src.material_matcher_app - INFO - Loading materials from C:/Users/uzun.a.i/PycharmProjects/PythonProject/material.xlsx
2025-09-05 14:29:49,811 - src.material_matcher_app - INFO - Loaded 31 materials
2025-09-05 14:29:54,188 - src.material_matcher_app - INFO - Loading price list from C:/Users/uzun.a.i/PycharmProjects/PythonProject/pricelist.xlsx
2025-09-05 14:29:54,245 - src.material_matcher_app - INFO - Loaded 466 price list items
2025-09-05 14:29:57,639 - src.material_matcher_app - INFO - Starting matching process for 31 materials...
2025-09-05 14:29:57,639 - src.services.matching_service - INFO - Starting batch matching for 31 materials
2025-09-05 14:29:57,938 - src.services.matching_service - INFO - Completed matching for 10/31 materials
2025-09-05 14:29:58,314 - src.services.matching_service - INFO - Completed matching for 20/31 materials
2025-09-05 14:29:58,731 - src.services.matching_service - INFO - Completed matching for 30/31 materials
2025-09-05 14:29:58,752 - src.services.matching_service - INFO - Batch matching completed. Processed 31 materials
2025-09-05 14:29:58,752 - src.material_matcher_app - INFO - Matching completed in 1.11 seconds
2025-09-05 14:29:58,752 - src.material_matcher_app - INFO - Matching statistics: {'total_materials': 31, 'materials_with_matches': 31, 'materials_without_matches': 0, 'match_rate': 100.0, 'total_matches': 310, 'average_matches_per_material': 10.0, 'average_similarity': 67.47326714354234, 'max_similarity': 100.0, 'min_similarity': 49.21999999999999}
2025-09-05 14:34:20,861 - src.services.elasticsearch_service - INFO - Initialized Elasticsearch connection to localhost:9200
2025-09-05 14:34:20,861 - src.material_matcher_app - INFO - MaterialMatcher application initialized successfully
2025-09-05 15:00:01,926 - src.services.elasticsearch_service - INFO - Initialized Elasticsearch connection to localhost:9200
2025-09-05 15:00:01,926 - src.material_matcher_app - INFO - MaterialMatcher application initialized successfully
2025-09-05 15:00:11,300 - src.material_matcher_app - INFO - Loading materials from C:/Users/uzun.a.i/PycharmProjects/PythonProject/material.xlsx
2025-09-05 15:00:11,470 - src.material_matcher_app - INFO - Loaded 31 materials
2025-09-05 15:00:11,993 - src.material_matcher_app - INFO - Loading price list from C:/Users/uzun.a.i/PycharmProjects/PythonProject/pricelist.xlsx
2025-09-05 15:00:12,051 - src.material_matcher_app - INFO - Loaded 466 price list items
2025-09-05 15:00:16,715 - src.material_matcher_app - INFO - Starting matching process for 31 materials...
2025-09-05 15:00:16,716 - src.services.matching_service - INFO - Starting batch matching for 31 materials
2025-09-05 15:00:17,000 - src.services.matching_service - INFO - Completed matching for 10/31 materials
2025-09-05 15:00:17,343 - src.services.matching_service - INFO - Completed matching for 20/31 materials
2025-09-05 15:00:17,688 - src.services.matching_service - INFO - Completed matching for 30/31 materials
2025-09-05 15:00:17,750 - src.services.matching_service - INFO - Batch matching completed. Processed 31 materials
2025-09-05 15:00:17,750 - src.material_matcher_app - INFO - Matching completed in 1.03 seconds
2025-09-05 15:00:17,750 - src.material_matcher_app - INFO - Matching statistics: {'total_materials': 31, 'materials_with_matches': 31, 'materials_without_matches': 0, 'match_rate': 100.0, 'total_matches': 310, 'average_matches_per_material': 10.0, 'average_similarity': 67.47326714354234, 'max_similarity': 100.0, 'min_similarity': 49.21999999999999}
2025-09-05 15:27:00,650 - src.services.elasticsearch_service - INFO - Initialized Elasticsearch connection to localhost:9200
2025-09-05 15:27:00,650 - src.material_matcher_app - INFO - MaterialMatcher application initialized successfully
2025-09-05 15:27:10,158 - src.material_matcher_app - INFO - Loading materials from C:/Users/uzun.a.i/PycharmProjects/PythonProject/material.xlsx
2025-09-05 15:27:10,323 - src.material_matcher_app - INFO - Loaded 31 materials
2025-09-05 15:27:10,794 - src.material_matcher_app - INFO - Loading price list from C:/Users/uzun.a.i/PycharmProjects/PythonProject/pricelist.xlsx
2025-09-05 15:27:10,854 - src.material_matcher_app - INFO - Loaded 466 price list items
2025-09-05 15:27:14,279 - src.material_matcher_app - INFO - Starting matching process for 31 materials...
2025-09-05 15:27:14,279 - src.services.matching_service - INFO - Starting batch matching for 31 materials
2025-09-05 15:27:14,565 - src.services.matching_service - INFO - Completed matching for 10/31 materials
2025-09-05 15:27:14,925 - src.services.matching_service - INFO - Completed matching for 20/31 materials
2025-09-05 15:27:15,275 - src.services.matching_service - INFO - Completed matching for 30/31 materials
2025-09-05 15:27:15,296 - src.services.matching_service - INFO - Batch matching completed. Processed 31 materials
2025-09-05 15:27:15,296 - src.material_matcher_app - INFO - Matching completed in 1.02 seconds
2025-09-05 15:27:15,296 - src.material_matcher_app - INFO - Matching statistics: {'total_materials': 31, 'materials_with_matches': 31, 'materials_without_matches': 0, 'match_rate': 100.0, 'total_matches': 310, 'average_matches_per_material': 10.0, 'average_similarity': 67.47326714354234, 'max_similarity': 100.0, 'min_similarity': 49.21999999999999}
2025-09-05 16:39:39,142 - src.material_matcher_app - INFO - Starting matching process for 31 materials...
2025-09-05 16:39:39,143 - src.services.matching_service - INFO - Starting batch matching for 31 materials
2025-09-05 16:39:39,394 - src.services.matching_service - INFO - Completed matching for 10/31 materials
2025-09-05 16:39:39,781 - src.services.matching_service - INFO - Completed matching for 20/31 materials
2025-09-05 16:39:40,114 - src.services.matching_service - INFO - Completed matching for 30/31 materials
2025-09-05 16:39:40,134 - src.services.matching_service - INFO - Batch matching completed. Processed 31 materials
2025-09-05 16:39:40,134 - src.material_matcher_app - INFO - Matching completed in 0.99 seconds
2025-09-05 16:39:40,134 - src.material_matcher_app - INFO - Matching statistics: {'total_materials': 31, 'materials_with_matches': 31, 'materials_without_matches': 0, 'match_rate': 100.0, 'total_matches': 310, 'average_matches_per_material': 10.0, 'average_similarity': 67.47326714354234, 'max_similarity': 100.0, 'min_similarity': 49.21999999999999}
2025-09-05 21:54:51,947 - src.services.elasticsearch_service - INFO - Initialized Elasticsearch connection to localhost:9200
2025-09-05 21:54:51,948 - src.material_matcher_app - INFO - MaterialMatcher application initialized successfully
2025-09-05 21:55:03,848 - src.material_matcher_app - INFO - Loading materials from C:/Users/uzun.a.i/PycharmProjects/PythonProject/material.xlsx
2025-09-05 21:55:04,060 - src.material_matcher_app - INFO - Loaded 31 materials
2025-09-05 21:55:04,458 - src.material_matcher_app - INFO - Loading price list from C:/Users/uzun.a.i/PycharmProjects/PythonProject/pricelist.xlsx
2025-09-05 21:55:04,513 - src.material_matcher_app - INFO - Loaded 466 price list items
2025-09-05 21:55:06,526 - src.material_matcher_app - INFO - Starting matching process for 31 materials...
2025-09-05 21:55:06,526 - src.services.matching_service - INFO - Starting batch matching for 31 materials
2025-09-05 21:55:07,191 - src.services.matching_service - INFO - Completed matching for 10/31 materials
2025-09-05 21:55:08,184 - src.services.matching_service - INFO - Completed matching for 20/31 materials
2025-09-05 21:55:08,948 - src.services.matching_service - INFO - Completed matching for 30/31 materials
2025-09-05 21:55:08,980 - src.services.matching_service - INFO - Batch matching completed. Processed 31 materials
2025-09-05 21:55:08,980 - src.material_matcher_app - INFO - Matching completed in 2.45 seconds
2025-09-05 21:55:08,980 - src.material_matcher_app - INFO - Matching statistics: {'total_materials': 31, 'materials_with_matches': 31, 'materials_without_matches': 0, 'match_rate': 100.0, 'total_matches': 310, 'average_matches_per_material': 10.0, 'average_similarity': 67.47326714354234, 'max_similarity': 100.0, 'min_similarity': 49.21999999999999}
2025-09-05 22:08:27,140 - src.services.elasticsearch_service - INFO - Initialized Elasticsearch connection to localhost:9200
2025-09-05 22:08:27,140 - src.material_matcher_app - INFO - MaterialMatcher application initialized successfully
2025-09-05 22:08:38,444 - src.services.elasticsearch_service - INFO - Initialized Elasticsearch connection to localhost:9200
2025-09-05 22:08:38,444 - src.material_matcher_app - INFO - MaterialMatcher application initialized successfully
2025-09-05 22:08:50,501 - src.material_matcher_app - INFO - Loading materials from C:/Users/uzun.a.i/PycharmProjects/PythonProject/material.xlsx
2025-09-05 22:08:50,664 - src.material_matcher_app - INFO - Loaded 31 materials
2025-09-05 22:08:51,061 - src.material_matcher_app - INFO - Loading price list from C:/Users/uzun.a.i/PycharmProjects/PythonProject/pricelist.xlsx
2025-09-05 22:08:51,119 - src.material_matcher_app - INFO - Loaded 466 price list items
2025-09-05 22:08:54,052 - src.material_matcher_app - INFO - Starting matching process for 31 materials...
2025-09-05 22:08:54,052 - src.services.matching_service - INFO - Starting batch matching for 31 materials
2025-09-05 22:08:54,594 - src.services.matching_service - INFO - Completed matching for 10/31 materials
2025-09-05 22:08:55,506 - src.services.matching_service - INFO - Completed matching for 20/31 materials
2025-09-05 22:08:56,283 - src.services.matching_service - INFO - Completed matching for 30/31 materials
2025-09-05 22:08:56,304 - src.services.matching_service - INFO - Batch matching completed. Processed 31 materials
2025-09-05 22:08:56,304 - src.material_matcher_app - INFO - Matching completed in 2.25 seconds
2025-09-05 22:08:56,304 - src.material_matcher_app - INFO - Matching statistics: {'total_materials': 31, 'materials_with_matches': 31, 'materials_without_matches': 0, 'match_rate': 100.0, 'total_matches': 310, 'average_matches_per_material': 10.0, 'average_similarity': 67.47326714354234, 'max_similarity': 100.0, 'min_similarity': 49.21999999999999}
2025-09-05 22:17:31,536 - src.material_matcher_app - INFO - Starting matching process for 31 materials...
2025-09-05 22:17:31,536 - src.services.matching_service - INFO - Starting batch matching for 31 materials
2025-09-05 22:17:32,366 - src.services.matching_service - INFO - Completed matching for 10/31 materials
2025-09-05 22:17:33,300 - src.services.matching_service - INFO - Completed matching for 20/31 materials
2025-09-05 22:17:34,089 - src.services.matching_service - INFO - Completed matching for 30/31 materials
2025-09-05 22:17:34,110 - src.services.matching_service - INFO - Batch matching completed. Processed 31 materials
2025-09-05 22:17:34,111 - src.material_matcher_app - INFO - Matching completed in 2.57 seconds
2025-09-05 22:17:34,111 - src.material_matcher_app - INFO - Matching statistics: {'total_materials': 31, 'materials_with_matches': 31, 'materials_without_matches': 0, 'match_rate': 100.0, 'total_matches': 310, 'average_matches_per_material': 10.0, 'average_similarity': 67.47326714354234, 'max_similarity': 100.0, 'min_similarity': 49.21999999999999}
2025-09-05 22:22:49,802 - src.services.elasticsearch_service - INFO - Initialized Elasticsearch connection to localhost:9200
2025-09-05 22:22:49,802 - src.material_matcher_app - INFO - MaterialMatcher application initialized successfully
2025-09-06 11:07:47,051 - src.services.elasticsearch_service - INFO - Initialized Elasticsearch connection to localhost:9200
2025-09-06 11:07:47,051 - src.material_matcher_app - INFO - MaterialMatcher application initialized successfully
2025-09-06 11:07:56,838 - src.material_matcher_app - INFO - Loading materials from C:/Users/uzun.a.i/PycharmProjects/PythonProject/material.xlsx
2025-09-06 11:07:57,002 - src.material_matcher_app - INFO - Loaded 31 materials
2025-09-06 11:07:57,910 - src.material_matcher_app - INFO - Loading price list from C:/Users/uzun.a.i/PycharmProjects/PythonProject/pricelist.xlsx
2025-09-06 11:07:57,967 - src.material_matcher_app - INFO - Loaded 466 price list items
2025-09-06 11:08:01,791 - src.material_matcher_app - INFO - Starting matching process for 31 materials...
2025-09-06 11:08:01,791 - src.services.matching_service - INFO - Starting batch matching for 31 materials
2025-09-06 11:08:01,888 - src.services.matching_service - INFO - Completed matching for 10/31 materials
2025-09-06 11:08:02,018 - src.services.matching_service - INFO - Completed matching for 20/31 materials
2025-09-06 11:08:02,113 - src.services.matching_service - INFO - Completed matching for 30/31 materials
2025-09-06 11:08:02,130 - src.services.matching_service - INFO - Batch matching completed. Processed 31 materials
2025-09-06 11:08:02,130 - src.material_matcher_app - INFO - Matching completed in 0.34 seconds
2025-09-06 11:08:02,131 - src.material_matcher_app - INFO - Matching statistics: {'total_materials': 31, 'materials_with_matches': 0, 'materials_without_matches': 31, 'match_rate': 0.0, 'total_matches': 0, 'average_matches_per_material': 0.0}
2025-09-06 11:08:11,449 - src.material_matcher_app - INFO - Indexing 31 materials...
2025-09-06 11:08:12,970 - src.services.elasticsearch_service - INFO - Indexed 31 materials
2025-09-06 11:08:12,970 - src.material_matcher_app - INFO - Indexing 466 price list items...
2025-09-06 11:08:16,530 - src.material_matcher_app - INFO - Starting matching process for 31 materials...
2025-09-06 11:08:16,530 - src.services.matching_service - INFO - Starting batch matching for 31 materials
2025-09-06 11:08:16,841 - src.services.matching_service - INFO - Completed matching for 10/31 materials
2025-09-06 11:08:17,182 - src.services.matching_service - INFO - Completed matching for 20/31 materials
2025-09-06 11:08:17,684 - src.services.matching_service - INFO - Completed matching for 30/31 materials
2025-09-06 11:08:17,684 - src.services.matching_service - INFO - Batch matching completed. Processed 31 materials
2025-09-06 11:08:17,685 - src.material_matcher_app - INFO - Matching completed in 1.15 seconds
2025-09-06 11:08:17,685 - src.material_matcher_app - INFO - Matching statistics: {'total_materials': 31, 'materials_with_matches': 31, 'materials_without_matches': 0, 'match_rate': 100.0, 'total_matches': 310, 'average_matches_per_material': 10.0, 'average_similarity': 57.66098402904801, 'max_similarity': 84.67101910828023, 'min_similarity': 47.10117647058823}
2025-09-06 11:08:37,127 - src.services.elasticsearch_service - INFO - Indexed 466 price list items
